{
  "version": 8,
  "blockIdVersion": 11,
  "anchorX": 0,
  "anchorY": 0,
  "anchorZ": 0,
  "blocks": [
    {
      "x": -13,
      "y": 22,
      "z": 2,
      "name": "Plant_Coral_Block_Violet"
    },
    {
      "x": -12,
      "y": 21,
      "z": -9,
      "name": "Plant_Coral_Block_Pink"
    },
    {
      "x": -12,
      "y": 22,
      "z": -9,
      "name": "Plant_Coral_Block_Pink"
    },
    {
      "x": -12,
      "y": 21,
      "z": -8,
      "name": "Plant_Coral_Block_Purple"
    },
    {
      "x": -12,
      "y": 21,
      "z": -7,
      "name": "Plant_Coral_Block_Violet"
    },
    {
      "x": -12,
      "y": 18,
      "z": -6,
      "name": "Plant_Coral_Bush_Pink"
    },
    {
      "x": -12,
      "y": 19,
      "z": -6,
      "name": "Plant_Coral_Block_Violet"
    },
    {
      "x": -12,
      "y": 20,
      "z": -6,
      "name": "Plant_Coral_Block_Purple"
    },
    {
      "x": -12,
      "y": 21,
      "z": -6,
      "name": "Plant_Coral_Bush_Pink"
    },
    {
      "x": -12,
      "y": 18,
      "z": 1,
      "name": "Plant_Coral_Bush_Purple"
    },
    {
      "x": -12,
      "y": 19,
      "z": 1,
      "name": "Plant_Coral_Bush_Pink"
    },
    {
      "x": -12,
      "y": 21,
      "z": 1,
      "name": "Plant_Coral_Bush_Pink"
    },
    {
      "x": -12,
      "y": 22,
      "z": 1,
      "name": "Plant_Coral_Bush_Pink"
    },
    {
      "x": -12,
      "y": 21,
      "z": 2,
      "name": "Plant_Coral_Block_Pink"
    },
    {
      "x": -12,
      "y": 22,
      "z": 2,
      "name": "Plant_Coral_Block_Violet"
    },
    {
      "x": -12,
      "y": 23,
      "z": 2,
      "name": "Plant_Coral_Block_Violet"
    },
    {
      "x": -12,
      "y": 22,
      "z": 3,
      "name": "Plant_Coral_Bush_Violet"
    },
    {
      "x": -11,
      "y": 21,
      "z": -10,
      "name": "Plant_Coral_Block_Pink"
    },
    {
      "x": -11,
      "y": 22,
      "z": -10,
      "name": "Plant_Coral_Bush_Purple"
    },
    {
      "x": -11,
      "y": 20,
      "z": -9,
      "name": "Plant_Coral_Bush_Pink"
    },
    {
      "x": -11,
      "y": 21,
      "z": -9,
      "name": "Plant_Coral_Bush_Pink"
    },
    {
      "x": -11,
      "y": 22,
      "z": -9,
      "name": "Plant_Coral_Bush_Purple"
    },
    {
      "x": -11,
      "y": 23,
      "z": -9,
      "name": "Plant_Coral_Bush_Violet"
    },
    {
      "x": -11,
      "y": 20,
      "z": -8,
      "name": "Plant_Coral_Bush_Pink"
    },
    {
      "x": -11,
      "y": 21,
      "z": -8,
      "name": "Plant_Coral_Block_Violet"
    },
    {
      "x": -11,
      "y": 22,
      "z": -8,
      "name": "Plant_Coral_Block_Violet"
    },
    {
      "x": -11,
      "y": 18,
      "z": -7,
      "name": "Plant_Coral_Bush_Purple"
    },
    {
      "x": -11,
      "y": 19,
      "z": -7,
      "name": "Plant_Coral_Bush_Pink"
    },
    {
      "x": -11,
      "y": 20,
      "z": -7,
      "name": "Plant_Coral_Block_Pink"
    },
    {
      "x": -11,
      "y": 21,
      "z": -7,
      "name": "Plant_Coral_Block_Purple"
    },
    {
      "x": -11,
      "y": 22,
      "z": -7,
      "name": "Plant_Coral_Bush_Violet"
    },
    {
      "x": -11,
      "y": 17,
      "z": -6,
      "name": "Plant_Coral_Bush_Pink"
    },
    {
      "x": -11,
      "y": 18,
      "z": -6,
      "name": "Plant_Coral_Bush_Violet"
    },
    {
      "x": -11,
      "y": 19,
      "z": -6,
      "name": "Plant_Coral_Block_Violet"
    },
    {
      "x": -11,
      "y": 20,
      "z": -6,
      "name": "Plant_Coral_Bush_Purple"
    },
    {
      "x": -11,
      "y": 21,
      "z": -6,
      "name": "Plant_Coral_Bush_Violet"
    },
    {
      "x": -11,
      "y": 22,
      "z": -6,
      "name": "Plant_Coral_Bush_Pink"
    },
    {
      "x": -11,
      "y": 18,
      "z": -5,
      "name": "Plant_Coral_Bush_Violet"
    },
    {
      "x": -11,
      "y": 19,
      "z": -5,
      "name": "Plant_Coral_Bush_Purple"
    },
    {
      "x": -11,
      "y": 20,
      "z": -5,
      "name": "Plant_Coral_Block_Violet"
    },
    {
      "x": -11,
      "y": 21,
      "z": -5,
      "name": "Plant_Coral_Block_Purple"
    },
    {
      "x": -11,
      "y": 18,
      "z": -4,
      "name": "Plant_Coral_Bush_Violet"
    },
    {
      "x": -11,
      "y": 18,
      "z": 0,
      "name": "Plant_Coral_Bush_Violet"
    },
    {
      "x": -11,
      "y": 19,
      "z": 0,
      "name": "Plant_Coral_Bush_Violet"
    },
    {
      "x": -11,
      "y": 21,
      "z": 0,
      "name": "Plant_Coral_Bush_Pink"
    },
    {
      "x": -11,
      "y": 22,
      "z": 0,
      "name": "Plant_Coral_Block_Violet"
    },
    {
      "x": -11,
      "y": 17,
      "z": 1,
      "name": "Plant_Coral_Block_Pink"
    },
    {
      "x": -11,
      "y": 18,
      "z": 1,
      "name": "Plant_Coral_Bush_Violet"
    },
    {
      "x": -11,
      "y": 19,
      "z": 1,
      "name": "Plant_Coral_Block_Violet"
    },
    {
      "x": -11,
      "y": 20,
      "z": 1,
      "name": "Plant_Coral_Bush_Purple"
    },
    {
      "x": -11,
      "y": 21,
      "z": 1,
      "name": "Plant_Coral_Bush_Purple"
    },
    {
      "x": -11,
      "y": 22,
      "z": 1,
      "name": "Plant_Coral_Bush_Pink"
    },
    {
      "x": -11,
      "y": 23,
      "z": 1,
      "name": "Plant_Coral_Block_Pink"
    },
    {
      "x": -11,
      "y": 18,
      "z": 2,
      "name": "Plant_Coral_Bush_Purple"
    },
    {
      "x": -11,
      "y": 19,
      "z": 2,
      "name": "Plant_Coral_Bush_Purple"
    },
    {
      "x": -11,
      "y": 20,
      "z": 2,
      "name": "Plant_Coral_Block_Pink"
    },
    {
      "x": -11,
      "y": 21,
      "z": 2,
      "name": "Plant_Coral_Block_Pink"
    },
    {
      "x": -11,
      "y": 22,
      "z": 2,
      "name": "Plant_Coral_Block_Purple"
    },
    {
      "x": -11,
      "y": 23,
      "z": 2,
      "name": "Plant_Coral_Bush_Violet"
    },
    {
      "x": -11,
      "y": 21,
      "z": 3,
      "name": "Plant_Coral_Bush_Pink"
    },
    {
      "x": -11,
      "y": 22,
      "z": 3,
      "name": "Plant_Coral_Bush_Pink"
    },
    {
      "x": -11,
      "y": 23,
      "z": 3,
      "name": "Plant_Coral_Bush_Violet"
    },
    {
      "x": -11,
      "y": 22,
      "z": 4,
      "name": "Plant_Coral_Block_Purple"
    },
    {
      "x": -10,
      "y": 21,
      "z": -11,
      "name": "Plant_Coral_Block_Purple"
    },
    {
      "x": -10,
      "y": 20,
      "z": -10,
      "name": "Plant_Coral_Bush_Violet"
    },
    {
      "x": -10,
      "y": 21,
      "z": -10,
      "name": "Plant_Coral_Block_Purple"
    },
    {
      "x": -10,
      "y": 22,
      "z": -10,
      "name": "Plant_Coral_Bush_Purple"
    },
    {
      "x": -10,
      "y": 20,
      "z": -9,
      "name": "Plant_Coral_Block_Pink"
    },
    {
      "x": -10,
      "y": 21,
      "z": -9,
      "name": "Plant_Coral_Block_Pink"
    },
    {
      "x": -10,
      "y": 22,
      "z": -9,
      "name": "Plant_Coral_Block_Purple"
    },
    {
      "x": -10,
      "y": 21,
      "z": -8,
      "name": "Plant_Coral_Bush_Purple"
    },
    {
      "x": -10,
      "y": 18,
      "z": -7,
      "name": "Plant_Coral_Block_Pink"
    },
    {
      "x": -10,
      "y": 20,
      "z": -7,
      "name": "Plant_Coral_Block_Pink"
    },
    {
      "x": -10,
      "y": 21,
      "z": -7,
      "name": "Plant_Coral_Block_Violet"
    },
    {
      "x": -10,
      "y": 22,
      "z": -7,
      "name": "Plant_Coral_Bush_Violet"
    },
    {
      "x": -10,
      "y": 17,
      "z": -6,
      "name": "Plant_Coral_Block_Pink"
    },
    {
      "x": -10,
      "y": 18,
      "z": -6,
      "name": "Plant_Coral_Block_Purple"
    },
    {
      "x": -10,
      "y": 19,
      "z": -6,
      "name": "Plant_Coral_Bush_Purple"
    },
    {
      "x": -10,
      "y": 20,
      "z": -6,
      "name": "Plant_Coral_Block_Pink"
    },
    {
      "x": -10,
      "y": 21,
      "z": -6,
      "name": "Plant_Coral_Block_Purple"
    },
    {
      "x": -10,
      "y": 17,
      "z": -5,
      "name": "Plant_Coral_Block_Violet"
    },
    {
      "x": -10,
      "y": 18,
      "z": -5,
      "name": "Plant_Coral_Block_Pink"
    },
    {
      "x": -10,
      "y": 19,
      "z": -5,
      "name": "Plant_Coral_Block_Purple"
    },
    {
      "x": -10,
      "y": 20,
      "z": -5,
      "name": "Plant_Coral_Bush_Purple"
    },
    {
      "x": -10,
      "y": 17,
      "z": -4,
      "name": "Plant_Coral_Bush_Violet"
    },
    {
      "x": -10,
      "y": 18,
      "z": -4,
      "name": "Plant_Coral_Bush_Pink"
    },
    {
      "x": -10,
      "y": 19,
      "z": -4,
      "name": "Plant_Coral_Bush_Violet"
    },
    {
      "x": -10,
      "y": 18,
      "z": -3,
      "name": "Plant_Coral_Bush_Purple"
    },
    {
      "x": -10,
      "y": 19,
      "z": -1,
      "name": "Plant_Coral_Block_Purple"
    },
    {
      "x": -10,
      "y": 18,
      "z": 0,
      "name": "Plant_Coral_Bush_Violet"
    },
    {
      "x": -10,
      "y": 19,
      "z": 0,
      "name": "Plant_Coral_Block_Pink"
    },
    {
      "x": -10,
      "y": 20,
      "z": 0,
      "name": "Plant_Coral_Block_Purple"
    },
    {
      "x": -10,
      "y": 21,
      "z": 0,
      "name": "Plant_Coral_Bush_Purple"
    },
    {
      "x": -10,
      "y": 17,
      "z": 1,
      "name": "Plant_Coral_Bush_Violet"
    },
    {
      "x": -10,
      "y": 18,
      "z": 1,
      "name": "Plant_Coral_Bush_Violet"
    },
    {
      "x": -10,
      "y": 19,
      "z": 1,
      "name": "Plant_Coral_Bush_Pink"
    },
    {
      "x": -10,
      "y": 20,
      "z": 1,
      "name": "Plant_Coral_Block_Purple"
    },
    {
      "x": -10,
      "y": 21,
      "z": 1,
      "name": "Plant_Coral_Block_Pink"
    },
    {
      "x": -10,
      "y": 22,
      "z": 1,
      "name": "Plant_Coral_Block_Purple"
    },
    {
      "x": -10,
      "y": 18,
      "z": 2,
      "name": "Plant_Coral_Block_Purple"
    },
    {
      "x": -10,
      "y": 19,
      "z": 2,
      "name": "Plant_Coral_Block_Purple"
    },
    {
      "x": -10,
      "y": 20,
      "z": 2,
      "name": "Plant_Coral_Bush_Pink"
    },
    {
      "x": -10,
      "y": 21,
      "z": 2,
      "name": "Plant_Coral_Bush_Purple"
    },
    {
      "x": -10,
      "y": 22,
      "z": 2,
      "name": "Plant_Coral_Bush_Purple"
    },
    {
      "x": -10,
      "y": 19,
      "z": 3,
      "name": "Plant_Coral_Block_Pink"
    },
    {
      "x": -10,
      "y": 22,
      "z": 3,
      "name": "Plant_Coral_Bush_Violet"
    },
    {
      "x": -9,
      "y": 21,
      "z": -10,
      "name": "Plant_Coral_Bush_Violet"
    },
    {
      "x": -9,
      "y": 21,
      "z": -9,
      "name": "Plant_Coral_Block_Violet"
    },
    {
      "x": -9,
      "y": 21,
      "z": -7,
      "name": "Plant_Coral_Bush_Pink"
    },
    {
      "x": -9,
      "y": 18,
      "z": -6,
      "name": "Plant_Coral_Bush_Pink"
    },
    {
      "x": -9,
      "y": 19,
      "z": -6,
      "name": "Plant_Coral_Bush_Purple"
    },
    {
      "x": -9,
      "y": 17,
      "z": -5,
      "name": "Plant_Coral_Bush_Violet"
    },
    {
      "x": -9,
      "y": 18,
      "z": -5,
      "name": "Plant_Coral_Block_Purple"
    },
    {
      "x": -9,
      "y": 19,
      "z": -5,
      "name": "Plant_Coral_Block_Violet"
    },
    {
      "x": -9,
      "y": 20,
      "z": -5,
      "name": "Plant_Coral_Block_Pink"
    },
    {
      "x": -9,
      "y": 17,
      "z": -4,
      "name": "Plant_Coral_Block_Purple"
    },
    {
      "x": -9,
      "y": 18,
      "z": -4,
      "name": "Plant_Coral_Block_Pink"
    },
    {
      "x": -9,
      "y": 19,
      "z": -4,
      "name": "Plant_Coral_Bush_Violet"
    },
    {
      "x": -9,
      "y": 18,
      "z": -3,
      "name": "Plant_Coral_Bush_Violet"
    },
    {
      "x": -9,
      "y": 18,
      "z": -1,
      "name": "Plant_Coral_Bush_Violet"
    },
    {
      "x": -9,
      "y": 19,
      "z": -1,
      "name": "Plant_Coral_Bush_Purple"
    },
    {
      "x": -9,
      "y": 17,
      "z": 0,
      "name": "Plant_Coral_Block_Purple"
    },
    {
      "x": -9,
      "y": 18,
      "z": 0,
      "name": "Plant_Coral_Block_Purple"
    },
    {
      "x": -9,
      "y": 19,
      "z": 0,
      "name": "Plant_Coral_Block_Pink"
    },
    {
      "x": -9,
      "y": 20,
      "z": 0,
      "name": "Plant_Coral_Bush_Pink"
    },
    {
      "x": -9,
      "y": 17,
      "z": 1,
      "name": "Plant_Coral_Block_Purple"
    },
    {
      "x": -9,
      "y": 18,
      "z": 1,
      "name": "Plant_Coral_Block_Pink"
    },
    {
      "x": -9,
      "y": 19,
      "z": 1,
      "name": "Plant_Coral_Bush_Pink"
    },
    {
      "x": -9,
      "y": 20,
      "z": 1,
      "name": "Plant_Coral_Bush_Violet"
    },
    {
      "x": -9,
      "y": 21,
      "z": 1,
      "name": "Plant_Coral_Block_Violet"
    },
    {
      "x": -9,
      "y": 18,
      "z": 2,
      "name": "Plant_Coral_Bush_Purple"
    },
    {
      "x": -9,
      "y": 19,
      "z": 2,
      "name": "Plant_Coral_Bush_Pink"
    },
    {
      "x": -8,
      "y": 18,
      "z": -5,
      "name": "Plant_Coral_Bush_Pink"
    },
    {
      "x": -8,
      "y": 19,
      "z": -5,
      "name": "Plant_Coral_Bush_Violet"
    },
    {
      "x": -8,
      "y": 17,
      "z": -4,
      "name": "Plant_Coral_Block_Pink"
    },
    {
      "x": -8,
      "y": 18,
      "z": -4,
      "name": "Plant_Coral_Block_Violet"
    },
    {
      "x": -8,
      "y": 19,
      "z": -4,
      "name": "Plant_Coral_Bush_Violet"
    },
    {
      "x": -8,
      "y": 18,
      "z": -3,
      "name": "Plant_Coral_Block_Violet"
    },
    {
      "x": -8,
      "y": 18,
      "z": -1,
      "name": "Plant_Coral_Bush_Pink"
    },
    {
      "x": -8,
      "y": 17,
      "z": 0,
      "name": "Plant_Coral_Block_Violet"
    },
    {
      "x": -8,
      "y": 18,
      "z": 0,
      "name": "Plant_Coral_Bush_Purple"
    },
    {
      "x": -8,
      "y": 19,
      "z": 0,
      "name": "Plant_Coral_Bush_Purple"
    },
    {
      "x": -8,
      "y": 18,
      "z": 1,
      "name": "Plant_Coral_Block_Pink"
    },
    {
      "x": -8,
      "y": 19,
      "z": 1,
      "name": "Plant_Coral_Block_Purple"
    },
    {
      "x": -8,
      "y": 21,
      "z": 10,
      "name": "Plant_Coral_Block_Purple"
    },
    {
      "x": -7,
      "y": 18,
      "z": -5,
      "name": "Plant_Coral_Block_Violet"
    },
    {
      "x": -7,
      "y": 17,
      "z": -4,
      "name": "Plant_Coral_Block_Purple"
    },
    {
      "x": -7,
      "y": 18,
      "z": -4,
      "name": "Plant_Coral_Bush_Pink"
    },
    {
      "x": -7,
      "y": 19,
      "z": -4,
      "name": "Plant_Coral_Bush_Purple"
    },
    {
      "x": -7,
      "y": 17,
      "z": -3,
      "name": "Plant_Coral_Bush_Violet"
    },
    {
      "x": -7,
      "y": 18,
      "z": -3,
      "name": "Plant_Coral_Bush_Violet"
    },
    {
      "x": -7,
      "y": 17,
      "z": -2,
      "name": "Plant_Coral_Block_Pink"
    },
    {
      "x": -7,
      "y": 18,
      "z": -2,
      "name": "Plant_Coral_Bush_Violet"
    },
    {
      "x": -7,
      "y": 16,
      "z": -1,
      "name": "Plant_Coral_Bush_Violet"
    },
    {
      "x": -7,
      "y": 17,
      "z": -1,
      "name": "Plant_Coral_Bush_Violet"
    },
    {
      "x": -7,
      "y": 18,
      "z": -1,
      "name": "Plant_Coral_Bush_Purple"
    },
    {
      "x": -7,
      "y": 19,
      "z": -1,
      "name": "Plant_Coral_Bush_Violet"
    },
    {
      "x": -7,
      "y": 17,
      "z": 0,
      "name": "Plant_Coral_Block_Pink"
    },
    {
      "x": -7,
      "y": 18,
      "z": 0,
      "name": "Plant_Coral_Block_Pink"
    },
    {
      "x": -7,
      "y": 19,
      "z": 0,
      "name": "Plant_Coral_Bush_Purple"
    },
    {
      "x": -7,
      "y": 18,
      "z": 1,
      "name": "Plant_Coral_Block_Pink"
    },
    {
      "x": -7,
      "y": 18,
      "z": 3,
      "name": "Plant_Coral_Block_Violet"
    },
    {
      "x": -7,
      "y": 21,
      "z": 9,
      "name": "Plant_Coral_Block_Purple"
    },
    {
      "x": -7,
      "y": 20,
      "z": 10,
      "name": "Plant_Coral_Bush_Violet"
    },
    {
      "x": -7,
      "y": 21,
      "z": 10,
      "name": "Plant_Coral_Bush_Pink"
    },
    {
      "x": -7,
      "y": 22,
      "z": 10,
      "name": "Plant_Coral_Bush_Violet"
    },
    {
      "x": -7,
      "y": 21,
      "z": 11,
      "name": "Plant_Coral_Block_Pink"
    },
    {
      "x": -6,
      "y": 17,
      "z": -5,
      "name": "Plant_Coral_Block_Violet"
    },
    {
      "x": -6,
      "y": 18,
      "z": -5,
      "name": "Plant_Coral_Bush_Pink"
    },
    {
      "x": -6,
      "y": 16,
      "z": -4,
      "name": "Plant_Coral_Bush_Pink"
    },
    {
      "x": -6,
      "y": 17,
      "z": -4,
      "name": "Plant_Coral_Bush_Purple"
    },
    {
      "x": -6,
      "y": 18,
      "z": -4,
      "name": "Plant_Coral_Bush_Purple"
    },
    {
      "x": -6,
      "y": 19,
      "z": -4,
      "name": "Plant_Coral_Block_Purple"
    },
    {
      "x": -6,
      "y": 16,
      "z": -3,
      "name": "Plant_Coral_Block_Violet"
    },
    {
      "x": -6,
      "y": 17,
      "z": -3,
      "name": "Plant_Coral_Bush_Violet"
    },
    {
      "x": -6,
      "y": 18,
      "z": -3,
      "name": "Plant_Coral_Bush_Violet"
    },
    {
      "x": -6,
      "y": 16,
      "z": -2,
      "name": "Plant_Coral_Block_Purple"
    },
    {
      "x": -6,
      "y": 17,
      "z": -2,
      "name": "Plant_Coral_Block_Purple"
    },
    {
      "x": -6,
      "y": 18,
      "z": -2,
      "name": "Plant_Coral_Block_Purple"
    },
    {
      "x": -6,
      "y": 15,
      "z": -1,
      "name": "Plant_Coral_Block_Violet"
    },
    {
      "x": -6,
      "y": 16,
      "z": -1,
      "name": "Plant_Coral_Bush_Pink"
    },
    {
      "x": -6,
      "y": 17,
      "z": -1,
      "name": "Plant_Coral_Bush_Violet"
    },
    {
      "x": -6,
      "y": 18,
      "z": -1,
      "name": "Plant_Coral_Block_Pink"
    },
    {
      "x": -6,
      "y": 19,
      "z": -1,
      "name": "Plant_Coral_Block_Pink"
    },
    {
      "x": -6,
      "y": 16,
      "z": 0,
      "name": "Plant_Coral_Bush_Purple"
    },
    {
      "x": -6,
      "y": 17,
      "z": 0,
      "name": "Plant_Coral_Block_Pink"
    },
    {
      "x": -6,
      "y": 18,
      "z": 0,
      "name": "Plant_Coral_Bush_Violet"
    },
    {
      "x": -6,
      "y": 17,
      "z": 1,
      "name": "Plant_Coral_Bush_Violet"
    },
    {
      "x": -6,
      "y": 18,
      "z": 2,
      "name": "Plant_Coral_Bush_Pink"
    },
    {
      "x": -6,
      "y": 17,
      "z": 3,
      "name": "Plant_Coral_Block_Violet"
    },
    {
      "x": -6,
      "y": 18,
      "z": 3,
      "name": "Plant_Coral_Block_Purple"
    },
    {
      "x": -6,
      "y": 19,
      "z": 3,
      "name": "Plant_Coral_Block_Pink"
    },
    {
      "x": -6,
      "y": 18,
      "z": 4,
      "name": "Plant_Coral_Block_Violet"
    },
    {
      "x": -6,
      "y": 18,
      "z": 6,
      "name": "Plant_Coral_Block_Pink"
    },
    {
      "x": -6,
      "y": 19,
      "z": 6,
      "name": "Plant_Coral_Block_Pink"
    },
    {
      "x": -6,
      "y": 18,
      "z": 7,
      "name": "Plant_Coral_Bush_Purple"
    },
    {
      "x": -6,
      "y": 19,
      "z": 7,
      "name": "Plant_Coral_Bush_Violet"
    },
    {
      "x": -6,
      "y": 20,
      "z": 7,
      "name": "Plant_Coral_Block_Pink"
    },
    {
      "x": -6,
      "y": 18,
      "z": 8,
      "name": "Plant_Coral_Block_Purple"
    },
    {
      "x": -6,
      "y": 19,
      "z": 8,
      "name": "Plant_Coral_Block_Pink"
    },
    {
      "x": -6,
      "y": 19,
      "z": 9,
      "name": "Plant_Coral_Block_Purple"
    },
    {
      "x": -6,
      "y": 21,
      "z": 9,
      "name": "Plant_Coral_Bush_Pink"
    },
    {
      "x": -6,
      "y": 19,
      "z": 10,
      "name": "Plant_Coral_Block_Pink"
    },
    {
      "x": -6,
      "y": 20,
      "z": 10,
      "name": "Plant_Coral_Bush_Purple"
    },
    {
      "x": -6,
      "y": 21,
      "z": 10,
      "name": "Plant_Coral_Block_Pink"
    },
    {
      "x": -6,
      "y": 22,
      "z": 10,
      "name": "Plant_Coral_Block_Violet"
    },
    {
      "x": -6,
      "y": 21,
      "z": 11,
      "name": "Plant_Coral_Block_Purple"
    },
    {
      "x": -5,
      "y": 17,
      "z": -4,
      "name": "Plant_Coral_Bush_Purple"
    },
    {
      "x": -5,
      "y": 18,
      "z": -4,
      "name": "Plant_Coral_Block_Violet"
    },
    {
      "x": -5,
      "y": 16,
      "z": -3,
      "name": "Plant_Coral_Bush_Pink"
    },
    {
      "x": -5,
      "y": 17,
      "z": -3,
      "name": "Plant_Coral_Block_Purple"
    },
    {
      "x": -5,
      "y": 18,
      "z": -3,
      "name": "Plant_Coral_Block_Purple"
    },
    {
      "x": -5,
      "y": 15,
      "z": -2,
      "name": "Plant_Coral_Block_Purple"
    },
    {
      "x": -5,
      "y": 16,
      "z": -2,
      "name": "Plant_Coral_Block_Purple"
    },
    {
      "x": -5,
      "y": 17,
      "z": -2,
      "name": "Plant_Coral_Block_Violet"
    },
    {
      "x": -5,
      "y": 18,
      "z": -2,
      "name": "Plant_Coral_Block_Violet"
    },
    {
      "x": -5,
      "y": 19,
      "z": -2,
      "name": "Plant_Coral_Bush_Violet"
    },
    {
      "x": -5,
      "y": 15,
      "z": -1,
      "name": "Plant_Coral_Block_Pink"
    },
    {
      "x": -5,
      "y": 16,
      "z": -1,
      "name": "Plant_Coral_Bush_Pink"
    },
    {
      "x": -5,
      "y": 17,
      "z": -1,
      "name": "Plant_Coral_Block_Purple"
    },
    {
      "x": -5,
      "y": 18,
      "z": -1,
      "name": "Plant_Coral_Block_Violet"
    },
    {
      "x": -5,
      "y": 19,
      "z": -1,
      "name": "Plant_Coral_Bush_Violet"
    },
    {
      "x": -5,
      "y": 15,
      "z": 0,
      "name": "Plant_Coral_Block_Pink"
    },
    {
      "x": -5,
      "y": 16,
      "z": 0,
      "name": "Plant_Coral_Bush_Purple"
    },
    {
      "x": -5,
      "y": 17,
      "z": 0,
      "name": "Plant_Coral_Block_Purple"
    },
    {
      "x": -5,
      "y": 18,
      "z": 0,
      "name": "Plant_Coral_Bush_Pink"
    },
    {
      "x": -5,
      "y": 19,
      "z": 0,
      "name": "Plant_Coral_Block_Purple"
    },
    {
      "x": -5,
      "y": 16,
      "z": 1,
      "name": "Plant_Coral_Block_Purple"
    },
    {
      "x": -5,
      "y": 17,
      "z": 1,
      "name": "Plant_Coral_Bush_Purple"
    },
    {
      "x": -5,
      "y": 18,
      "z": 1,
      "name": "Plant_Coral_Bush_Pink"
    },
    {
      "x": -5,
      "y": 18,
      "z": 2,
      "name": "Plant_Coral_Bush_Pink"
    },
    {
      "x": -5,
      "y": 17,
      "z": 3,
      "name": "Plant_Coral_Bush_Purple"
    },
    {
      "x": -5,
      "y": 18,
      "z": 3,
      "name": "Plant_Coral_Block_Pink"
    },
    {
      "x": -5,
      "y": 19,
      "z": 3,
      "name": "Plant_Coral_Bush_Purple"
    },
    {
      "x": -5,
      "y": 17,
      "z": 4,
      "name": "Plant_Coral_Bush_Pink"
    },
    {
      "x": -5,
      "y": 18,
      "z": 4,
      "name": "Plant_Coral_Bush_Pink"
    },
    {
      "x": -5,
      "y": 19,
      "z": 4,
      "name": "Plant_Coral_Bush_Violet"
    },
    {
      "x": -5,
      "y": 18,
      "z": 5,
      "name": "Plant_Coral_Block_Pink"
    },
    {
      "x": -5,
      "y": 19,
      "z": 5,
      "name": "Plant_Coral_Bush_Violet"
    },
    {
      "x": -5,
      "y": 17,
      "z": 6,
      "name": "Plant_Coral_Bush_Pink"
    },
    {
      "x": -5,
      "y": 18,
      "z": 6,
      "name": "Plant_Coral_Bush_Pink"
    },
    {
      "x": -5,
      "y": 19,
      "z": 6,
      "name": "Plant_Coral_Block_Pink"
    },
    {
      "x": -5,
      "y": 20,
      "z": 6,
      "name": "Plant_Coral_Block_Violet"
    },
    {
      "x": -5,
      "y": 17,
      "z": 7,
      "name": "Plant_Coral_Block_Pink"
    },
    {
      "x": -5,
      "y": 18,
      "z": 7,
      "name": "Plant_Coral_Bush_Purple"
    },
    {
      "x": -5,
      "y": 19,
      "z": 7,
      "name": "Plant_Coral_Bush_Pink"
    },
    {
      "x": -5,
      "y": 20,
      "z": 7,
      "name": "Plant_Coral_Bush_Pink"
    },
    {
      "x": -5,
      "y": 21,
      "z": 7,
      "name": "Plant_Coral_Bush_Violet"
    },
    {
      "x": -5,
      "y": 17,
      "z": 8,
      "name": "Plant_Coral_Bush_Violet"
    },
    {
      "x": -5,
      "y": 18,
      "z": 8,
      "name": "Plant_Coral_Block_Purple"
    },
    {
      "x": -5,
      "y": 19,
      "z": 8,
      "name": "Plant_Coral_Block_Pink"
    },
    {
      "x": -5,
      "y": 20,
      "z": 8,
      "name": "Plant_Coral_Bush_Purple"
    },
    {
      "x": -5,
      "y": 18,
      "z": 9,
      "name": "Plant_Coral_Bush_Pink"
    },
    {
      "x": -5,
      "y": 19,
      "z": 9,
      "name": "Plant_Coral_Bush_Pink"
    },
    {
      "x": -5,
      "y": 20,
      "z": 9,
      "name": "Plant_Coral_Bush_Purple"
    },
    {
      "x": -5,
      "y": 21,
      "z": 9,
      "name": "Plant_Coral_Block_Violet"
    },
    {
      "x": -5,
      "y": 18,
      "z": 10,
      "name": "Plant_Coral_Bush_Violet"
    },
    {
      "x": -5,
      "y": 19,
      "z": 10,
      "name": "Plant_Coral_Block_Violet"
    },
    {
      "x": -5,
      "y": 20,
      "z": 10,
      "name": "Plant_Coral_Block_Purple"
    },
    {
      "x": -5,
      "y": 21,
      "z": 10,
      "name": "Plant_Coral_Bush_Pink"
    },
    {
      "x": -5,
      "y": 22,
      "z": 10,
      "name": "Plant_Coral_Block_Violet"
    },
    {
      "x": -5,
      "y": 19,
      "z": 11,
      "name": "Plant_Coral_Block_Violet"
    },
    {
      "x": -5,
      "y": 20,
      "z": 11,
      "name": "Plant_Coral_Bush_Pink"
    },
    {
      "x": -5,
      "y": 21,
      "z": 11,
      "name": "Plant_Coral_Bush_Violet"
    },
    {
      "x": -4,
      "y": 19,
      "z": -11,
      "name": "Plant_Coral_Block_Purple"
    },
    {
      "x": -4,
      "y": 18,
      "z": -10,
      "name": "Plant_Coral_Block_Pink"
    },
    {
      "x": -4,
      "y": 19,
      "z": -10,
      "name": "Plant_Coral_Bush_Violet"
    },
    {
      "x": -4,
      "y": 18,
      "z": -9,
      "name": "Plant_Coral_Bush_Violet"
    },
    {
      "x": -4,
      "y": 18,
      "z": -8,
      "name": "Plant_Coral_Block_Pink"
    },
    {
      "x": -4,
      "y": 18,
      "z": -7,
      "name": "Plant_Coral_Bush_Violet"
    },
    {
      "x": -4,
      "y": 17,
      "z": -3,
      "name": "Plant_Coral_Block_Purple"
    },
    {
      "x": -4,
      "y": 16,
      "z": -2,
      "name": "Plant_Coral_Block_Pink"
    },
    {
      "x": -4,
      "y": 17,
      "z": -2,
      "name": "Plant_Coral_Block_Violet"
    },
    {
      "x": -4,
      "y": 18,
      "z": -2,
      "name": "Plant_Coral_Block_Violet"
    },
    {
      "x": -4,
      "y": 15,
      "z": -1,
      "name": "Plant_Coral_Block_Pink"
    },
    {
      "x": -4,
      "y": 16,
      "z": -1,
      "name": "Plant_Coral_Block_Purple"
    },
    {
      "x": -4,
      "y": 17,
      "z": -1,
      "name": "Plant_Coral_Block_Pink"
    },
    {
      "x": -4,
      "y": 18,
      "z": -1,
      "name": "Plant_Coral_Bush_Pink"
    },
    {
      "x": -4,
      "y": 19,
      "z": -1,
      "name": "Plant_Coral_Bush_Pink"
    },
    {
      "x": -4,
      "y": 15,
      "z": 0,
      "name": "Plant_Coral_Bush_Purple"
    },
    {
      "x": -4,
      "y": 16,
      "z": 0,
      "name": "Plant_Coral_Block_Violet"
    },
    {
      "x": -4,
      "y": 17,
      "z": 0,
      "name": "Plant_Coral_Block_Pink"
    },
    {
      "x": -4,
      "y": 18,
      "z": 0,
      "name": "Plant_Coral_Block_Purple"
    },
    {
      "x": -4,
      "y": 19,
      "z": 0,
      "name": "Plant_Coral_Block_Pink"
    },
    {
      "x": -4,
      "y": 16,
      "z": 1,
      "name": "Plant_Coral_Bush_Purple"
    },
    {
      "x": -4,
      "y": 17,
      "z": 1,
      "name": "Plant_Coral_Bush_Purple"
    },
    {
      "x": -4,
      "y": 18,
      "z": 1,
      "name": "Plant_Coral_Block_Purple"
    },
    {
      "x": -4,
      "y": 19,
      "z": 1,
      "name": "Plant_Coral_Bush_Pink"
    },
    {
      "x": -4,
      "y": 17,
      "z": 2,
      "name": "Plant_Coral_Block_Pink"
    },
    {
      "x": -4,
      "y": 18,
      "z": 2,
      "name": "Plant_Coral_Bush_Pink"
    },
    {
      "x": -4,
      "y": 19,
      "z": 2,
      "name": "Plant_Coral_Bush_Purple"
    },
    {
      "x": -4,
      "y": 17,
      "z": 3,
      "name": "Plant_Coral_Block_Pink"
    },
    {
      "x": -4,
      "y": 18,
      "z": 3,
      "name": "Plant_Coral_Bush_Violet"
    },
    {
      "x": -4,
      "y": 19,
      "z": 3,
      "name": "Plant_Coral_Block_Pink"
    },
    {
      "x": -4,
      "y": 17,
      "z": 4,
      "name": "Plant_Coral_Bush_Pink"
    },
    {
      "x": -4,
      "y": 18,
      "z": 4,
      "name": "Plant_Coral_Bush_Violet"
    },
    {
      "x": -4,
      "y": 19,
      "z": 4,
      "name": "Plant_Coral_Bush_Violet"
    },
    {
      "x": -4,
      "y": 17,
      "z": 5,
      "name": "Plant_Coral_Block_Violet"
    },
    {
      "x": -4,
      "y": 18,
      "z": 5,
      "name": "Plant_Coral_Block_Purple"
    },
    {
      "x": -4,
      "y": 19,
      "z": 5,
      "name": "Plant_Coral_Bush_Purple"
    },
    {
      "x": -4,
      "y": 17,
      "z": 6,
      "name": "Plant_Coral_Block_Pink"
    },
    {
      "x": -4,
      "y": 18,
      "z": 6,
      "name": "Plant_Coral_Bush_Violet"
    },
    {
      "x": -4,
      "y": 19,
      "z": 6,
      "name": "Plant_Coral_Bush_Violet"
    },
    {
      "x": -4,
      "y": 18,
      "z": 7,
      "name": "Plant_Coral_Block_Pink"
    },
    {
      "x": -4,
      "y": 19,
      "z": 7,
      "name": "Plant_Coral_Bush_Pink"
    },
    {
      "x": -4,
      "y": 20,
      "z": 7,
      "name": "Plant_Coral_Block_Pink"
    },
    {
      "x": -4,
      "y": 18,
      "z": 8,
      "name": "Plant_Coral_Bush_Purple"
    },
    {
      "x": -4,
      "y": 19,
      "z": 8,
      "name": "Plant_Coral_Block_Purple"
    },
    {
      "x": -4,
      "y": 19,
      "z": 9,
      "name": "Plant_Coral_Block_Pink"
    },
    {
      "x": -4,
      "y": 19,
      "z": 10,
      "name": "Plant_Coral_Block_Purple"
    },
    {
      "x": -4,
      "y": 20,
      "z": 10,
      "name": "Plant_Coral_Block_Violet"
    },
    {
      "x": -4,
      "y": 21,
      "z": 10,
      "name": "Plant_Coral_Bush_Purple"
    },
    {
      "x": -3,
      "y": 19,
      "z": -12,
      "name": "Plant_Coral_Bush_Pink"
    },
    {
      "x": -3,
      "y": 20,
      "z": -12,
      "name": "Plant_Coral_Bush_Violet"
    },
    {
      "x": -3,
      "y": 21,
      "z": -12,
      "name": "Plant_Coral_Block_Violet"
    },
    {
      "x": -3,
      "y": 18,
      "z": -11,
      "name": "Plant_Coral_Bush_Purple"
    },
    {
      "x": -3,
      "y": 19,
      "z": -11,
      "name": "Plant_Coral_Block_Violet"
    },
    {
      "x": -3,
      "y": 20,
      "z": -11,
      "name": "Plant_Coral_Block_Violet"
    },
    {
      "x": -3,
      "y": 17,
      "z": -10,
      "name": "Plant_Coral_Block_Pink"
    },
    {
      "x": -3,
      "y": 18,
      "z": -10,
      "name": "Plant_Coral_Block_Violet"
    },
    {
      "x": -3,
      "y": 19,
      "z": -10,
      "name": "Plant_Coral_Block_Violet"
    },
    {
      "x": -3,
      "y": 20,
      "z": -10,
      "name": "Plant_Coral_Block_Violet"
    },
    {
      "x": -3,
      "y": 17,
      "z": -9,
      "name": "Plant_Coral_Block_Violet"
    },
    {
      "x": -3,
      "y": 18,
      "z": -9,
      "name": "Plant_Coral_Bush_Violet"
    },
    {
      "x": -3,
      "y": 19,
      "z": -9,
      "name": "Plant_Coral_Block_Purple"
    },
    {
      "x": -3,
      "y": 17,
      "z": -8,
      "name": "Plant_Coral_Block_Purple"
    },
    {
      "x": -3,
      "y": 18,
      "z": -8,
      "name": "Plant_Coral_Bush_Purple"
    },
    {
      "x": -3,
      "y": 19,
      "z": -8,
      "name": "Plant_Coral_Bush_Purple"
    },
    {
      "x": -3,
      "y": 17,
      "z": -7,
      "name": "Plant_Coral_Block_Purple"
    },
    {
      "x": -3,
      "y": 18,
      "z": -7,
      "name": "Plant_Coral_Bush_Pink"
    },
    {
      "x": -3,
      "y": 19,
      "z": -7,
      "name": "Plant_Coral_Block_Purple"
    },
    {
      "x": -3,
      "y": 18,
      "z": -6,
      "name": "Plant_Coral_Block_Violet"
    },
    {
      "x": -3,
      "y": 16,
      "z": -2,
      "name": "Plant_Coral_Block_Violet"
    },
    {
      "x": -3,
      "y": 17,
      "z": -2,
      "name": "Plant_Coral_Bush_Pink"
    },
    {
      "x": -3,
      "y": 18,
      "z": -2,
      "name": "Plant_Coral_Bush_Pink"
    },
    {
      "x": -3,
      "y": 15,
      "z": -1,
      "name": "Plant_Coral_Bush_Violet"
    },
    {
      "x": -3,
      "y": 16,
      "z": -1,
      "name": "Plant_Coral_Bush_Pink"
    },
    {
      "x": -3,
      "y": 17,
      "z": -1,
      "name": "Plant_Coral_Block_Purple"
    },
    {
      "x": -3,
      "y": 18,
      "z": -1,
      "name": "Plant_Coral_Block_Violet"
    },
    {
      "x": -3,
      "y": 19,
      "z": -1,
      "name": "Plant_Coral_Block_Violet"
    },
    {
      "x": -3,
      "y": 15,
      "z": 0,
      "name": "Plant_Coral_Block_Purple"
    },
    {
      "x": -3,
      "y": 16,
      "z": 0,
      "name": "Plant_Coral_Block_Pink"
    },
    {
      "x": -3,
      "y": 17,
      "z": 0,
      "name": "Plant_Coral_Block_Pink"
    },
    {
      "x": -3,
      "y": 18,
      "z": 0,
      "name": "Plant_Coral_Bush_Pink"
    },
    {
      "x": -3,
      "y": 19,
      "z": 0,
      "name": "Plant_Coral_Bush_Purple"
    },
    {
      "x": -3,
      "y": 15,
      "z": 1,
      "name": "Plant_Coral_Block_Purple"
    },
    {
      "x": -3,
      "y": 16,
      "z": 1,
      "name": "Plant_Coral_Bush_Purple"
    },
    {
      "x": -3,
      "y": 17,
      "z": 1,
      "name": "Plant_Coral_Block_Pink"
    },
    {
      "x": -3,
      "y": 18,
      "z": 1,
      "name": "Plant_Coral_Bush_Violet"
    },
    {
      "x": -3,
      "y": 19,
      "z": 1,
      "name": "Plant_Coral_Bush_Violet"
    },
    {
      "x": -3,
      "y": 16,
      "z": 2,
      "name": "Plant_Coral_Bush_Pink"
    },
    {
      "x": -3,
      "y": 17,
      "z": 2,
      "name": "Plant_Coral_Bush_Pink"
    },
    {
      "x": -3,
      "y": 18,
      "z": 2,
      "name": "Plant_Coral_Bush_Violet"
    },
    {
      "x": -3,
      "y": 19,
      "z": 2,
      "name": "Plant_Coral_Block_Pink"
    },
    {
      "x": -3,
      "y": 18,
      "z": 3,
      "name": "Plant_Coral_Bush_Pink"
    },
    {
      "x": -3,
      "y": 18,
      "z": 4,
      "name": "Plant_Coral_Block_Violet"
    },
    {
      "x": -3,
      "y": 18,
      "z": 5,
      "name": "Plant_Coral_Bush_Violet"
    },
    {
      "x": -3,
      "y": 18,
      "z": 6,
      "name": "Plant_Coral_Bush_Purple"
    },
    {
      "x": -2,
      "y": 20,
      "z": -13,
      "name": "Plant_Coral_Bush_Purple"
    },
    {
      "x": -2,
      "y": 21,
      "z": -13,
      "name": "Plant_Coral_Block_Purple"
    },
    {
      "x": -2,
      "y": 19,
      "z": -12,
      "name": "Plant_Coral_Block_Pink"
    },
    {
      "x": -2,
      "y": 20,
      "z": -12,
      "name": "Plant_Coral_Bush_Purple"
    },
    {
      "x": -2,
      "y": 21,
      "z": -12,
      "name": "Plant_Coral_Bush_Pink"
    },
    {
      "x": -2,
      "y": 22,
      "z": -12,
      "name": "Plant_Coral_Bush_Pink"
    },
    {
      "x": -2,
      "y": 18,
      "z": -11,
      "name": "Plant_Coral_Block_Purple"
    },
    {
      "x": -2,
      "y": 19,
      "z": -11,
      "name": "Plant_Coral_Block_Pink"
    },
    {
      "x": -2,
      "y": 20,
      "z": -11,
      "name": "Plant_Coral_Block_Violet"
    },
    {
      "x": -2,
      "y": 21,
      "z": -11,
      "name": "Plant_Coral_Bush_Violet"
    },
    {
      "x": -2,
      "y": 17,
      "z": -10,
      "name": "Plant_Coral_Block_Purple"
    },
    {
      "x": -2,
      "y": 18,
      "z": -10,
      "name": "Plant_Coral_Bush_Pink"
    },
    {
      "x": -2,
      "y": 19,
      "z": -10,
      "name": "Plant_Coral_Bush_Violet"
    },
    {
      "x": -2,
      "y": 20,
      "z": -10,
      "name": "Plant_Coral_Bush_Pink"
    },
    {
      "x": -2,
      "y": 18,
      "z": -9,
      "name": "Plant_Coral_Bush_Purple"
    },
    {
      "x": -2,
      "y": 18,
      "z": -8,
      "name": "Plant_Coral_Bush_Pink"
    },
    {
      "x": -2,
      "y": 17,
      "z": -7,
      "name": "Plant_Coral_Bush_Pink"
    },
    {
      "x": -2,
      "y": 18,
      "z": -7,
      "name": "Plant_Coral_Bush_Violet"
    },
    {
      "x": -2,
      "y": 19,
      "z": -7,
      "name": "Plant_Coral_Bush_Purple"
    },
    {
      "x": -2,
      "y": 17,
      "z": -6,
      "name": "Plant_Coral_Bush_Purple"
    },
    {
      "x": -2,
      "y": 18,
      "z": -6,
      "name": "Plant_Coral_Bush_Violet"
    },
    {
      "x": -2,
      "y": 17,
      "z": -5,
      "name": "Plant_Coral_Block_Violet"
    },
    {
      "x": -2,
      "y": 16,
      "z": -4,
      "name": "Plant_Coral_Bush_Pink"
    },
    {
      "x": -2,
      "y": 17,
      "z": -4,
      "name": "Plant_Coral_Block_Violet"
    },
    {
      "x": -2,
      "y": 16,
      "z": -3,
      "name": "Plant_Coral_Bush_Purple"
    },
    {
      "x": -2,
      "y": 17,
      "z": -3,
      "name": "Plant_Coral_Bush_Violet"
    },
    {
      "x": -2,
      "y": 16,
      "z": -2,
      "name": "Plant_Coral_Block_Violet"
    },
    {
      "x": -2,
      "y": 17,
      "z": -2,
      "name": "Plant_Coral_Block_Pink"
    },
    {
      "x": -2,
      "y": 18,
      "z": -2,
      "name": "Plant_Coral_Block_Pink"
    },
    {
      "x": -2,
      "y": 15,
      "z": -1,
      "name": "Plant_Coral_Block_Purple"
    },
    {
      "x": -2,
      "y": 16,
      "z": -1,
      "name": "Plant_Coral_Block_Violet"
    },
    {
      "x": -2,
      "y": 17,
      "z": -1,
      "name": "Plant_Coral_Block_Purple"
    },
    {
      "x": -2,
      "y": 18,
      "z": -1,
      "name": "Plant_Coral_Bush_Purple"
    },
    {
      "x": -2,
      "y": 14,
      "z": 0,
      "name": "Plant_Coral_Block_Violet"
    },
    {
      "x": -2,
      "y": 15,
      "z": 0,
      "name": "Plant_Coral_Block_Pink"
    },
    {
      "x": -2,
      "y": 16,
      "z": 0,
      "name": "Plant_Coral_Block_Purple"
    },
    {
      "x": -2,
      "y": 17,
      "z": 0,
      "name": "Plant_Coral_Bush_Purple"
    },
    {
      "x": -2,
      "y": 18,
      "z": 0,
      "name": "Plant_Coral_Block_Purple"
    },
    {
      "x": -2,
      "y": 19,
      "z": 0,
      "name": "Plant_Coral_Bush_Violet"
    },
    {
      "x": -2,
      "y": 15,
      "z": 1,
      "name": "Plant_Coral_Bush_Violet"
    },
    {
      "x": -2,
      "y": 16,
      "z": 1,
      "name": "Plant_Coral_Bush_Violet"
    },
    {
      "x": -2,
      "y": 17,
      "z": 1,
      "name": "Plant_Coral_Block_Purple"
    },
    {
      "x": -2,
      "y": 18,
      "z": 1,
      "name": "Plant_Coral_Block_Purple"
    },
    {
      "x": -2,
      "y": 16,
      "z": 2,
      "name": "Plant_Coral_Bush_Violet"
    },
    {
      "x": -2,
      "y": 17,
      "z": 2,
      "name": "Plant_Coral_Block_Violet"
    },
    {
      "x": -2,
      "y": 18,
      "z": 2,
      "name": "Plant_Coral_Bush_Pink"
    },
    {
      "x": -2,
      "y": 17,
      "z": 3,
      "name": "Plant_Coral_Bush_Pink"
    },
    {
      "x": -2,
      "y": 17,
      "z": 4,
      "name": "Plant_Coral_Bush_Violet"
    },
    {
      "x": -1,
      "y": 20,
      "z": -12,
      "name": "Plant_Coral_Block_Pink"
    },
    {
      "x": -1,
      "y": 21,
      "z": -12,
      "name": "Plant_Coral_Bush_Purple"
    },
    {
      "x": -1,
      "y": 19,
      "z": -11,
      "name": "Plant_Coral_Bush_Pink"
    },
    {
      "x": -1,
      "y": 20,
      "z": -11,
      "name": "Plant_Coral_Block_Purple"
    },
    {
      "x": -1,
      "y": 18,
      "z": -10,
      "name": "Plant_Coral_Block_Pink"
    },
    {
      "x": -1,
      "y": 17,
      "z": -8,
      "name": "Plant_Coral_Bush_Purple"
    },
    {
      "x": -1,
      "y": 18,
      "z": -8,
      "name": "Plant_Coral_Bush_Violet"
    },
    {
      "x": -1,
      "y": 16,
      "z": -7,
      "name": "Plant_Coral_Block_Pink"
    },
    {
      "x": -1,
      "y": 17,
      "z": -7,
      "name": "Plant_Coral_Bush_Pink"
    },
    {
      "x": -1,
      "y": 18,
      "z": -7,
      "name": "Plant_Coral_Bush_Pink"
    },
    {
      "x": -1,
      "y": 19,
      "z": -7,
      "name": "Plant_Coral_Bush_Pink"
    },
    {
      "x": -1,
      "y": 16,
      "z": -6,
      "name": "Plant_Coral_Block_Purple"
    },
    {
      "x": -1,
      "y": 17,
      "z": -6,
      "name": "Plant_Coral_Block_Pink"
    },
    {
      "x": -1,
      "y": 18,
      "z": -6,
      "name": "Plant_Coral_Block_Purple"
    },
    {
      "x": -1,
      "y": 16,
      "z": -5,
      "name": "Plant_Coral_Block_Pink"
    },
    {
      "x": -1,
      "y": 17,
      "z": -5,
      "name": "Plant_Coral_Bush_Pink"
    },
    {
      "x": -1,
      "y": 18,
      "z": -5,
      "name": "Plant_Coral_Bush_Violet"
    },
    {
      "x": -1,
      "y": 15,
      "z": -4,
      "name": "Plant_Coral_Block_Pink"
    },
    {
      "x": -1,
      "y": 16,
      "z": -4,
      "name": "Plant_Coral_Block_Pink"
    },
    {
      "x": -1,
      "y": 17,
      "z": -4,
      "name": "Plant_Coral_Block_Pink"
    },
    {
      "x": -1,
      "y": 18,
      "z": -4,
      "name": "Plant_Coral_Bush_Violet"
    },
    {
      "x": -1,
      "y": 15,
      "z": -3,
      "name": "Plant_Coral_Block_Violet"
    },
    {
      "x": -1,
      "y": 16,
      "z": -3,
      "name": "Plant_Coral_Block_Purple"
    },
    {
      "x": -1,
      "y": 17,
      "z": -3,
      "name": "Plant_Coral_Bush_Pink"
    },
    {
      "x": -1,
      "y": 15,
      "z": -2,
      "name": "Plant_Coral_Bush_Pink"
    },
    {
      "x": -1,
      "y": 16,
      "z": -2,
      "name": "Plant_Coral_Bush_Pink"
    },
    {
      "x": -1,
      "y": 17,
      "z": -2,
      "name": "Plant_Coral_Bush_Purple"
    },
    {
      "x": -1,
      "y": 18,
      "z": -2,
      "name": "Plant_Coral_Bush_Violet"
    },
    {
      "x": -1,
      "y": 14,
      "z": -1,
      "name": "Plant_Coral_Bush_Violet"
    },
    {
      "x": -1,
      "y": 15,
      "z": -1,
      "name": "Plant_Coral_Bush_Pink"
    },
    {
      "x": -1,
      "y": 16,
      "z": -1,
      "name": "Plant_Coral_Bush_Pink"
    },
    {
      "x": -1,
      "y": 17,
      "z": -1,
      "name": "Plant_Coral_Block_Pink"
    },
    {
      "x": -1,
      "y": 18,
      "z": -1,
      "name": "Plant_Coral_Block_Violet"
    },
    {
      "x": -1,
      "y": 14,
      "z": 0,
      "name": "Plant_Coral_Block_Purple"
    },
    {
      "x": -1,
      "y": 15,
      "z": 0,
      "name": "Plant_Coral_Bush_Purple"
    },
    {
      "x": -1,
      "y": 16,
      "z": 0,
      "name": "Plant_Coral_Bush_Pink"
    },
    {
      "x": -1,
      "y": 17,
      "z": 0,
      "name": "Plant_Coral_Block_Violet"
    },
    {
      "x": -1,
      "y": 18,
      "z": 0,
      "name": "Plant_Coral_Block_Purple"
    },
    {
      "x": -1,
      "y": 14,
      "z": 1,
      "name": "Plant_Coral_Block_Purple"
    },
    {
      "x": -1,
      "y": 15,
      "z": 1,
      "name": "Plant_Coral_Block_Purple"
    },
    {
      "x": -1,
      "y": 16,
      "z": 1,
      "name": "Plant_Coral_Block_Violet"
    },
    {
      "x": -1,
      "y": 17,
      "z": 1,
      "name": "Plant_Coral_Block_Purple"
    },
    {
      "x": -1,
      "y": 18,
      "z": 1,
      "name": "Plant_Coral_Block_Violet"
    },
    {
      "x": -1,
      "y": 15,
      "z": 2,
      "name": "Plant_Coral_Bush_Purple"
    },
    {
      "x": -1,
      "y": 16,
      "z": 2,
      "name": "Plant_Coral_Block_Pink"
    },
    {
      "x": -1,
      "y": 17,
      "z": 2,
      "name": "Plant_Coral_Block_Pink"
    },
    {
      "x": -1,
      "y": 18,
      "z": 2,
      "name": "Plant_Coral_Bush_Pink"
    },
    {
      "x": -1,
      "y": 19,
      "z": 2,
      "name": "Plant_Coral_Block_Pink"
    },
    {
      "x": -1,
      "y": 16,
      "z": 3,
      "name": "Plant_Coral_Bush_Pink"
    },
    {
      "x": -1,
      "y": 17,
      "z": 3,
      "name": "Plant_Coral_Bush_Violet"
    },
    {
      "x": -1,
      "y": 18,
      "z": 3,
      "name": "Plant_Coral_Bush_Violet"
    },
    {
      "x": -1,
      "y": 16,
      "z": 4,
      "name": "Plant_Coral_Bush_Violet"
    },
    {
      "x": -1,
      "y": 17,
      "z": 4,
      "name": "Plant_Coral_Bush_Purple"
    },
    {
      "x": -1,
      "y": 18,
      "z": 4,
      "name": "Plant_Coral_Bush_Violet"
    },
    {
      "x": -1,
      "y": 17,
      "z": 5,
      "name": "Plant_Coral_Block_Purple"
    },
    {
      "x": 0,
      "y": 17,
      "z": -7,
      "name": "Plant_Coral_Bush_Purple"
    },
    {
      "x": 0,
      "y": 18,
      "z": -7,
      "name": "Plant_Coral_Block_Violet"
    },
    {
      "x": 0,
      "y": 17,
      "z": -6,
      "name": "Plant_Coral_Bush_Violet"
    },
    {
      "x": 0,
      "y": 17,
      "z": -5,
      "name": "Plant_Coral_Block_Pink"
    },
    {
      "x": 0,
      "y": 16,
      "z": -4,
      "name": "Plant_Coral_Bush_Purple"
    },
    {
      "x": 0,
      "y": 17,
      "z": -4,
      "name": "Plant_Coral_Block_Violet"
    },
    {
      "x": 0,
      "y": 16,
      "z": -3,
      "name": "Plant_Coral_Bush_Violet"
    },
    {
      "x": 0,
      "y": 16,
      "z": -2,
      "name": "Plant_Coral_Block_Pink"
    },
    {
      "x": 0,
      "y": 17,
      "z": -2,
      "name": "Plant_Coral_Bush_Violet"
    },
    {
      "x": 0,
      "y": 15,
      "z": -1,
      "name": "Plant_Coral_Block_Violet"
    },
    {
      "x": 0,
      "y": 16,
      "z": -1,
      "name": "Plant_Coral_Bush_Purple"
    },
    {
      "x": 0,
      "y": 17,
      "z": -1,
      "name": "Plant_Coral_Bush_Purple"
    },
    {
      "x": 0,
      "y": 14,
      "z": 0,
      "name": "Plant_Coral_Block_Pink"
    },
    {
      "x": 0,
      "y": 15,
      "z": 0,
      "name": "Plant_Coral_Block_Pink"
    },
    {
      "x": 0,
      "y": 16,
      "z": 0,
      "name": "Plant_Coral_Block_Purple"
    },
    {
      "x": 0,
      "y": 17,
      "z": 0,
      "name": "Plant_Coral_Bush_Purple"
    },
    {
      "x": 0,
      "y": 18,
      "z": 0,
      "name": "Plant_Coral_Block_Purple"
    },
    {
      "x": 0,
      "y": 14,
      "z": 1,
      "name": "Plant_Coral_Block_Violet"
    },
    {
      "x": 0,
      "y": 15,
      "z": 1,
      "name": "Plant_Coral_Bush_Purple"
    },
    {
      "x": 0,
      "y": 16,
      "z": 1,
      "name": "Plant_Coral_Bush_Purple"
    },
    {
      "x": 0,
      "y": 17,
      "z": 1,
      "name": "Plant_Coral_Block_Purple"
    },
    {
      "x": 0,
      "y": 18,
      "z": 1,
      "name": "Plant_Coral_Block_Pink"
    },
    {
      "x": 0,
      "y": 15,
      "z": 2,
      "name": "Plant_Coral_Block_Pink"
    },
    {
      "x": 0,
      "y": 16,
      "z": 2,
      "name": "Plant_Coral_Bush_Pink"
    },
    {
      "x": 0,
      "y": 17,
      "z": 2,
      "name": "Plant_Coral_Bush_Violet"
    },
    {
      "x": 0,
      "y": 18,
      "z": 2,
      "name": "Plant_Coral_Bush_Purple"
    },
    {
      "x": 0,
      "y": 16,
      "z": 3,
      "name": "Plant_Coral_Bush_Pink"
    },
    {
      "x": 0,
      "y": 17,
      "z": 3,
      "name": "Plant_Coral_Block_Purple"
    },
    {
      "x": 0,
      "y": 18,
      "z": 3,
      "name": "Plant_Coral_Block_Violet"
    },
    {
      "x": 0,
      "y": 16,
      "z": 4,
      "name": "Plant_Coral_Block_Purple"
    },
    {
      "x": 0,
      "y": 17,
      "z": 4,
      "name": "Plant_Coral_Bush_Purple"
    },
    {
      "x": 0,
      "y": 18,
      "z": 4,
      "name": "Plant_Coral_Block_Purple"
    },
    {
      "x": 0,
      "y": 17,
      "z": 5,
      "name": "Plant_Coral_Bush_Pink"
    },
    {
      "x": 0,
      "y": 19,
      "z": 11,
      "name": "Plant_Coral_Block_Violet"
    },
    {
      "x": 0,
      "y": 20,
      "z": 11,
      "name": "Plant_Coral_Bush_Violet"
    },
    {
      "x": 0,
      "y": 21,
      "z": 11,
      "name": "Plant_Coral_Block_Purple"
    },
    {
      "x": 0,
      "y": 20,
      "z": 12,
      "name": "Plant_Coral_Bush_Purple"
    },
    {
      "x": 0,
      "y": 21,
      "z": 12,
      "name": "Plant_Coral_Block_Purple"
    },
    {
      "x": 0,
      "y": 22,
      "z": 12,
      "name": "Plant_Coral_Bush_Pink"
    },
    {
      "x": 1,
      "y": 15,
      "z": -1,
      "name": "Plant_Coral_Bush_Pink"
    },
    {
      "x": 1,
      "y": 16,
      "z": -1,
      "name": "Plant_Coral_Bush_Purple"
    },
    {
      "x": 1,
      "y": 17,
      "z": -1,
      "name": "Plant_Coral_Bush_Pink"
    },
    {
      "x": 1,
      "y": 14,
      "z": 0,
      "name": "Plant_Coral_Block_Violet"
    },
    {
      "x": 1,
      "y": 15,
      "z": 0,
      "name": "Plant_Coral_Block_Pink"
    },
    {
      "x": 1,
      "y": 16,
      "z": 0,
      "name": "Plant_Coral_Bush_Violet"
    },
    {
      "x": 1,
      "y": 17,
      "z": 0,
      "name": "Plant_Coral_Block_Purple"
    },
    {
      "x": 1,
      "y": 18,
      "z": 0,
      "name": "Plant_Coral_Block_Violet"
    },
    {
      "x": 1,
      "y": 14,
      "z": 1,
      "name": "Plant_Coral_Bush_Violet"
    },
    {
      "x": 1,
      "y": 15,
      "z": 1,
      "name": "Plant_Coral_Block_Violet"
    },
    {
      "x": 1,
      "y": 16,
      "z": 1,
      "name": "Plant_Coral_Block_Pink"
    },
    {
      "x": 1,
      "y": 17,
      "z": 1,
      "name": "Plant_Coral_Block_Purple"
    },
    {
      "x": 1,
      "y": 18,
      "z": 1,
      "name": "Plant_Coral_Bush_Violet"
    },
    {
      "x": 1,
      "y": 5,
      "z": 2,
      "name": "Plant_Coral_Block_Pink"
    },
    {
      "x": 1,
      "y": 14,
      "z": 2,
      "name": "Plant_Coral_Bush_Pink"
    },
    {
      "x": 1,
      "y": 15,
      "z": 2,
      "name": "Plant_Coral_Block_Purple"
    },
    {
      "x": 1,
      "y": 16,
      "z": 2,
      "name": "Plant_Coral_Block_Pink"
    },
    {
      "x": 1,
      "y": 17,
      "z": 2,
      "name": "Plant_Coral_Block_Purple"
    },
    {
      "x": 1,
      "y": 18,
      "z": 2,
      "name": "Plant_Coral_Block_Purple"
    },
    {
      "x": 1,
      "y": 15,
      "z": 3,
      "name": "Plant_Coral_Bush_Purple"
    },
    {
      "x": 1,
      "y": 16,
      "z": 3,
      "name": "Plant_Coral_Bush_Pink"
    },
    {
      "x": 1,
      "y": 17,
      "z": 3,
      "name": "Plant_Coral_Bush_Pink"
    },
    {
      "x": 1,
      "y": 18,
      "z": 3,
      "name": "Plant_Coral_Bush_Pink"
    },
    {
      "x": 1,
      "y": 16,
      "z": 4,
      "name": "Plant_Coral_Block_Purple"
    },
    {
      "x": 1,
      "y": 17,
      "z": 4,
      "name": "Plant_Coral_Block_Pink"
    },
    {
      "x": 1,
      "y": 18,
      "z": 4,
      "name": "Plant_Coral_Block_Pink"
    },
    {
      "x": 1,
      "y": 16,
      "z": 5,
      "name": "Plant_Coral_Bush_Purple"
    },
    {
      "x": 1,
      "y": 17,
      "z": 5,
      "name": "Plant_Coral_Bush_Pink"
    },
    {
      "x": 1,
      "y": 18,
      "z": 5,
      "name": "Plant_Coral_Bush_Purple"
    },
    {
      "x": 1,
      "y": 17,
      "z": 6,
      "name": "Plant_Coral_Bush_Violet"
    },
    {
      "x": 1,
      "y": 18,
      "z": 10,
      "name": "Plant_Coral_Block_Pink"
    },
    {
      "x": 1,
      "y": 19,
      "z": 10,
      "name": "Plant_Coral_Bush_Purple"
    },
    {
      "x": 1,
      "y": 20,
      "z": 10,
      "name": "Plant_Coral_Bush_Violet"
    },
    {
      "x": 1,
      "y": 21,
      "z": 10,
      "name": "Plant_Coral_Bush_Purple"
    },
    {
      "x": 1,
      "y": 18,
      "z": 11,
      "name": "Plant_Coral_Block_Purple"
    },
    {
      "x": 1,
      "y": 19,
      "z": 11,
      "name": "Plant_Coral_Bush_Purple"
    },
    {
      "x": 1,
      "y": 20,
      "z": 11,
      "name": "Plant_Coral_Block_Violet"
    },
    {
      "x": 1,
      "y": 21,
      "z": 11,
      "name": "Plant_Coral_Block_Violet"
    },
    {
      "x": 1,
      "y": 22,
      "z": 11,
      "name": "Plant_Coral_Bush_Purple"
    },
    {
      "x": 1,
      "y": 19,
      "z": 12,
      "name": "Plant_Coral_Bush_Pink"
    },
    {
      "x": 1,
      "y": 20,
      "z": 12,
      "name": "Plant_Coral_Bush_Violet"
    },
    {
      "x": 1,
      "y": 21,
      "z": 12,
      "name": "Plant_Coral_Bush_Purple"
    },
    {
      "x": 1,
      "y": 22,
      "z": 12,
      "name": "Plant_Coral_Bush_Violet"
    },
    {
      "x": 1,
      "y": 23,
      "z": 12,
      "name": "Plant_Coral_Block_Violet"
    },
    {
      "x": 1,
      "y": 20,
      "z": 13,
      "name": "Plant_Coral_Bush_Violet"
    },
    {
      "x": 1,
      "y": 21,
      "z": 13,
      "name": "Plant_Coral_Bush_Pink"
    },
    {
      "x": 1,
      "y": 22,
      "z": 13,
      "name": "Plant_Coral_Block_Purple"
    },
    {
      "x": 2,
      "y": 3,
      "z": -1,
      "name": "Rock_Lime"
    },
    {
      "x": 2,
      "y": 15,
      "z": -1,
      "name": "Plant_Coral_Bush_Pink"
    },
    {
      "x": 2,
      "y": 16,
      "z": -1,
      "name": "Plant_Coral_Bush_Purple"
    },
    {
      "x": 2,
      "y": 2,
      "z": 0,
      "name": "Rock_Lime"
    },
    {
      "x": 2,
      "y": 5,
      "z": 0,
      "name": "Plant_Coral_Block_Pink"
    },
    {
      "x": 2,
      "y": 14,
      "z": 0,
      "name": "Plant_Coral_Block_Violet"
    },
    {
      "x": 2,
      "y": 15,
      "z": 0,
      "name": "Plant_Coral_Block_Purple"
    },
    {
      "x": 2,
      "y": 16,
      "z": 0,
      "name": "Plant_Coral_Block_Pink"
    },
    {
      "x": 2,
      "y": 17,
      "z": 0,
      "name": "Plant_Coral_Bush_Violet"
    },
    {
      "x": 2,
      "y": 5,
      "z": 1,
      "name": "Plant_Coral_Block_Purple"
    },
    {
      "x": 2,
      "y": 12,
      "z": 1,
      "name": "Plant_Coral_Block_Pink"
    },
    {
      "x": 2,
      "y": 13,
      "z": 1,
      "name": "Plant_Coral_Bush_Purple"
    },
    {
      "x": 2,
      "y": 14,
      "z": 1,
      "name": "Plant_Coral_Bush_Pink"
    },
    {
      "x": 2,
      "y": 15,
      "z": 1,
      "name": "Plant_Coral_Bush_Violet"
    },
    {
      "x": 2,
      "y": 16,
      "z": 1,
      "name": "Plant_Coral_Block_Violet"
    },
    {
      "x": 2,
      "y": 17,
      "z": 1,
      "name": "Plant_Coral_Block_Purple"
    },
    {
      "x": 2,
      "y": 18,
      "z": 1,
      "name": "Plant_Coral_Bush_Violet"
    },
    {
      "x": 2,
      "y": 2,
      "z": 2,
      "name": "Rock_Lime"
    },
    {
      "x": 2,
      "y": 3,
      "z": 2,
      "name": "Rock_Lime"
    },
    {
      "x": 2,
      "y": 4,
      "z": 2,
      "name": "Plant_Coral_Block_Purple"
    },
    {
      "x": 2,
      "y": 5,
      "z": 2,
      "name": "Plant_Coral_Block_Pink"
    },
    {
      "x": 2,
      "y": 6,
      "z": 2,
      "name": "Plant_Coral_Block_Violet"
    },
    {
      "x": 2,
      "y": 11,
      "z": 2,
      "name": "Plant_Coral_Bush_Violet"
    },
    {
      "x": 2,
      "y": 12,
      "z": 2,
      "name": "Plant_Coral_Block_Purple"
    },
    {
      "x": 2,
      "y": 13,
      "z": 2,
      "name": "Plant_Coral_Block_Purple"
    },
    {
      "x": 2,
      "y": 14,
      "z": 2,
      "name": "Plant_Coral_Bush_Violet"
    },
    {
      "x": 2,
      "y": 15,
      "z": 2,
      "name": "Plant_Coral_Block_Pink"
    },
    {
      "x": 2,
      "y": 16,
      "z": 2,
      "name": "Plant_Coral_Block_Violet"
    },
    {
      "x": 2,
      "y": 17,
      "z": 2,
      "name": "Plant_Coral_Block_Purple"
    },
    {
      "x": 2,
      "y": 3,
      "z": 3,
      "name": "Rock_Lime"
    },
    {
      "x": 2,
      "y": 5,
      "z": 3,
      "name": "Plant_Coral_Block_Pink"
    },
    {
      "x": 2,
      "y": 12,
      "z": 3,
      "name": "Plant_Coral_Bush_Violet"
    },
    {
      "x": 2,
      "y": 15,
      "z": 3,
      "name": "Plant_Coral_Block_Violet"
    },
    {
      "x": 2,
      "y": 16,
      "z": 3,
      "name": "Plant_Coral_Block_Pink"
    },
    {
      "x": 2,
      "y": 17,
      "z": 3,
      "name": "Plant_Coral_Bush_Pink"
    },
    {
      "x": 2,
      "y": 16,
      "z": 4,
      "name": "Plant_Coral_Bush_Purple"
    },
    {
      "x": 2,
      "y": 17,
      "z": 4,
      "name": "Plant_Coral_Bush_Violet"
    },
    {
      "x": 2,
      "y": 18,
      "z": 4,
      "name": "Plant_Coral_Block_Pink"
    },
    {
      "x": 2,
      "y": 16,
      "z": 5,
      "name": "Plant_Coral_Block_Pink"
    },
    {
      "x": 2,
      "y": 17,
      "z": 5,
      "name": "Plant_Coral_Block_Purple"
    },
    {
      "x": 2,
      "y": 18,
      "z": 5,
      "name": "Plant_Coral_Block_Pink"
    },
    {
      "x": 2,
      "y": 16,
      "z": 6,
      "name": "Plant_Coral_Bush_Violet"
    },
    {
      "x": 2,
      "y": 17,
      "z": 6,
      "name": "Plant_Coral_Block_Purple"
    },
    {
      "x": 2,
      "y": 18,
      "z": 6,
      "name": "Plant_Coral_Block_Violet"
    },
    {
      "x": 2,
      "y": 17,
      "z": 7,
      "name": "Plant_Coral_Block_Pink"
    },
    {
      "x": 2,
      "y": 17,
      "z": 8,
      "name": "Plant_Coral_Bush_Purple"
    },
    {
      "x": 2,
      "y": 18,
      "z": 9,
      "name": "Plant_Coral_Bush_Purple"
    },
    {
      "x": 2,
      "y": 17,
      "z": 10,
      "name": "Plant_Coral_Bush_Purple"
    },
    {
      "x": 2,
      "y": 18,
      "z": 10,
      "name": "Plant_Coral_Bush_Pink"
    },
    {
      "x": 2,
      "y": 19,
      "z": 10,
      "name": "Plant_Coral_Bush_Violet"
    },
    {
      "x": 2,
      "y": 20,
      "z": 10,
      "name": "Plant_Coral_Bush_Purple"
    },
    {
      "x": 2,
      "y": 17,
      "z": 11,
      "name": "Plant_Coral_Bush_Purple"
    },
    {
      "x": 2,
      "y": 18,
      "z": 11,
      "name": "Plant_Coral_Block_Pink"
    },
    {
      "x": 2,
      "y": 19,
      "z": 11,
      "name": "Plant_Coral_Bush_Violet"
    },
    {
      "x": 2,
      "y": 20,
      "z": 11,
      "name": "Plant_Coral_Block_Purple"
    },
    {
      "x": 2,
      "y": 21,
      "z": 11,
      "name": "Plant_Coral_Bush_Violet"
    },
    {
      "x": 2,
      "y": 18,
      "z": 12,
      "name": "Plant_Coral_Block_Pink"
    },
    {
      "x": 2,
      "y": 19,
      "z": 12,
      "name": "Plant_Coral_Bush_Purple"
    },
    {
      "x": 2,
      "y": 20,
      "z": 12,
      "name": "Plant_Coral_Block_Purple"
    },
    {
      "x": 2,
      "y": 21,
      "z": 12,
      "name": "Plant_Coral_Bush_Pink"
    },
    {
      "x": 2,
      "y": 22,
      "z": 12,
      "name": "Plant_Coral_Bush_Purple"
    },
    {
      "x": 3,
      "y": 2,
      "z": -2,
      "name": "Rock_Lime"
    },
    {
      "x": 3,
      "y": 8,
      "z": -2,
      "name": "Plant_Coral_Block_Purple"
    },
    {
      "x": 3,
      "y": 14,
      "z": -2,
      "name": "Plant_Coral_Block_Pink"
    },
    {
      "x": 3,
      "y": 1,
      "z": -1,
      "name": "Rock_Lime_Cobble"
    },
    {
      "x": 3,
      "y": 2,
      "z": -1,
      "name": "Rock_Lime"
    },
    {
      "x": 3,
      "y": 3,
      "z": -1,
      "name": "Rock_Lime"
    },
    {
      "x": 3,
      "y": 4,
      "z": -1,
      "name": "Plant_Coral_Block_Violet"
    },
    {
      "x": 3,
      "y": 5,
      "z": -1,
      "name": "Plant_Coral_Block_Purple"
    },
    {
      "x": 3,
      "y": 7,
      "z": -1,
      "name": "Plant_Coral_Bush_Violet"
    },
    {
      "x": 3,
      "y": 8,
      "z": -1,
      "name": "Plant_Coral_Bush_Violet"
    },
    {
      "x": 3,
      "y": 9,
      "z": -1,
      "name": "Plant_Coral_Bush_Pink"
    },
    {
      "x": 3,
      "y": 12,
      "z": -1,
      "name": "Plant_Coral_Block_Violet"
    },
    {
      "x": 3,
      "y": 15,
      "z": -1,
      "name": "Plant_Coral_Bush_Violet"
    },
    {
      "x": 3,
      "y": 16,
      "z": -1,
      "name": "Plant_Coral_Block_Purple"
    },
    {
      "x": 3,
      "y": 1,
      "z": 0,
      "name": "Rock_Lime"
    },
    {
      "x": 3,
      "y": 2,
      "z": 0,
      "name": "Rock_Lime"
    },
    {
      "x": 3,
      "y": 3,
      "z": 0,
      "name": "Rock_Lime"
    },
    {
      "x": 3,
      "y": 4,
      "z": 0,
      "name": "Plant_Coral_Block_Pink"
    },
    {
      "x": 3,
      "y": 5,
      "z": 0,
      "name": "Plant_Coral_Block_Pink"
    },
    {
      "x": 3,
      "y": 6,
      "z": 0,
      "name": "Plant_Coral_Block_Pink"
    },
    {
      "x": 3,
      "y": 8,
      "z": 0,
      "name": "Plant_Coral_Bush_Purple"
    },
    {
      "x": 3,
      "y": 10,
      "z": 0,
      "name": "Plant_Coral_Block_Purple"
    },
    {
      "x": 3,
      "y": 11,
      "z": 0,
      "name": "Plant_Coral_Bush_Pink"
    },
    {
      "x": 3,
      "y": 12,
      "z": 0,
      "name": "Plant_Coral_Block_Purple"
    },
    {
      "x": 3,
      "y": 13,
      "z": 0,
      "name": "Plant_Coral_Block_Violet"
    },
    {
      "x": 3,
      "y": 14,
      "z": 0,
      "name": "Plant_Coral_Block_Purple"
    },
    {
      "x": 3,
      "y": 15,
      "z": 0,
      "name": "Plant_Coral_Block_Violet"
    },
    {
      "x": 3,
      "y": 16,
      "z": 0,
      "name": "Plant_Coral_Block_Pink"
    },
    {
      "x": 3,
      "y": 17,
      "z": 0,
      "name": "Plant_Coral_Bush_Violet"
    },
    {
      "x": 3,
      "y": 1,
      "z": 1,
      "name": "Rock_Lime"
    },
    {
      "x": 3,
      "y": 2,
      "z": 1,
      "name": "Rock_Lime"
    },
    {
      "x": 3,
      "y": 3,
      "z": 1,
      "name": "Rock_Lime"
    },
    {
      "x": 3,
      "y": 4,
      "z": 1,
      "name": "Plant_Coral_Block_Violet"
    },
    {
      "x": 3,
      "y": 5,
      "z": 1,
      "name": "Plant_Coral_Block_Pink"
    },
    {
      "x": 3,
      "y": 6,
      "z": 1,
      "name": "Plant_Coral_Block_Purple"
    },
    {
      "x": 3,
      "y": 7,
      "z": 1,
      "name": "Plant_Coral_Bush_Purple"
    },
    {
      "x": 3,
      "y": 9,
      "z": 1,
      "name": "Plant_Coral_Block_Pink"
    },
    {
      "x": 3,
      "y": 10,
      "z": 1,
      "name": "Plant_Coral_Bush_Pink"
    },
    {
      "x": 3,
      "y": 11,
      "z": 1,
      "name": "Plant_Coral_Bush_Pink"
    },
    {
      "x": 3,
      "y": 12,
      "z": 1,
      "name": "Plant_Coral_Bush_Pink"
    },
    {
      "x": 3,
      "y": 13,
      "z": 1,
      "name": "Plant_Coral_Bush_Pink"
    },
    {
      "x": 3,
      "y": 14,
      "z": 1,
      "name": "Plant_Coral_Block_Pink"
    },
    {
      "x": 3,
      "y": 15,
      "z": 1,
      "name": "Plant_Coral_Bush_Pink"
    },
    {
      "x": 3,
      "y": 16,
      "z": 1,
      "name": "Plant_Coral_Bush_Purple"
    },
    {
      "x": 3,
      "y": 17,
      "z": 1,
      "name": "Plant_Coral_Block_Violet"
    },
    {
      "x": 3,
      "y": 1,
      "z": 2,
      "name": "Rock_Lime_Cobble"
    },
    {
      "x": 3,
      "y": 2,
      "z": 2,
      "name": "Rock_Lime_Cobble"
    },
    {
      "x": 3,
      "y": 3,
      "z": 2,
      "name": "Plant_Coral_Block_Purple"
    },
    {
      "x": 3,
      "y": 4,
      "z": 2,
      "name": "Plant_Coral_Block_Purple"
    },
    {
      "x": 3,
      "y": 5,
      "z": 2,
      "name": "Plant_Coral_Block_Violet"
    },
    {
      "x": 3,
      "y": 6,
      "z": 2,
      "name": "Plant_Coral_Block_Violet"
    },
    {
      "x": 3,
      "y": 7,
      "z": 2,
      "name": "Plant_Coral_Bush_Violet"
    },
    {
      "x": 3,
      "y": 10,
      "z": 2,
      "name": "Plant_Coral_Block_Violet"
    },
    {
      "x": 3,
      "y": 11,
      "z": 2,
      "name": "Plant_Coral_Block_Purple"
    },
    {
      "x": 3,
      "y": 12,
      "z": 2,
      "name": "Plant_Coral_Bush_Pink"
    },
    {
      "x": 3,
      "y": 13,
      "z": 2,
      "name": "Plant_Coral_Block_Pink"
    },
    {
      "x": 3,
      "y": 14,
      "z": 2,
      "name": "Plant_Coral_Block_Purple"
    },
    {
      "x": 3,
      "y": 15,
      "z": 2,
      "name": "Plant_Coral_Block_Pink"
    },
    {
      "x": 3,
      "y": 16,
      "z": 2,
      "name": "Plant_Coral_Bush_Purple"
    },
    {
      "x": 3,
      "y": 17,
      "z": 2,
      "name": "Plant_Coral_Block_Pink"
    },
    {
      "x": 3,
      "y": 2,
      "z": 3,
      "name": "Rock_Lime_Cobble"
    },
    {
      "x": 3,
      "y": 3,
      "z": 3,
      "name": "Rock_Lime_Cobble"
    },
    {
      "x": 3,
      "y": 4,
      "z": 3,
      "name": "Plant_Coral_Block_Purple"
    },
    {
      "x": 3,
      "y": 5,
      "z": 3,
      "name": "Plant_Coral_Block_Pink"
    },
    {
      "x": 3,
      "y": 6,
      "z": 3,
      "name": "Plant_Coral_Block_Purple"
    },
    {
      "x": 3,
      "y": 11,
      "z": 3,
      "name": "Plant_Coral_Block_Purple"
    },
    {
      "x": 3,
      "y": 12,
      "z": 3,
      "name": "Plant_Coral_Bush_Purple"
    },
    {
      "x": 3,
      "y": 13,
      "z": 3,
      "name": "Plant_Coral_Bush_Purple"
    },
    {
      "x": 3,
      "y": 14,
      "z": 3,
      "name": "Plant_Coral_Block_Pink"
    },
    {
      "x": 3,
      "y": 15,
      "z": 3,
      "name": "Plant_Coral_Block_Violet"
    },
    {
      "x": 3,
      "y": 16,
      "z": 3,
      "name": "Plant_Coral_Block_Pink"
    },
    {
      "x": 3,
      "y": 2,
      "z": 4,
      "name": "Rock_Lime"
    },
    {
      "x": 3,
      "y": 5,
      "z": 4,
      "name": "Plant_Coral_Block_Purple"
    },
    {
      "x": 3,
      "y": 6,
      "z": 4,
      "name": "Plant_Coral_Bush_Purple"
    },
    {
      "x": 3,
      "y": 12,
      "z": 4,
      "name": "Plant_Coral_Block_Purple"
    },
    {
      "x": 3,
      "y": 17,
      "z": 4,
      "name": "Plant_Coral_Bush_Pink"
    },
    {
      "x": 3,
      "y": 17,
      "z": 5,
      "name": "Plant_Coral_Bush_Purple"
    },
    {
      "x": 3,
      "y": 16,
      "z": 6,
      "name": "Plant_Coral_Bush_Pink"
    },
    {
      "x": 3,
      "y": 17,
      "z": 6,
      "name": "Plant_Coral_Bush_Pink"
    },
    {
      "x": 3,
      "y": 18,
      "z": 6,
      "name": "Plant_Coral_Block_Purple"
    },
    {
      "x": 3,
      "y": 16,
      "z": 7,
      "name": "Plant_Coral_Block_Pink"
    },
    {
      "x": 3,
      "y": 17,
      "z": 7,
      "name": "Plant_Coral_Block_Pink"
    },
    {
      "x": 3,
      "y": 18,
      "z": 7,
      "name": "Plant_Coral_Block_Pink"
    },
    {
      "x": 3,
      "y": 16,
      "z": 8,
      "name": "Plant_Coral_Bush_Pink"
    },
    {
      "x": 3,
      "y": 17,
      "z": 8,
      "name": "Plant_Coral_Block_Violet"
    },
    {
      "x": 3,
      "y": 18,
      "z": 8,
      "name": "Plant_Coral_Block_Pink"
    },
    {
      "x": 3,
      "y": 17,
      "z": 9,
      "name": "Plant_Coral_Block_Purple"
    },
    {
      "x": 3,
      "y": 18,
      "z": 9,
      "name": "Plant_Coral_Bush_Pink"
    },
    {
      "x": 3,
      "y": 19,
      "z": 9,
      "name": "Plant_Coral_Bush_Purple"
    },
    {
      "x": 3,
      "y": 17,
      "z": 10,
      "name": "Plant_Coral_Bush_Purple"
    },
    {
      "x": 3,
      "y": 18,
      "z": 10,
      "name": "Plant_Coral_Bush_Purple"
    },
    {
      "x": 3,
      "y": 19,
      "z": 10,
      "name": "Plant_Coral_Bush_Purple"
    },
    {
      "x": 3,
      "y": 20,
      "z": 10,
      "name": "Plant_Coral_Bush_Pink"
    },
    {
      "x": 3,
      "y": 18,
      "z": 11,
      "name": "Plant_Coral_Bush_Purple"
    },
    {
      "x": 3,
      "y": 19,
      "z": 11,
      "name": "Plant_Coral_Block_Pink"
    },
    {
      "x": 3,
      "y": 20,
      "z": 11,
      "name": "Plant_Coral_Bush_Pink"
    },
    {
      "x": 4,
      "y": 2,
      "z": -3,
      "name": "Rock_Lime_Cobble"
    },
    {
      "x": 4,
      "y": 8,
      "z": -3,
      "name": "Plant_Coral_Block_Violet"
    },
    {
      "x": 4,
      "y": 1,
      "z": -2,
      "name": "Soil_Gravel_Lime"
    },
    {
      "x": 4,
      "y": 2,
      "z": -2,
      "name": "Rock_Lime_Cobble"
    },
    {
      "x": 4,
      "y": 3,
      "z": -2,
      "name": "Rock_Lime_Cobble"
    },
    {
      "x": 4,
      "y": 4,
      "z": -2,
      "name": "Plant_Coral_Block_Violet"
    },
    {
      "x": 4,
      "y": 5,
      "z": -2,
      "name": "Plant_Coral_Block_Purple"
    },
    {
      "x": 4,
      "y": 6,
      "z": -2,
      "name": "Plant_Coral_Bush_Purple"
    },
    {
      "x": 4,
      "y": 7,
      "z": -2,
      "name": "Plant_Coral_Block_Purple"
    },
    {
      "x": 4,
      "y": 8,
      "z": -2,
      "name": "Plant_Coral_Bush_Pink"
    },
    {
      "x": 4,
      "y": 9,
      "z": -2,
      "name": "Plant_Coral_Bush_Pink"
    },
    {
      "x": 4,
      "y": 12,
      "z": -2,
      "name": "Plant_Coral_Block_Purple"
    },
    {
      "x": 4,
      "y": 0,
      "z": -1,
      "name": "Soil_Gravel_Lime"
    },
    {
      "x": 4,
      "y": 1,
      "z": -1,
      "name": "Rock_Lime_Cobble"
    },
    {
      "x": 4,
      "y": 2,
      "z": -1,
      "name": "Rock_Lime_Cobble"
    },
    {
      "x": 4,
      "y": 3,
      "z": -1,
      "name": "Plant_Coral_Block_Violet"
    },
    {
      "x": 4,
      "y": 4,
      "z": -1,
      "name": "Plant_Coral_Block_Purple"
    },
    {
      "x": 4,
      "y": 5,
      "z": -1,
      "name": "Plant_Coral_Block_Pink"
    },
    {
      "x": 4,
      "y": 6,
      "z": -1,
      "name": "Plant_Coral_Block_Purple"
    },
    {
      "x": 4,
      "y": 7,
      "z": -1,
      "name": "Plant_Coral_Block_Pink"
    },
    {
      "x": 4,
      "y": 8,
      "z": -1,
      "name": "Plant_Coral_Bush_Purple"
    },
    {
      "x": 4,
      "y": 9,
      "z": -1,
      "name": "Plant_Coral_Bush_Violet"
    },
    {
      "x": 4,
      "y": 10,
      "z": -1,
      "name": "Plant_Coral_Block_Violet"
    },
    {
      "x": 4,
      "y": 11,
      "z": -1,
      "name": "Plant_Coral_Block_Pink"
    },
    {
      "x": 4,
      "y": 12,
      "z": -1,
      "name": "Plant_Coral_Bush_Violet"
    },
    {
      "x": 4,
      "y": 13,
      "z": -1,
      "name": "Plant_Coral_Block_Purple"
    },
    {
      "x": 4,
      "y": 0,
      "z": 0,
      "name": "Rock_Lime_Cobble"
    },
    {
      "x": 4,
      "y": 1,
      "z": 0,
      "name": "Rock_Lime_Cobble"
    },
    {
      "x": 4,
      "y": 2,
      "z": 0,
      "name": "Rock_Lime_Cobble"
    },
    {
      "x": 4,
      "y": 3,
      "z": 0,
      "name": "Soil_Gravel_Lime"
    },
    {
      "x": 4,
      "y": 4,
      "z": 0,
      "name": "Plant_Coral_Block_Purple"
    },
    {
      "x": 4,
      "y": 5,
      "z": 0,
      "name": "Plant_Coral_Block_Violet"
    },
    {
      "x": 4,
      "y": 6,
      "z": 0,
      "name": "Plant_Coral_Block_Purple"
    },
    {
      "x": 4,
      "y": 7,
      "z": 0,
      "name": "Plant_Coral_Bush_Purple"
    },
    {
      "x": 4,
      "y": 8,
      "z": 0,
      "name": "Plant_Coral_Bush_Violet"
    },
    {
      "x": 4,
      "y": 9,
      "z": 0,
      "name": "Plant_Coral_Block_Violet"
    },
    {
      "x": 4,
      "y": 10,
      "z": 0,
      "name": "Plant_Coral_Block_Pink"
    },
    {
      "x": 4,
      "y": 11,
      "z": 0,
      "name": "Plant_Coral_Block_Violet"
    },
    {
      "x": 4,
      "y": 12,
      "z": 0,
      "name": "Plant_Coral_Bush_Pink"
    },
    {
      "x": 4,
      "y": 13,
      "z": 0,
      "name": "Plant_Coral_Block_Violet"
    },
    {
      "x": 4,
      "y": 14,
      "z": 0,
      "name": "Plant_Coral_Block_Violet"
    },
    {
      "x": 4,
      "y": 15,
      "z": 0,
      "name": "Plant_Coral_Block_Pink"
    },
    {
      "x": 4,
      "y": 16,
      "z": 0,
      "name": "Plant_Coral_Block_Pink"
    },
    {
      "x": 4,
      "y": 0,
      "z": 1,
      "name": "Rock_Lime_Cobble"
    },
    {
      "x": 4,
      "y": 1,
      "z": 1,
      "name": "Soil_Gravel_Lime"
    },
    {
      "x": 4,
      "y": 2,
      "z": 1,
      "name": "Soil_Gravel_Lime"
    },
    {
      "x": 4,
      "y": 3,
      "z": 1,
      "name": "Rock_Lime"
    },
    {
      "x": 4,
      "y": 4,
      "z": 1,
      "name": "Plant_Coral_Block_Pink"
    },
    {
      "x": 4,
      "y": 5,
      "z": 1,
      "name": "Plant_Coral_Block_Violet"
    },
    {
      "x": 4,
      "y": 6,
      "z": 1,
      "name": "Plant_Coral_Block_Pink"
    },
    {
      "x": 4,
      "y": 7,
      "z": 1,
      "name": "Plant_Coral_Block_Pink"
    },
    {
      "x": 4,
      "y": 8,
      "z": 1,
      "name": "Plant_Coral_Bush_Purple"
    },
    {
      "x": 4,
      "y": 9,
      "z": 1,
      "name": "Plant_Coral_Block_Violet"
    },
    {
      "x": 4,
      "y": 10,
      "z": 1,
      "name": "Plant_Coral_Bush_Pink"
    },
    {
      "x": 4,
      "y": 11,
      "z": 1,
      "name": "Plant_Coral_Bush_Pink"
    },
    {
      "x": 4,
      "y": 12,
      "z": 1,
      "name": "Plant_Coral_Block_Violet"
    },
    {
      "x": 4,
      "y": 13,
      "z": 1,
      "name": "Plant_Coral_Block_Purple"
    },
    {
      "x": 4,
      "y": 14,
      "z": 1,
      "name": "Plant_Coral_Block_Pink"
    },
    {
      "x": 4,
      "y": 15,
      "z": 1,
      "name": "Plant_Coral_Bush_Violet"
    },
    {
      "x": 4,
      "y": 16,
      "z": 1,
      "name": "Plant_Coral_Bush_Violet"
    },
    {
      "x": 4,
      "y": 17,
      "z": 1,
      "name": "Plant_Coral_Block_Pink"
    },
    {
      "x": 4,
      "y": 0,
      "z": 2,
      "name": "Rock_Lime"
    },
    {
      "x": 4,
      "y": 1,
      "z": 2,
      "name": "Rock_Lime"
    },
    {
      "x": 4,
      "y": 2,
      "z": 2,
      "name": "Rock_Lime"
    },
    {
      "x": 4,
      "y": 3,
      "z": 2,
      "name": "Soil_Gravel_Lime"
    },
    {
      "x": 4,
      "y": 4,
      "z": 2,
      "name": "Plant_Coral_Block_Pink"
    },
    {
      "x": 4,
      "y": 5,
      "z": 2,
      "name": "Plant_Coral_Block_Violet"
    },
    {
      "x": 4,
      "y": 6,
      "z": 2,
      "name": "Plant_Coral_Block_Purple"
    },
    {
      "x": 4,
      "y": 8,
      "z": 2,
      "name": "Plant_Coral_Block_Purple"
    },
    {
      "x": 4,
      "y": 9,
      "z": 2,
      "name": "Plant_Coral_Bush_Purple"
    },
    {
      "x": 4,
      "y": 10,
      "z": 2,
      "name": "Plant_Coral_Bush_Purple"
    },
    {
      "x": 4,
      "y": 11,
      "z": 2,
      "name": "Plant_Coral_Bush_Violet"
    },
    {
      "x": 4,
      "y": 12,
      "z": 2,
      "name": "Plant_Coral_Bush_Purple"
    },
    {
      "x": 4,
      "y": 13,
      "z": 2,
      "name": "Plant_Coral_Bush_Violet"
    },
    {
      "x": 4,
      "y": 14,
      "z": 2,
      "name": "Plant_Coral_Bush_Pink"
    },
    {
      "x": 4,
      "y": 15,
      "z": 2,
      "name": "Plant_Coral_Block_Violet"
    },
    {
      "x": 4,
      "y": 16,
      "z": 2,
      "name": "Plant_Coral_Bush_Pink"
    },
    {
      "x": 4,
      "y": 0,
      "z": 3,
      "name": "Rock_Lime"
    },
    {
      "x": 4,
      "y": 1,
      "z": 3,
      "name": "Soil_Gravel_Lime"
    },
    {
      "x": 4,
      "y": 2,
      "z": 3,
      "name": "Rock_Lime"
    },
    {
      "x": 4,
      "y": 3,
      "z": 3,
      "name": "Plant_Coral_Block_Pink"
    },
    {
      "x": 4,
      "y": 4,
      "z": 3,
      "name": "Plant_Coral_Block_Violet"
    },
    {
      "x": 4,
      "y": 5,
      "z": 3,
      "name": "Plant_Coral_Block_Purple"
    },
    {
      "x": 4,
      "y": 6,
      "z": 3,
      "name": "Plant_Coral_Block_Pink"
    },
    {
      "x": 4,
      "y": 9,
      "z": 3,
      "name": "Plant_Coral_Block_Pink"
    },
    {
      "x": 4,
      "y": 10,
      "z": 3,
      "name": "Plant_Coral_Bush_Pink"
    },
    {
      "x": 4,
      "y": 11,
      "z": 3,
      "name": "Plant_Coral_Block_Purple"
    },
    {
      "x": 4,
      "y": 12,
      "z": 3,
      "name": "Plant_Coral_Bush_Pink"
    },
    {
      "x": 4,
      "y": 13,
      "z": 3,
      "name": "Plant_Coral_Bush_Purple"
    },
    {
      "x": 4,
      "y": 14,
      "z": 3,
      "name": "Plant_Coral_Bush_Purple"
    },
    {
      "x": 4,
      "y": 15,
      "z": 3,
      "name": "Plant_Coral_Bush_Pink"
    },
    {
      "x": 4,
      "y": 1,
      "z": 4,
      "name": "Rock_Lime_Cobble"
    },
    {
      "x": 4,
      "y": 2,
      "z": 4,
      "name": "Rock_Lime"
    },
    {
      "x": 4,
      "y": 3,
      "z": 4,
      "name": "Soil_Gravel_Lime"
    },
    {
      "x": 4,
      "y": 4,
      "z": 4,
      "name": "Plant_Coral_Block_Purple"
    },
    {
      "x": 4,
      "y": 5,
      "z": 4,
      "name": "Plant_Coral_Block_Violet"
    },
    {
      "x": 4,
      "y": 6,
      "z": 4,
      "name": "Plant_Coral_Bush_Violet"
    },
    {
      "x": 4,
      "y": 11,
      "z": 4,
      "name": "Plant_Coral_Block_Pink"
    },
    {
      "x": 4,
      "y": 12,
      "z": 4,
      "name": "Plant_Coral_Block_Violet"
    },
    {
      "x": 4,
      "y": 13,
      "z": 4,
      "name": "Plant_Coral_Bush_Pink"
    },
    {
      "x": 4,
      "y": 1,
      "z": 5,
      "name": "Rock_Lime"
    },
    {
      "x": 4,
      "y": 2,
      "z": 5,
      "name": "Rock_Lime_Cobble"
    },
    {
      "x": 4,
      "y": 3,
      "z": 5,
      "name": "Rock_Lime_Cobble"
    },
    {
      "x": 4,
      "y": 4,
      "z": 5,
      "name": "Plant_Coral_Block_Purple"
    },
    {
      "x": 4,
      "y": 2,
      "z": 6,
      "name": "Soil_Gravel_Lime"
    },
    {
      "x": 4,
      "y": 17,
      "z": 6,
      "name": "Plant_Coral_Bush_Pink"
    },
    {
      "x": 4,
      "y": 17,
      "z": 7,
      "name": "Plant_Coral_Bush_Violet"
    },
    {
      "x": 4,
      "y": 16,
      "z": 8,
      "name": "Plant_Coral_Block_Violet"
    },
    {
      "x": 4,
      "y": 17,
      "z": 8,
      "name": "Plant_Coral_Bush_Purple"
    },
    {
      "x": 4,
      "y": 18,
      "z": 8,
      "name": "Plant_Coral_Block_Pink"
    },
    {
      "x": 4,
      "y": 16,
      "z": 9,
      "name": "Plant_Coral_Bush_Violet"
    },
    {
      "x": 4,
      "y": 17,
      "z": 9,
      "name": "Plant_Coral_Block_Pink"
    },
    {
      "x": 4,
      "y": 18,
      "z": 9,
      "name": "Plant_Coral_Block_Violet"
    },
    {
      "x": 4,
      "y": 19,
      "z": 9,
      "name": "Plant_Coral_Bush_Purple"
    },
    {
      "x": 4,
      "y": 17,
      "z": 10,
      "name": "Plant_Coral_Block_Pink"
    },
    {
      "x": 4,
      "y": 18,
      "z": 10,
      "name": "Plant_Coral_Bush_Purple"
    },
    {
      "x": 4,
      "y": 19,
      "z": 10,
      "name": "Plant_Coral_Block_Purple"
    },
    {
      "x": 4,
      "y": 17,
      "z": 11,
      "name": "Plant_Coral_Block_Pink"
    },
    {
      "x": 4,
      "y": 18,
      "z": 11,
      "name": "Plant_Coral_Bush_Pink"
    },
    {
      "x": 4,
      "y": 19,
      "z": 11,
      "name": "Plant_Coral_Block_Purple"
    },
    {
      "x": 4,
      "y": 18,
      "z": 12,
      "name": "Plant_Coral_Bush_Pink"
    },
    {
      "x": 5,
      "y": 2,
      "z": -4,
      "name": "Soil_Gravel_Lime"
    },
    {
      "x": 5,
      "y": 1,
      "z": -3,
      "name": "Rock_Lime"
    },
    {
      "x": 5,
      "y": 2,
      "z": -3,
      "name": "Rock_Lime"
    },
    {
      "x": 5,
      "y": 3,
      "z": -3,
      "name": "Rock_Lime_Cobble"
    },
    {
      "x": 5,
      "y": 4,
      "z": -3,
      "name": "Plant_Coral_Block_Purple"
    },
    {
      "x": 5,
      "y": 5,
      "z": -3,
      "name": "Plant_Coral_Block_Violet"
    },
    {
      "x": 5,
      "y": 7,
      "z": -3,
      "name": "Plant_Coral_Block_Violet"
    },
    {
      "x": 5,
      "y": 8,
      "z": -3,
      "name": "Plant_Coral_Block_Violet"
    },
    {
      "x": 5,
      "y": 9,
      "z": -3,
      "name": "Plant_Coral_Bush_Violet"
    },
    {
      "x": 5,
      "y": 0,
      "z": -2,
      "name": "Rock_Lime_Cobble"
    },
    {
      "x": 5,
      "y": 1,
      "z": -2,
      "name": "Rock_Lime_Cobble"
    },
    {
      "x": 5,
      "y": 2,
      "z": -2,
      "name": "Soil_Gravel_Lime"
    },
    {
      "x": 5,
      "y": 3,
      "z": -2,
      "name": "Rock_Lime"
    },
    {
      "x": 5,
      "y": 4,
      "z": -2,
      "name": "Plant_Coral_Block_Pink"
    },
    {
      "x": 5,
      "y": 5,
      "z": -2,
      "name": "Plant_Coral_Block_Purple"
    },
    {
      "x": 5,
      "y": 6,
      "z": -2,
      "name": "Plant_Coral_Block_Pink"
    },
    {
      "x": 5,
      "y": 7,
      "z": -2,
      "name": "Plant_Coral_Block_Purple"
    },
    {
      "x": 5,
      "y": 8,
      "z": -2,
      "name": "Plant_Coral_Bush_Pink"
    },
    {
      "x": 5,
      "y": 9,
      "z": -2,
      "name": "Plant_Coral_Block_Violet"
    },
    {
      "x": 5,
      "y": 10,
      "z": -2,
      "name": "Plant_Coral_Bush_Pink"
    },
    {
      "x": 5,
      "y": 11,
      "z": -2,
      "name": "Plant_Coral_Block_Pink"
    },
    {
      "x": 5,
      "y": 12,
      "z": -2,
      "name": "Plant_Coral_Bush_Purple"
    },
    {
      "x": 5,
      "y": 13,
      "z": -2,
      "name": "Plant_Coral_Bush_Violet"
    },
    {
      "x": 5,
      "y": 0,
      "z": -1,
      "name": "Rock_Lime_Cobble"
    },
    {
      "x": 5,
      "y": 1,
      "z": -1,
      "name": "Soil_Gravel_Lime"
    },
    {
      "x": 5,
      "y": 2,
      "z": -1,
      "name": "Soil_Gravel_Lime"
    },
    {
      "x": 5,
      "y": 3,
      "z": -1,
      "name": "Rock_Lime_Cobble"
    },
    {
      "x": 5,
      "y": 4,
      "z": -1,
      "name": "Plant_Coral_Block_Violet"
    },
    {
      "x": 5,
      "y": 5,
      "z": -1,
      "name": "Plant_Coral_Block_Pink"
    },
    {
      "x": 5,
      "y": 6,
      "z": -1,
      "name": "Plant_Coral_Bush_Pink"
    },
    {
      "x": 5,
      "y": 7,
      "z": -1,
      "name": "Plant_Coral_Bush_Purple"
    },
    {
      "x": 5,
      "y": 8,
      "z": -1,
      "name": "Plant_Coral_Bush_Pink"
    },
    {
      "x": 5,
      "y": 9,
      "z": -1,
      "name": "Plant_Coral_Block_Violet"
    },
    {
      "x": 5,
      "y": 10,
      "z": -1,
      "name": "Plant_Coral_Block_Pink"
    },
    {
      "x": 5,
      "y": 11,
      "z": -1,
      "name": "Plant_Coral_Block_Violet"
    },
    {
      "x": 5,
      "y": 12,
      "z": -1,
      "name": "Plant_Coral_Bush_Pink"
    },
    {
      "x": 5,
      "y": 13,
      "z": -1,
      "name": "Plant_Coral_Bush_Pink"
    },
    {
      "x": 5,
      "y": 14,
      "z": -1,
      "name": "Plant_Coral_Bush_Violet"
    },
    {
      "x": 5,
      "y": 0,
      "z": 0,
      "name": "Rock_Lime"
    },
    {
      "x": 5,
      "y": 1,
      "z": 0,
      "name": "Rock_Lime_Cobble"
    },
    {
      "x": 5,
      "y": 2,
      "z": 0,
      "name": "Rock_Lime_Cobble"
    },
    {
      "x": 5,
      "y": 3,
      "z": 0,
      "name": "Rock_Lime_Cobble"
    },
    {
      "x": 5,
      "y": 4,
      "z": 0,
      "name": "Plant_Coral_Block_Violet"
    },
    {
      "x": 5,
      "y": 5,
      "z": 0,
      "name": "Plant_Coral_Block_Purple"
    },
    {
      "x": 5,
      "y": 6,
      "z": 0,
      "name": "Plant_Coral_Block_Violet"
    },
    {
      "x": 5,
      "y": 7,
      "z": 0,
      "name": "Plant_Coral_Block_Pink"
    },
    {
      "x": 5,
      "y": 8,
      "z": 0,
      "name": "Plant_Coral_Bush_Pink"
    },
    {
      "x": 5,
      "y": 9,
      "z": 0,
      "name": "Plant_Coral_Block_Purple"
    },
    {
      "x": 5,
      "y": 10,
      "z": 0,
      "name": "Plant_Coral_Block_Violet"
    },
    {
      "x": 5,
      "y": 11,
      "z": 0,
      "name": "Plant_Coral_Block_Purple"
    },
    {
      "x": 5,
      "y": 12,
      "z": 0,
      "name": "Plant_Coral_Bush_Pink"
    },
    {
      "x": 5,
      "y": 13,
      "z": 0,
      "name": "Plant_Coral_Block_Violet"
    },
    {
      "x": 5,
      "y": 14,
      "z": 0,
      "name": "Plant_Coral_Bush_Pink"
    },
    {
      "x": 5,
      "y": 16,
      "z": 0,
      "name": "Plant_Coral_Bush_Pink"
    },
    {
      "x": 5,
      "y": 0,
      "z": 1,
      "name": "Rock_Lime_Cobble"
    },
    {
      "x": 5,
      "y": 1,
      "z": 1,
      "name": "Soil_Gravel_Lime"
    },
    {
      "x": 5,
      "y": 2,
      "z": 1,
      "name": "Rock_Lime_Cobble"
    },
    {
      "x": 5,
      "y": 3,
      "z": 1,
      "name": "Plant_Coral_Block_Violet"
    },
    {
      "x": 5,
      "y": 4,
      "z": 1,
      "name": "Plant_Coral_Block_Violet"
    },
    {
      "x": 5,
      "y": 5,
      "z": 1,
      "name": "Plant_Coral_Block_Purple"
    },
    {
      "x": 5,
      "y": 6,
      "z": 1,
      "name": "Plant_Coral_Block_Violet"
    },
    {
      "x": 5,
      "y": 7,
      "z": 1,
      "name": "Plant_Coral_Bush_Purple"
    },
    {
      "x": 5,
      "y": 8,
      "z": 1,
      "name": "Plant_Coral_Bush_Purple"
    },
    {
      "x": 5,
      "y": 9,
      "z": 1,
      "name": "Plant_Coral_Block_Purple"
    },
    {
      "x": 5,
      "y": 10,
      "z": 1,
      "name": "Plant_Coral_Bush_Violet"
    },
    {
      "x": 5,
      "y": 11,
      "z": 1,
      "name": "Plant_Coral_Bush_Violet"
    },
    {
      "x": 5,
      "y": 12,
      "z": 1,
      "name": "Plant_Coral_Block_Purple"
    },
    {
      "x": 5,
      "y": 13,
      "z": 1,
      "name": "Plant_Coral_Bush_Pink"
    },
    {
      "x": 5,
      "y": 14,
      "z": 1,
      "name": "Plant_Coral_Bush_Pink"
    },
    {
      "x": 5,
      "y": 15,
      "z": 1,
      "name": "Plant_Coral_Bush_Pink"
    },
    {
      "x": 5,
      "y": 16,
      "z": 1,
      "name": "Plant_Coral_Block_Pink"
    },
    {
      "x": 5,
      "y": 0,
      "z": 2,
      "name": "Soil_Gravel_Lime"
    },
    {
      "x": 5,
      "y": 1,
      "z": 2,
      "name": "Soil_Gravel_Lime"
    },
    {
      "x": 5,
      "y": 2,
      "z": 2,
      "name": "Rock_Lime_Cobble"
    },
    {
      "x": 5,
      "y": 3,
      "z": 2,
      "name": "Rock_Lime_Cobble"
    },
    {
      "x": 5,
      "y": 4,
      "z": 2,
      "name": "Plant_Coral_Block_Purple"
    },
    {
      "x": 5,
      "y": 5,
      "z": 2,
      "name": "Plant_Coral_Block_Purple"
    },
    {
      "x": 5,
      "y": 6,
      "z": 2,
      "name": "Plant_Coral_Block_Pink"
    },
    {
      "x": 5,
      "y": 7,
      "z": 2,
      "name": "Plant_Coral_Bush_Violet"
    },
    {
      "x": 5,
      "y": 8,
      "z": 2,
      "name": "Plant_Coral_Block_Pink"
    },
    {
      "x": 5,
      "y": 9,
      "z": 2,
      "name": "Plant_Coral_Bush_Purple"
    },
    {
      "x": 5,
      "y": 10,
      "z": 2,
      "name": "Plant_Coral_Block_Pink"
    },
    {
      "x": 5,
      "y": 11,
      "z": 2,
      "name": "Plant_Coral_Bush_Pink"
    },
    {
      "x": 5,
      "y": 12,
      "z": 2,
      "name": "Plant_Coral_Bush_Purple"
    },
    {
      "x": 5,
      "y": 13,
      "z": 2,
      "name": "Plant_Coral_Block_Purple"
    },
    {
      "x": 5,
      "y": 14,
      "z": 2,
      "name": "Plant_Coral_Block_Violet"
    },
    {
      "x": 5,
      "y": 15,
      "z": 2,
      "name": "Plant_Coral_Bush_Violet"
    },
    {
      "x": 5,
      "y": 0,
      "z": 3,
      "name": "Rock_Lime"
    },
    {
      "x": 5,
      "y": 1,
      "z": 3,
      "name": "Rock_Lime"
    },
    {
      "x": 5,
      "y": 2,
      "z": 3,
      "name": "Rock_Lime"
    },
    {
      "x": 5,
      "y": 3,
      "z": 3,
      "name": "Soil_Gravel_Lime"
    },
    {
      "x": 5,
      "y": 4,
      "z": 3,
      "name": "Plant_Coral_Block_Pink"
    },
    {
      "x": 5,
      "y": 5,
      "z": 3,
      "name": "Plant_Coral_Block_Purple"
    },
    {
      "x": 5,
      "y": 6,
      "z": 3,
      "name": "Plant_Coral_Block_Pink"
    },
    {
      "x": 5,
      "y": 7,
      "z": 3,
      "name": "Plant_Coral_Block_Purple"
    },
    {
      "x": 5,
      "y": 8,
      "z": 3,
      "name": "Plant_Coral_Block_Purple"
    },
    {
      "x": 5,
      "y": 9,
      "z": 3,
      "name": "Plant_Coral_Block_Purple"
    },
    {
      "x": 5,
      "y": 10,
      "z": 3,
      "name": "Plant_Coral_Bush_Violet"
    },
    {
      "x": 5,
      "y": 11,
      "z": 3,
      "name": "Plant_Coral_Block_Violet"
    },
    {
      "x": 5,
      "y": 12,
      "z": 3,
      "name": "Plant_Coral_Bush_Violet"
    },
    {
      "x": 5,
      "y": 13,
      "z": 3,
      "name": "Plant_Coral_Block_Pink"
    },
    {
      "x": 5,
      "y": 14,
      "z": 3,
      "name": "Plant_Coral_Bush_Pink"
    },
    {
      "x": 5,
      "y": 0,
      "z": 4,
      "name": "Rock_Lime"
    },
    {
      "x": 5,
      "y": 1,
      "z": 4,
      "name": "Rock_Lime"
    },
    {
      "x": 5,
      "y": 2,
      "z": 4,
      "name": "Rock_Lime_Cobble"
    },
    {
      "x": 5,
      "y": 3,
      "z": 4,
      "name": "Plant_Coral_Block_Purple"
    },
    {
      "x": 5,
      "y": 4,
      "z": 4,
      "name": "Plant_Coral_Block_Violet"
    },
    {
      "x": 5,
      "y": 5,
      "z": 4,
      "name": "Plant_Coral_Block_Pink"
    },
    {
      "x": 5,
      "y": 6,
      "z": 4,
      "name": "Plant_Coral_Block_Purple"
    },
    {
      "x": 5,
      "y": 7,
      "z": 4,
      "name": "Plant_Coral_Bush_Pink"
    },
    {
      "x": 5,
      "y": 9,
      "z": 4,
      "name": "Plant_Coral_Bush_Purple"
    },
    {
      "x": 5,
      "y": 11,
      "z": 4,
      "name": "Plant_Coral_Block_Pink"
    },
    {
      "x": 5,
      "y": 12,
      "z": 4,
      "name": "Plant_Coral_Bush_Purple"
    },
    {
      "x": 5,
      "y": 13,
      "z": 4,
      "name": "Plant_Coral_Block_Pink"
    },
    {
      "x": 5,
      "y": 0,
      "z": 5,
      "name": "Rock_Lime"
    },
    {
      "x": 5,
      "y": 1,
      "z": 5,
      "name": "Soil_Gravel_Lime"
    },
    {
      "x": 5,
      "y": 2,
      "z": 5,
      "name": "Rock_Lime_Cobble"
    },
    {
      "x": 5,
      "y": 3,
      "z": 5,
      "name": "Plant_Coral_Block_Violet"
    },
    {
      "x": 5,
      "y": 4,
      "z": 5,
      "name": "Plant_Coral_Block_Purple"
    },
    {
      "x": 5,
      "y": 5,
      "z": 5,
      "name": "Plant_Coral_Block_Violet"
    },
    {
      "x": 5,
      "y": 6,
      "z": 5,
      "name": "Plant_Coral_Bush_Purple"
    },
    {
      "x": 5,
      "y": 12,
      "z": 5,
      "name": "Plant_Coral_Bush_Pink"
    },
    {
      "x": 5,
      "y": 1,
      "z": 6,
      "name": "Soil_Gravel_Lime"
    },
    {
      "x": 5,
      "y": 2,
      "z": 6,
      "name": "Soil_Gravel_Lime"
    },
    {
      "x": 5,
      "y": 3,
      "z": 6,
      "name": "Soil_Gravel_Lime"
    },
    {
      "x": 5,
      "y": 4,
      "z": 6,
      "name": "Plant_Coral_Block_Violet"
    },
    {
      "x": 5,
      "y": 5,
      "z": 6,
      "name": "Plant_Coral_Bush_Violet"
    },
    {
      "x": 5,
      "y": 2,
      "z": 7,
      "name": "Rock_Lime_Cobble"
    },
    {
      "x": 5,
      "y": 17,
      "z": 8,
      "name": "Plant_Coral_Block_Purple"
    },
    {
      "x": 5,
      "y": 16,
      "z": 9,
      "name": "Plant_Coral_Block_Purple"
    },
    {
      "x": 5,
      "y": 17,
      "z": 9,
      "name": "Plant_Coral_Block_Purple"
    },
    {
      "x": 5,
      "y": 18,
      "z": 9,
      "name": "Plant_Coral_Bush_Purple"
    },
    {
      "x": 5,
      "y": 17,
      "z": 10,
      "name": "Plant_Coral_Bush_Pink"
    },
    {
      "x": 5,
      "y": 18,
      "z": 10,
      "name": "Plant_Coral_Bush_Violet"
    },
    {
      "x": 5,
      "y": 18,
      "z": 11,
      "name": "Plant_Coral_Block_Purple"
    },
    {
      "x": 6,
      "y": 1,
      "z": -4,
      "name": "Soil_Gravel_Lime"
    },
    {
      "x": 6,
      "y": 2,
      "z": -4,
      "name": "Rock_Lime_Cobble"
    },
    {
      "x": 6,
      "y": 3,
      "z": -4,
      "name": "Rock_Lime"
    },
    {
      "x": 6,
      "y": 4,
      "z": -4,
      "name": "Plant_Coral_Block_Pink"
    },
    {
      "x": 6,
      "y": 5,
      "z": -4,
      "name": "Plant_Coral_Block_Violet"
    },
    {
      "x": 6,
      "y": 0,
      "z": -3,
      "name": "Soil_Gravel_Lime"
    },
    {
      "x": 6,
      "y": 1,
      "z": -3,
      "name": "Rock_Lime"
    },
    {
      "x": 6,
      "y": 2,
      "z": -3,
      "name": "Rock_Lime"
    },
    {
      "x": 6,
      "y": 3,
      "z": -3,
      "name": "Plant_Coral_Block_Purple"
    },
    {
      "x": 6,
      "y": 4,
      "z": -3,
      "name": "Plant_Coral_Block_Pink"
    },
    {
      "x": 6,
      "y": 5,
      "z": -3,
      "name": "Plant_Coral_Block_Pink"
    },
    {
      "x": 6,
      "y": 6,
      "z": -3,
      "name": "Plant_Coral_Block_Violet"
    },
    {
      "x": 6,
      "y": 7,
      "z": -3,
      "name": "Plant_Coral_Bush_Violet"
    },
    {
      "x": 6,
      "y": 8,
      "z": -3,
      "name": "Plant_Coral_Bush_Purple"
    },
    {
      "x": 6,
      "y": 0,
      "z": -2,
      "name": "Rock_Lime_Cobble"
    },
    {
      "x": 6,
      "y": 1,
      "z": -2,
      "name": "Rock_Lime_Cobble"
    },
    {
      "x": 6,
      "y": 2,
      "z": -2,
      "name": "Rock_Lime"
    },
    {
      "x": 6,
      "y": 3,
      "z": -2,
      "name": "Rock_Lime"
    },
    {
      "x": 6,
      "y": 4,
      "z": -2,
      "name": "Plant_Coral_Block_Violet"
    },
    {
      "x": 6,
      "y": 5,
      "z": -2,
      "name": "Plant_Coral_Block_Pink"
    },
    {
      "x": 6,
      "y": 6,
      "z": -2,
      "name": "Plant_Coral_Block_Violet"
    },
    {
      "x": 6,
      "y": 7,
      "z": -2,
      "name": "Plant_Coral_Block_Violet"
    },
    {
      "x": 6,
      "y": 8,
      "z": -2,
      "name": "Plant_Coral_Block_Purple"
    },
    {
      "x": 6,
      "y": 9,
      "z": -2,
      "name": "Plant_Coral_Block_Violet"
    },
    {
      "x": 6,
      "y": 12,
      "z": -2,
      "name": "Plant_Coral_Block_Purple"
    },
    {
      "x": 6,
      "y": 0,
      "z": -1,
      "name": "Rock_Lime"
    },
    {
      "x": 6,
      "y": 1,
      "z": -1,
      "name": "Soil_Gravel_Lime"
    },
    {
      "x": 6,
      "y": 2,
      "z": -1,
      "name": "Soil_Gravel_Lime"
    },
    {
      "x": 6,
      "y": 3,
      "z": -1,
      "name": "Soil_Gravel_Lime"
    },
    {
      "x": 6,
      "y": 4,
      "z": -1,
      "name": "Plant_Coral_Block_Violet"
    },
    {
      "x": 6,
      "y": 5,
      "z": -1,
      "name": "Plant_Coral_Block_Pink"
    },
    {
      "x": 6,
      "y": 6,
      "z": -1,
      "name": "Plant_Coral_Bush_Purple"
    },
    {
      "x": 6,
      "y": 7,
      "z": -1,
      "name": "Plant_Coral_Bush_Purple"
    },
    {
      "x": 6,
      "y": 8,
      "z": -1,
      "name": "Plant_Coral_Block_Violet"
    },
    {
      "x": 6,
      "y": 9,
      "z": -1,
      "name": "Plant_Coral_Bush_Pink"
    },
    {
      "x": 6,
      "y": 10,
      "z": -1,
      "name": "Plant_Coral_Bush_Pink"
    },
    {
      "x": 6,
      "y": 11,
      "z": -1,
      "name": "Plant_Coral_Block_Purple"
    },
    {
      "x": 6,
      "y": 12,
      "z": -1,
      "name": "Plant_Coral_Bush_Violet"
    },
    {
      "x": 6,
      "y": 13,
      "z": -1,
      "name": "Plant_Coral_Block_Violet"
    },
    {
      "x": 6,
      "y": 0,
      "z": 0,
      "name": "Soil_Gravel_Lime"
    },
    {
      "x": 6,
      "y": 1,
      "z": 0,
      "name": "Soil_Gravel_Lime"
    },
    {
      "x": 6,
      "y": 2,
      "z": 0,
      "name": "Soil_Gravel_Lime"
    },
    {
      "x": 6,
      "y": 3,
      "z": 0,
      "name": "Plant_Coral_Block_Pink"
    },
    {
      "x": 6,
      "y": 4,
      "z": 0,
      "name": "Plant_Coral_Block_Pink"
    },
    {
      "x": 6,
      "y": 5,
      "z": 0,
      "name": "Plant_Coral_Block_Violet"
    },
    {
      "x": 6,
      "y": 6,
      "z": 0,
      "name": "Plant_Coral_Block_Pink"
    },
    {
      "x": 6,
      "y": 7,
      "z": 0,
      "name": "Plant_Coral_Bush_Pink"
    },
    {
      "x": 6,
      "y": 8,
      "z": 0,
      "name": "Plant_Coral_Block_Pink"
    },
    {
      "x": 6,
      "y": 9,
      "z": 0,
      "name": "Plant_Coral_Bush_Pink"
    },
    {
      "x": 6,
      "y": 10,
      "z": 0,
      "name": "Plant_Coral_Bush_Purple"
    },
    {
      "x": 6,
      "y": 11,
      "z": 0,
      "name": "Plant_Coral_Bush_Violet"
    },
    {
      "x": 6,
      "y": 12,
      "z": 0,
      "name": "Plant_Coral_Bush_Pink"
    },
    {
      "x": 6,
      "y": 13,
      "z": 0,
      "name": "Plant_Coral_Bush_Purple"
    },
    {
      "x": 6,
      "y": 14,
      "z": 0,
      "name": "Plant_Coral_Bush_Pink"
    },
    {
      "x": 6,
      "y": 0,
      "z": 1,
      "name": "Rock_Lime_Cobble"
    },
    {
      "x": 6,
      "y": 1,
      "z": 1,
      "name": "Rock_Lime_Cobble"
    },
    {
      "x": 6,
      "y": 2,
      "z": 1,
      "name": "Plant_Coral_Block_Violet"
    },
    {
      "x": 6,
      "y": 3,
      "z": 1,
      "name": "Plant_Coral_Block_Violet"
    },
    {
      "x": 6,
      "y": 4,
      "z": 1,
      "name": "Plant_Coral_Block_Pink"
    },
    {
      "x": 6,
      "y": 5,
      "z": 1,
      "name": "Plant_Coral_Block_Violet"
    },
    {
      "x": 6,
      "y": 6,
      "z": 1,
      "name": "Plant_Coral_Block_Pink"
    },
    {
      "x": 6,
      "y": 7,
      "z": 1,
      "name": "Plant_Coral_Bush_Purple"
    },
    {
      "x": 6,
      "y": 8,
      "z": 1,
      "name": "Plant_Coral_Bush_Purple"
    },
    {
      "x": 6,
      "y": 9,
      "z": 1,
      "name": "Plant_Coral_Bush_Purple"
    },
    {
      "x": 6,
      "y": 10,
      "z": 1,
      "name": "Plant_Coral_Bush_Violet"
    },
    {
      "x": 6,
      "y": 11,
      "z": 1,
      "name": "Plant_Coral_Bush_Violet"
    },
    {
      "x": 6,
      "y": 12,
      "z": 1,
      "name": "Plant_Coral_Bush_Pink"
    },
    {
      "x": 6,
      "y": 13,
      "z": 1,
      "name": "Plant_Coral_Bush_Pink"
    },
    {
      "x": 6,
      "y": 15,
      "z": 1,
      "name": "Plant_Coral_Block_Violet"
    },
    {
      "x": 6,
      "y": 0,
      "z": 2,
      "name": "Rock_Lime_Cobble"
    },
    {
      "x": 6,
      "y": 1,
      "z": 2,
      "name": "Soil_Gravel_Lime"
    },
    {
      "x": 6,
      "y": 2,
      "z": 2,
      "name": "Rock_Lime_Cobble"
    },
    {
      "x": 6,
      "y": 3,
      "z": 2,
      "name": "Plant_Coral_Block_Purple"
    },
    {
      "x": 6,
      "y": 4,
      "z": 2,
      "name": "Plant_Coral_Block_Violet"
    },
    {
      "x": 6,
      "y": 5,
      "z": 2,
      "name": "Plant_Coral_Block_Pink"
    },
    {
      "x": 6,
      "y": 6,
      "z": 2,
      "name": "Plant_Coral_Block_Pink"
    },
    {
      "x": 6,
      "y": 7,
      "z": 2,
      "name": "Plant_Coral_Block_Purple"
    },
    {
      "x": 6,
      "y": 8,
      "z": 2,
      "name": "Plant_Coral_Bush_Purple"
    },
    {
      "x": 6,
      "y": 9,
      "z": 2,
      "name": "Plant_Coral_Bush_Violet"
    },
    {
      "x": 6,
      "y": 10,
      "z": 2,
      "name": "Plant_Coral_Bush_Pink"
    },
    {
      "x": 6,
      "y": 11,
      "z": 2,
      "name": "Plant_Coral_Block_Pink"
    },
    {
      "x": 6,
      "y": 12,
      "z": 2,
      "name": "Plant_Coral_Bush_Violet"
    },
    {
      "x": 6,
      "y": 13,
      "z": 2,
      "name": "Plant_Coral_Block_Purple"
    },
    {
      "x": 6,
      "y": 14,
      "z": 2,
      "name": "Plant_Coral_Block_Pink"
    },
    {
      "x": 6,
      "y": 0,
      "z": 3,
      "name": "Rock_Lime_Cobble"
    },
    {
