{
  "version": 8,
  "blockIdVersion": 11,
  "anchorX": -34,
  "anchorY": 7,
  "anchorZ": -21,
  "blocks": [
    {
      "x": -43,
      "y": 7,
      "z": -24,
      "name": "Rock_Lime_Cobble"
    },
    {
      "x": -43,
      "y": 6,
      "z": -23,
      "name": "Rock_Lime_Cobble"
    },
    {
      "x": -43,
      "y": 7,
      "z": -23,
      "name": "Rock_Lime_Cobble"
    },
    {
      "x": -43,
      "y": 8,
      "z": -23,
      "name": "Rock_Lime_Cobble"
    },
    {
      "x": -43,
      "y": 6,
      "z": -22,
      "name": "Rock_Lime_Cobble"
    },
    {
      "x": -43,
      "y": 7,
      "z": -22,
      "name": "Soil_Gravel_Lime"
    },
    {
      "x": -43,
      "y": 8,
      "z": -22,
      "name": "Soil_Gravel_Lime"
    },
    {
      "x": -43,
      "y": 6,
      "z": -21,
      "name": "Rock_Lime_Cobble"
    },
    {
      "x": -43,
      "y": 7,
      "z": -21,
      "name": "Soil_Gravel_Lime"
    },
    {
      "x": -43,
      "y": 8,
      "z": -21,
      "name": "Soil_Gravel_Lime"
    },
    {
      "x": -43,
      "y": 7,
      "z": -20,
      "name": "Rock_Lime_Cobble"
    },
    {
      "x": -42,
      "y": 7,
      "z": -28,
      "name": "Rock_Lime"
    },
    {
      "x": -42,
      "y": 6,
      "z": -27,
      "name": "Soil_Gravel_Lime"
    },
    {
      "x": -42,
      "y": 7,
      "z": -27,
      "name": "Soil_Gravel_Lime"
    },
    {
      "x": -42,
      "y": 8,
      "z": -27,
      "name": "Rock_Lime_Cobble"
    },
    {
      "x": -42,
      "y": 7,
      "z": -26,
      "name": "Rock_Lime"
    },
    {
      "x": -42,
      "y": 7,
      "z": -25,
      "name": "Rock_Lime_Cobble"
    },
    {
      "x": -42,
      "y": 6,
      "z": -24,
      "name": "Rock_Lime_Cobble"
    },
    {
      "x": -42,
      "y": 7,
      "z": -24,
      "name": "Soil_Gravel_Lime"
    },
    {
      "x": -42,
      "y": 8,
      "z": -24,
      "name": "Soil_Gravel_Lime"
    },
    {
      "x": -42,
      "y": 5,
      "z": -23,
      "name": "Soil_Gravel_Lime"
    },
    {
      "x": -42,
      "y": 6,
      "z": -23,
      "name": "Rock_Lime_Cobble"
    },
    {
      "x": -42,
      "y": 7,
      "z": -23,
      "name": "Rock_Lime_Cobble"
    },
    {
      "x": -42,
      "y": 8,
      "z": -23,
      "name": "Rock_Lime"
    },
    {
      "x": -42,
      "y": 9,
      "z": -23,
      "name": "Soil_Gravel_Lime"
    },
    {
      "x": -42,
      "y": 5,
      "z": -22,
      "name": "Soil_Gravel_Lime"
    },
    {
      "x": -42,
      "y": 6,
      "z": -22,
      "name": "Rock_Lime_Cobble"
    },
    {
      "x": -42,
      "y": 7,
      "z": -22,
      "name": "Soil_Gravel_Lime"
    },
    {
      "x": -42,
      "y": 8,
      "z": -22,
      "name": "Rock_Lime"
    },
    {
      "x": -42,
      "y": 9,
      "z": -22,
      "name": "Rock_Lime"
    },
    {
      "x": -42,
      "y": 5,
      "z": -21,
      "name": "Rock_Lime_Cobble"
    },
    {
      "x": -42,
      "y": 6,
      "z": -21,
      "name": "Rock_Lime_Cobble"
    },
    {
      "x": -42,
      "y": 7,
      "z": -21,
      "name": "Soil_Gravel_Lime"
    },
    {
      "x": -42,
      "y": 8,
      "z": -21,
      "name": "Rock_Lime"
    },
    {
      "x": -42,
      "y": 9,
      "z": -21,
      "name": "Rock_Lime"
    },
    {
      "x": -42,
      "y": 6,
      "z": -20,
      "name": "Soil_Gravel_Lime"
    },
    {
      "x": -42,
      "y": 7,
      "z": -20,
      "name": "Rock_Lime"
    },
    {
      "x": -42,
      "y": 8,
      "z": -20,
      "name": "Rock_Lime_Cobble"
    },
    {
      "x": -42,
      "y": 7,
      "z": -19,
      "name": "Rock_Lime"
    },
    {
      "x": -42,
      "y": 6,
      "z": -18,
      "name": "Rock_Lime_Cobble"
    },
    {
      "x": -42,
      "y": 7,
      "z": -18,
      "name": "Soil_Gravel_Lime"
    },
    {
      "x": -42,
      "y": 8,
      "z": -18,
      "name": "Soil_Gravel_Lime"
    },
    {
      "x": -42,
      "y": 7,
      "z": -17,
      "name": "Soil_Gravel_Lime"
    },
    {
      "x": -41,
      "y": 7,
      "z": -29,
      "name": "Rock_Lime_Cobble"
    },
    {
      "x": -41,
      "y": 6,
      "z": -28,
      "name": "Soil_Gravel_Lime"
    },
    {
      "x": -41,
      "y": 7,
      "z": -28,
      "name": "Soil_Gravel_Lime"
    },
    {
      "x": -41,
      "y": 8,
      "z": -28,
      "name": "Rock_Lime"
    },
    {
      "x": -41,
      "y": 5,
      "z": -27,
      "name": "Soil_Gravel_Lime"
    },
    {
      "x": -41,
      "y": 6,
      "z": -27,
      "name": "Rock_Lime_Cobble"
    },
    {
      "x": -41,
      "y": 7,
      "z": -27,
      "name": "Soil_Gravel_Lime"
    },
    {
      "x": -41,
      "y": 8,
      "z": -27,
      "name": "Soil_Gravel_Lime"
    },
    {
      "x": -41,
      "y": 9,
      "z": -27,
      "name": "Soil_Gravel_Lime"
    },
    {
      "x": -41,
      "y": 6,
      "z": -26,
      "name": "Rock_Lime_Cobble"
    },
    {
      "x": -41,
      "y": 7,
      "z": -26,
      "name": "Rock_Lime_Cobble"
    },
    {
      "x": -41,
      "y": 8,
      "z": -26,
      "name": "Rock_Lime"
    },
    {
      "x": -41,
      "y": 6,
      "z": -25,
      "name": "Rock_Lime"
    },
    {
      "x": -41,
      "y": 7,
      "z": -25,
      "name": "Rock_Lime"
    },
    {
      "x": -41,
      "y": 8,
      "z": -25,
      "name": "Rock_Lime"
    },
    {
      "x": -41,
      "y": 9,
      "z": -25,
      "name": "Rock_Lime"
    },
    {
      "x": -41,
      "y": 10,
      "z": -25,
      "name": "Plant_Coral_Model_Cyan"
    },
    {
      "x": -41,
      "y": 5,
      "z": -24,
      "name": "Rock_Lime"
    },
    {
      "x": -41,
      "y": 6,
      "z": -24,
      "name": "Soil_Gravel_Lime"
    },
    {
      "x": -41,
      "y": 7,
      "z": -24,
      "name": "Rock_Lime"
    },
    {
      "x": -41,
      "y": 8,
      "z": -24,
      "name": "Rock_Lime_Cobble"
    },
    {
      "x": -41,
      "y": 9,
      "z": -24,
      "name": "Soil_Gravel_Lime"
    },
    {
      "x": -41,
      "y": 5,
      "z": -23,
      "name": "Soil_Gravel_Lime"
    },
    {
      "x": -41,
      "y": 6,
      "z": -23,
      "name": "Soil_Gravel_Lime"
    },
    {
      "x": -41,
      "y": 7,
      "z": -23,
      "name": "Soil_Gravel_Lime"
    },
    {
      "x": -41,
      "y": 8,
      "z": -23,
      "name": "Rock_Lime_Cobble"
    },
    {
      "x": -41,
      "y": 9,
      "z": -23,
      "name": "Rock_Lime_Cobble"
    },
    {
      "x": -41,
      "y": 5,
      "z": -22,
      "name": "Rock_Lime_Cobble"
    },
    {
      "x": -41,
      "y": 6,
      "z": -22,
      "name": "Rock_Lime_Cobble"
    },
    {
      "x": -41,
      "y": 7,
      "z": -22,
      "name": "Rock_Lime"
    },
    {
      "x": -41,
      "y": 8,
      "z": -22,
      "name": "Rock_Lime"
    },
    {
      "x": -41,
      "y": 9,
      "z": -22,
      "name": "Rock_Lime"
    },
    {
      "x": -41,
      "y": 5,
      "z": -21,
      "name": "Rock_Lime_Cobble"
    },
    {
      "x": -41,
      "y": 6,
      "z": -21,
      "name": "Soil_Gravel_Lime"
    },
    {
      "x": -41,
      "y": 7,
      "z": -21,
      "name": "Soil_Gravel_Lime"
    },
    {
      "x": -41,
      "y": 8,
      "z": -21,
      "name": "Rock_Lime_Cobble"
    },
    {
      "x": -41,
      "y": 9,
      "z": -21,
      "name": "Rock_Lime"
    },
    {
      "x": -41,
      "y": 5,
      "z": -20,
      "name": "Soil_Gravel_Lime"
    },
    {
      "x": -41,
      "y": 6,
      "z": -20,
      "name": "Rock_Lime_Cobble"
    },
    {
      "x": -41,
      "y": 7,
      "z": -20,
      "name": "Rock_Lime"
    },
    {
      "x": -41,
      "y": 8,
      "z": -20,
      "name": "Rock_Lime_Cobble"
    },
    {
      "x": -41,
      "y": 9,
      "z": -20,
      "name": "Soil_Gravel_Lime"
    },
    {
      "x": -41,
      "y": 6,
      "z": -19,
      "name": "Soil_Gravel_Lime"
    },
    {
      "x": -41,
      "y": 7,
      "z": -19,
      "name": "Rock_Lime_Cobble"
    },
    {
      "x": -41,
      "y": 8,
      "z": -19,
      "name": "Soil_Gravel_Lime"
    },
    {
      "x": -41,
      "y": 5,
      "z": -18,
      "name": "Rock_Lime"
    },
    {
      "x": -41,
      "y": 6,
      "z": -18,
      "name": "Soil_Gravel_Lime"
    },
    {
      "x": -41,
      "y": 7,
      "z": -18,
      "name": "Rock_Lime_Cobble"
    },
    {
      "x": -41,
      "y": 8,
      "z": -18,
      "name": "Rock_Lime"
    },
    {
      "x": -41,
      "y": 9,
      "z": -18,
      "name": "Rock_Lime_Cobble"
    },
    {
      "x": -41,
      "y": 6,
      "z": -17,
      "name": "Rock_Lime"
    },
    {
      "x": -41,
      "y": 7,
      "z": -17,
      "name": "Rock_Lime"
    },
    {
      "x": -41,
      "y": 8,
      "z": -17,
      "name": "Rock_Lime_Cobble"
    },
    {
      "x": -41,
      "y": 7,
      "z": -16,
      "name": "Soil_Gravel_Lime"
    },
    {
      "x": -40,
      "y": 7,
      "z": -30,
      "name": "Soil_Gravel_Lime"
    },
    {
      "x": -40,
      "y": 6,
      "z": -29,
      "name": "Rock_Lime_Cobble"
    },
    {
      "x": -40,
      "y": 7,
      "z": -29,
      "name": "Rock_Lime"
    },
    {
      "x": -40,
      "y": 8,
      "z": -29,
      "name": "Soil_Gravel_Lime"
    },
    {
      "x": -40,
      "y": 5,
      "z": -28,
      "name": "Soil_Gravel_Lime"
    },
    {
      "x": -40,
      "y": 6,
      "z": -28,
      "name": "Rock_Lime_Cobble"
    },
    {
      "x": -40,
      "y": 7,
      "z": -28,
      "name": "Rock_Lime_Cobble"
    },
    {
      "x": -40,
      "y": 8,
      "z": -28,
      "name": "Rock_Lime"
    },
    {
      "x": -40,
      "y": 9,
      "z": -28,
      "name": "Soil_Gravel_Lime"
    },
    {
      "x": -40,
      "y": 5,
      "z": -27,
      "name": "Rock_Lime"
    },
    {
      "x": -40,
      "y": 6,
      "z": -27,
      "name": "Rock_Lime"
    },
    {
      "x": -40,
      "y": 7,
      "z": -27,
      "name": "Soil_Gravel_Lime"
    },
    {
      "x": -40,
      "y": 8,
      "z": -27,
      "name": "Rock_Lime"
    },
    {
      "x": -40,
      "y": 9,
      "z": -27,
      "name": "Rock_Lime_Cobble"
    },
    {
      "x": -40,
      "y": 5,
      "z": -26,
      "name": "Rock_Lime"
    },
    {
      "x": -40,
      "y": 6,
      "z": -26,
      "name": "Rock_Lime"
    },
    {
      "x": -40,
      "y": 7,
      "z": -26,
      "name": "Soil_Gravel_Lime"
    },
    {
      "x": -40,
      "y": 8,
      "z": -26,
      "name": "Rock_Lime"
    },
    {
      "x": -40,
      "y": 9,
      "z": -26,
      "name": "Rock_Lime"
    },
    {
      "x": -40,
      "y": 6,
      "z": -25,
      "name": "Rock_Lime"
    },
    {
      "x": -40,
      "y": 7,
      "z": -25,
      "name": "Rock_Lime_Cobble"
    },
    {
      "x": -40,
      "y": 8,
      "z": -25,
      "name": "Soil_Gravel_Lime"
    },
    {
      "x": -40,
      "y": 9,
      "z": -25,
      "name": "Rock_Lime"
    },
    {
      "x": -40,
      "y": 5,
      "z": -24,
      "name": "Rock_Lime_Cobble"
    },
    {
      "x": -40,
      "y": 6,
      "z": -24,
      "name": "Rock_Lime_Cobble"
    },
    {
      "x": -40,
      "y": 7,
      "z": -24,
      "name": "Soil_Gravel_Lime"
    },
    {
      "x": -40,
      "y": 8,
      "z": -24,
      "name": "Soil_Gravel_Lime"
    },
    {
      "x": -40,
      "y": 9,
      "z": -24,
      "name": "Rock_Lime_Cobble"
    },
    {
      "x": -40,
      "y": 5,
      "z": -23,
      "name": "Rock_Lime"
    },
    {
      "x": -40,
      "y": 6,
      "z": -23,
      "name": "Rock_Lime"
    },
    {
      "x": -40,
      "y": 7,
      "z": -23,
      "name": "Rock_Lime"
    },
    {
      "x": -40,
      "y": 8,
      "z": -23,
      "name": "Soil_Gravel_Lime"
    },
    {
      "x": -40,
      "y": 9,
      "z": -23,
      "name": "Rock_Lime_Cobble"
    },
    {
      "x": -40,
      "y": 5,
      "z": -22,
      "name": "Rock_Lime"
    },
    {
      "x": -40,
      "y": 6,
      "z": -22,
      "name": "Soil_Gravel_Lime"
    },
    {
      "x": -40,
      "y": 7,
      "z": -22,
      "name": "Rock_Lime"
    },
    {
      "x": -40,
      "y": 8,
      "z": -22,
      "name": "Rock_Lime"
    },
    {
      "x": -40,
      "y": 9,
      "z": -22,
      "name": "Rock_Lime"
    },
    {
      "x": -40,
      "y": 5,
      "z": -21,
      "name": "Rock_Lime"
    },
    {
      "x": -40,
      "y": 6,
      "z": -21,
      "name": "Rock_Lime_Cobble"
    },
    {
      "x": -40,
      "y": 7,
      "z": -21,
      "name": "Rock_Lime_Cobble"
    },
    {
      "x": -40,
      "y": 8,
      "z": -21,
      "name": "Rock_Lime_Cobble"
    },
    {
      "x": -40,
      "y": 9,
      "z": -21,
      "name": "Rock_Lime"
    },
    {
      "x": -40,
      "y": 10,
      "z": -21,
      "name": "Plant_Coral_Bush_Blue"
    },
    {
      "x": -40,
      "y": 5,
      "z": -20,
      "name": "Rock_Lime"
    },
    {
      "x": -40,
      "y": 6,
      "z": -20,
      "name": "Soil_Gravel_Lime"
    },
    {
      "x": -40,
      "y": 7,
      "z": -20,
      "name": "Soil_Gravel_Lime"
    },
    {
      "x": -40,
      "y": 8,
      "z": -20,
      "name": "Soil_Gravel_Lime"
    },
    {
      "x": -40,
      "y": 9,
      "z": -20,
      "name": "Soil_Gravel_Lime"
    },
    {
      "x": -40,
      "y": 5,
      "z": -19,
      "name": "Rock_Lime"
    },
    {
      "x": -40,
      "y": 6,
      "z": -19,
      "name": "Soil_Gravel_Lime"
    },
    {
      "x": -40,
      "y": 7,
      "z": -19,
      "name": "Rock_Lime_Cobble"
    },
    {
      "x": -40,
      "y": 8,
      "z": -19,
      "name": "Soil_Gravel_Lime"
    },
    {
      "x": -40,
      "y": 9,
      "z": -19,
      "name": "Rock_Lime"
    },
    {
      "x": -40,
      "y": 10,
      "z": -19,
      "name": "Plant_Coral_Model_Cyan"
    },
    {
      "x": -40,
      "y": 5,
      "z": -18,
      "name": "Rock_Lime_Cobble"
    },
    {
      "x": -40,
      "y": 6,
      "z": -18,
      "name": "Soil_Gravel_Lime"
    },
    {
      "x": -40,
      "y": 7,
      "z": -18,
      "name": "Rock_Lime"
    },
    {
      "x": -40,
      "y": 8,
      "z": -18,
      "name": "Soil_Gravel_Lime"
    },
    {
      "x": -40,
      "y": 9,
      "z": -18,
      "name": "Rock_Lime_Cobble"
    },
    {
      "x": -40,
      "y": 5,
      "z": -17,
      "name": "Rock_Lime"
    },
    {
      "x": -40,
      "y": 6,
      "z": -17,
      "name": "Soil_Gravel_Lime"
    },
    {
      "x": -40,
      "y": 7,
      "z": -17,
      "name": "Rock_Lime"
    },
    {
      "x": -40,
      "y": 8,
      "z": -17,
      "name": "Rock_Lime_Cobble"
    },
    {
      "x": -40,
      "y": 9,
      "z": -17,
      "name": "Soil_Gravel_Lime"
    },
    {
      "x": -40,
      "y": 6,
      "z": -16,
      "name": "Rock_Lime_Cobble"
    },
    {
      "x": -40,
      "y": 7,
      "z": -16,
      "name": "Soil_Gravel_Lime"
    },
    {
      "x": -40,
      "y": 8,
      "z": -16,
      "name": "Rock_Lime_Cobble"
    },
    {
      "x": -40,
      "y": 7,
      "z": -15,
      "name": "Rock_Lime"
    },
    {
      "x": -39,
      "y": 7,
      "z": -31,
      "name": "Rock_Lime"
    },
    {
      "x": -39,
      "y": 6,
      "z": -30,
      "name": "Rock_Lime"
    },
    {
      "x": -39,
      "y": 7,
      "z": -30,
      "name": "Soil_Gravel_Lime"
    },
    {
      "x": -39,
      "y": 8,
      "z": -30,
      "name": "Rock_Lime_Cobble"
    },
    {
      "x": -39,
      "y": 5,
      "z": -29,
      "name": "Rock_Lime_Cobble"
    },
    {
      "x": -39,
      "y": 6,
      "z": -29,
      "name": "Soil_Gravel_Lime"
    },
    {
      "x": -39,
      "y": 7,
      "z": -29,
      "name": "Soil_Gravel_Lime"
    },
    {
      "x": -39,
      "y": 8,
      "z": -29,
      "name": "Rock_Lime_Cobble"
    },
    {
      "x": -39,
      "y": 9,
      "z": -29,
      "name": "Rock_Lime"
    },
    {
      "x": -39,
      "y": 6,
      "z": -28,
      "name": "Rock_Lime"
    },
    {
      "x": -39,
      "y": 7,
      "z": -28,
      "name": "Rock_Lime"
    },
    {
      "x": -39,
      "y": 8,
      "z": -28,
      "name": "Rock_Lime"
    },
    {
      "x": -39,
      "y": 9,
      "z": -28,
      "name": "Rock_Lime"
    },
    {
      "x": -39,
      "y": 5,
      "z": -27,
      "name": "Rock_Lime"
    },
    {
      "x": -39,
      "y": 6,
      "z": -27,
      "name": "Rock_Lime"
    },
    {
      "x": -39,
      "y": 7,
      "z": -27,
      "name": "Soil_Gravel_Lime"
    },
    {
      "x": -39,
      "y": 8,
      "z": -27,
      "name": "Rock_Lime"
    },
    {
      "x": -39,
      "y": 9,
      "z": -27,
      "name": "Rock_Lime"
    },
    {
      "x": -39,
      "y": 5,
      "z": -26,
      "name": "Rock_Lime"
    },
    {
      "x": -39,
      "y": 6,
      "z": -26,
      "name": "Rock_Lime"
    },
    {
      "x": -39,
      "y": 7,
      "z": -26,
      "name": "Rock_Lime_Cobble"
    },
    {
      "x": -39,
      "y": 8,
      "z": -26,
      "name": "Soil_Gravel_Lime"
    },
    {
      "x": -39,
      "y": 9,
      "z": -26,
      "name": "Rock_Lime"
    },
    {
      "x": -39,
      "y": 10,
      "z": -26,
      "name": "Plant_Coral_Block_Blue"
    },
    {
      "x": -39,
      "y": 11,
      "z": -26,
      "name": "Plant_Coral_Block_Blue"
    },
    {
      "x": -39,
      "y": 12,
      "z": -26,
      "name": "Plant_Coral_Block_Blue"
    },
    {
      "x": -39,
      "y": 13,
      "z": -26,
      "name": "Plant_Coral_Block_Blue"
    },
    {
      "x": -39,
      "y": 14,
      "z": -26,
      "name": "Plant_Coral_Block_Blue"
    },
    {
      "x": -39,
      "y": 15,
      "z": -26,
      "name": "Plant_Coral_Block_Blue"
    },
    {
      "x": -39,
      "y": 5,
      "z": -25,
      "name": "Soil_Gravel_Lime"
    },
    {
      "x": -39,
      "y": 6,
      "z": -25,
      "name": "Rock_Lime_Cobble"
    },
    {
      "x": -39,
      "y": 7,
      "z": -25,
      "name": "Rock_Lime_Cobble"
    },
    {
      "x": -39,
      "y": 8,
      "z": -25,
      "name": "Rock_Lime"
    },
    {
      "x": -39,
      "y": 9,
      "z": -25,
      "name": "Soil_Gravel_Lime"
    },
    {
      "x": -39,
      "y": 10,
      "z": -25,
      "name": "Plant_Coral_Block_Blue"
    },
    {
      "x": -39,
      "y": 11,
      "z": -25,
      "name": "Plant_Coral_Block_Blue"
    },
    {
      "x": -39,
      "y": 12,
      "z": -25,
      "name": "Plant_Coral_Block_Blue"
    },
    {
      "x": -39,
      "y": 13,
      "z": -25,
      "name": "Plant_Coral_Block_Blue"
    },
    {
      "x": -39,
      "y": 14,
      "z": -25,
      "name": "Plant_Coral_Block_Blue"
    },
    {
      "x": -39,
      "y": 15,
      "z": -25,
      "name": "Plant_Coral_Block_Blue"
    },
    {
      "x": -39,
      "y": 16,
      "z": -25,
      "name": "Plant_Coral_Model_Blue"
    },
    {
      "x": -39,
      "y": 5,
      "z": -24,
      "name": "Rock_Lime"
    },
    {
      "x": -39,
      "y": 6,
      "z": -24,
      "name": "Rock_Lime"
    },
    {
      "x": -39,
      "y": 7,
      "z": -24,
      "name": "Rock_Lime_Cobble"
    },
    {
      "x": -39,
      "y": 8,
      "z": -24,
      "name": "Soil_Gravel_Lime"
    },
    {
      "x": -39,
      "y": 9,
      "z": -24,
      "name": "Rock_Lime_Cobble"
    },
    {
      "x": -39,
      "y": 10,
      "z": -24,
      "name": "Plant_Coral_Block_Blue"
    },
    {
      "x": -39,
      "y": 11,
      "z": -24,
      "name": "Plant_Coral_Block_Blue"
    },
    {
      "x": -39,
      "y": 12,
      "z": -24,
      "name": "Plant_Coral_Block_Blue"
    },
    {
      "x": -39,
      "y": 13,
      "z": -24,
      "name": "Plant_Coral_Block_Blue"
    },
    {
      "x": -39,
      "y": 14,
      "z": -24,
      "name": "Plant_Coral_Block_Blue"
    },
    {
      "x": -39,
      "y": 15,
      "z": -24,
      "name": "Plant_Coral_Block_Blue"
    },
    {
      "x": -39,
      "y": 5,
      "z": -23,
      "name": "Rock_Lime_Cobble"
    },
    {
      "x": -39,
      "y": 6,
      "z": -23,
      "name": "Soil_Gravel_Lime"
    },
    {
      "x": -39,
      "y": 7,
      "z": -23,
      "name": "Rock_Lime_Cobble"
    },
    {
      "x": -39,
      "y": 8,
      "z": -23,
      "name": "Rock_Lime"
    },
    {
      "x": -39,
      "y": 9,
      "z": -23,
      "name": "Soil_Gravel_Lime"
    },
    {
      "x": -39,
      "y": 10,
      "z": -23,
      "name": "Plant_Coral_Bush_Blue"
    },
    {
      "x": -39,
      "y": 5,
      "z": -22,
      "name": "Rock_Lime"
    },
    {
      "x": -39,
      "y": 6,
      "z": -22,
      "name": "Soil_Gravel_Lime"
    },
    {
      "x": -39,
      "y": 7,
      "z": -22,
      "name": "Rock_Lime_Cobble"
    },
    {
      "x": -39,
      "y": 8,
      "z": -22,
      "name": "Rock_Lime_Cobble"
    },
    {
      "x": -39,
      "y": 9,
      "z": -22,
      "name": "Rock_Lime"
    },
    {
      "x": -39,
      "y": 10,
      "z": -22,
      "name": "Plant_Coral_Bush_Blue"
    },
    {
      "x": -39,
      "y": 5,
      "z": -21,
      "name": "Rock_Lime_Cobble"
    },
    {
      "x": -39,
      "y": 6,
      "z": -21,
      "name": "Soil_Gravel_Lime"
    },
    {
      "x": -39,
      "y": 7,
      "z": -21,
      "name": "Rock_Lime_Cobble"
    },
    {
      "x": -39,
      "y": 8,
      "z": -21,
      "name": "Rock_Lime_Cobble"
    },
    {
      "x": -39,
      "y": 9,
      "z": -21,
      "name": "Soil_Gravel_Lime"
    },
    {
      "x": -39,
      "y": 5,
      "z": -20,
      "name": "Rock_Lime"
    },
    {
      "x": -39,
      "y": 6,
      "z": -20,
      "name": "Rock_Lime"
    },
    {
      "x": -39,
      "y": 7,
      "z": -20,
      "name": "Rock_Lime"
    },
    {
      "x": -39,
      "y": 8,
      "z": -20,
      "name": "Soil_Gravel_Lime"
    },
    {
      "x": -39,
      "y": 9,
      "z": -20,
      "name": "Rock_Lime_Cobble"
    },
    {
      "x": -39,
      "y": 5,
      "z": -19,
      "name": "Rock_Lime_Cobble"
    },
    {
      "x": -39,
      "y": 6,
      "z": -19,
      "name": "Rock_Lime"
    },
    {
      "x": -39,
      "y": 7,
      "z": -19,
      "name": "Soil_Gravel_Lime"
    },
    {
      "x": -39,
      "y": 8,
      "z": -19,
      "name": "Rock_Lime"
    },
    {
      "x": -39,
      "y": 9,
      "z": -19,
      "name": "Rock_Lime_Cobble"
    },
    {
      "x": -39,
      "y": 13,
      "z": -19,
      "name": "Plant_Coral_Block_Blue"
    },
    {
      "x": -39,
      "y": 14,
      "z": -19,
      "name": "Plant_Coral_Block_Blue"
    },
    {
      "x": -39,
      "y": 15,
      "z": -19,
      "name": "Plant_Coral_Block_Blue"
    },
    {
      "x": -39,
      "y": 16,
      "z": -19,
      "name": "Plant_Coral_Block_Blue"
    },
    {
      "x": -39,
      "y": 17,
      "z": -19,
      "name": "Plant_Coral_Block_Blue"
    },
    {
      "x": -39,
      "y": 18,
      "z": -19,
      "name": "Plant_Coral_Model_Blue"
    },
    {
      "x": -39,
      "y": 5,
      "z": -18,
      "name": "Rock_Lime"
    },
    {
      "x": -39,
      "y": 6,
      "z": -18,
      "name": "Rock_Lime_Cobble"
    },
    {
      "x": -39,
      "y": 7,
      "z": -18,
      "name": "Rock_Lime_Cobble"
    },
    {
      "x": -39,
      "y": 8,
      "z": -18,
      "name": "Rock_Lime_Cobble"
    },
    {
      "x": -39,
      "y": 9,
      "z": -18,
      "name": "Rock_Lime"
    },
    {
      "x": -39,
      "y": 13,
      "z": -18,
      "name": "Plant_Coral_Block_Blue"
    },
    {
      "x": -39,
      "y": 14,
      "z": -18,
      "name": "Plant_Coral_Block_Blue"
    },
    {
      "x": -39,
      "y": 15,
      "z": -18,
      "name": "Plant_Coral_Block_Blue"
    },
    {
      "x": -39,
      "y": 16,
      "z": -18,
      "name": "Plant_Coral_Block_Blue"
    },
    {
      "x": -39,
      "y": 17,
      "z": -18,
      "name": "Plant_Coral_Block_Blue"
    },
    {
      "x": -39,
      "y": 5,
      "z": -17,
      "name": "Rock_Lime_Cobble"
    },
    {
      "x": -39,
      "y": 6,
      "z": -17,
      "name": "Soil_Gravel_Lime"
    },
    {
      "x": -39,
      "y": 7,
      "z": -17,
      "name": "Rock_Lime"
    },
    {
      "x": -39,
      "y": 8,
      "z": -17,
      "name": "Soil_Gravel_Lime"
    },
    {
      "x": -39,
      "y": 9,
      "z": -17,
      "name": "Rock_Lime_Cobble"
    },
    {
      "x": -39,
      "y": 13,
      "z": -17,
      "name": "Plant_Coral_Block_Blue"
    },
    {
      "x": -39,
      "y": 14,
      "z": -17,
      "name": "Plant_Coral_Block_Blue"
    },
    {
      "x": -39,
      "y": 15,
      "z": -17,
      "name": "Plant_Coral_Block_Blue"
    },
    {
      "x": -39,
      "y": 16,
      "z": -17,
      "name": "Plant_Coral_Block_Blue"
    },
    {
      "x": -39,
      "y": 17,
      "z": -17,
      "name": "Plant_Coral_Block_Blue"
    },
    {
      "x": -39,
      "y": 5,
      "z": -16,
      "name": "Soil_Gravel_Lime"
    },
    {
      "x": -39,
      "y": 6,
      "z": -16,
      "name": "Rock_Lime_Cobble"
    },
    {
      "x": -39,
      "y": 7,
      "z": -16,
      "name": "Soil_Gravel_Lime"
    },
    {
      "x": -39,
      "y": 8,
      "z": -16,
      "name": "Rock_Lime_Cobble"
    },
    {
      "x": -39,
      "y": 9,
      "z": -16,
      "name": "Rock_Lime"
    },
    {
      "x": -39,
      "y": 6,
      "z": -15,
      "name": "Rock_Lime"
    },
    {
      "x": -39,
      "y": 7,
      "z": -15,
      "name": "Soil_Gravel_Lime"
    },
    {
      "x": -39,
      "y": 8,
      "z": -15,
      "name": "Rock_Lime"
    },
    {
      "x": -39,
      "y": 7,
      "z": -14,
      "name": "Rock_Lime"
    },
    {
      "x": -38,
      "y": 6,
      "z": -31,
      "name": "Soil_Gravel_Lime"
    },
    {
      "x": -38,
      "y": 7,
      "z": -31,
      "name": "Rock_Lime"
    },
    {
      "x": -38,
      "y": 8,
      "z": -31,
      "name": "Soil_Gravel_Lime"
    },
    {
      "x": -38,
      "y": 5,
      "z": -30,
      "name": "Rock_Lime"
    },
    {
      "x": -38,
      "y": 6,
      "z": -30,
      "name": "Soil_Gravel_Lime"
    },
    {
      "x": -38,
      "y": 7,
      "z": -30,
      "name": "Rock_Lime"
    },
    {
      "x": -38,
      "y": 8,
      "z": -30,
      "name": "Rock_Lime_Cobble"
    },
    {
      "x": -38,
      "y": 9,
      "z": -30,
      "name": "Rock_Lime"
    },
    {
      "x": -38,
      "y": 5,
      "z": -29,
      "name": "Rock_Lime"
    },
    {
      "x": -38,
      "y": 6,
      "z": -29,
      "name": "Soil_Gravel_Lime"
    },
    {
      "x": -38,
      "y": 7,
      "z": -29,
      "name": "Rock_Lime_Cobble"
    },
    {
      "x": -38,
      "y": 8,
      "z": -29,
      "name": "Rock_Lime_Cobble"
    },
    {
      "x": -38,
      "y": 9,
      "z": -29,
      "name": "Rock_Lime"
    },
    {
      "x": -38,
      "y": 5,
      "z": -28,
      "name": "Rock_Lime_Cobble"
    },
    {
      "x": -38,
      "y": 6,
      "z": -28,
      "name": "Soil_Gravel_Lime"
    },
    {
      "x": -38,
      "y": 7,
      "z": -28,
      "name": "Rock_Lime_Cobble"
    },
    {
      "x": -38,
      "y": 8,
      "z": -28,
      "name": "Rock_Lime"
    },
    {
      "x": -38,
      "y": 9,
      "z": -28,
      "name": "Rock_Lime_Cobble"
    },
    {
      "x": -38,
      "y": 5,
      "z": -27,
      "name": "Rock_Lime"
    },
    {
      "x": -38,
      "y": 6,
      "z": -27,
      "name": "Soil_Gravel_Lime"
    },
    {
      "x": -38,
      "y": 7,
      "z": -27,
      "name": "Rock_Lime_Cobble"
    },
    {
      "x": -38,
      "y": 8,
      "z": -27,
      "name": "Soil_Gravel_Lime"
    },
    {
      "x": -38,
      "y": 9,
      "z": -27,
      "name": "Rock_Lime_Cobble"
    },
    {
      "x": -38,
      "y": 10,
      "z": -27,
      "name": "Plant_Coral_Block_Blue"
    },
    {
      "x": -38,
      "y": 11,
      "z": -27,
      "name": "Plant_Coral_Block_Blue"
    },
    {
      "x": -38,
      "y": 12,
      "z": -27,
      "name": "Plant_Coral_Block_Blue"
    },
    {
      "x": -38,
      "y": 13,
      "z": -27,
      "name": "Plant_Coral_Block_Blue"
    },
    {
      "x": -38,
      "y": 14,
      "z": -27,
      "name": "Plant_Coral_Block_Blue"
    },
    {
      "x": -38,
      "y": 15,
      "z": -27,
      "name": "Plant_Coral_Block_Blue"
    },
    {
      "x": -38,
      "y": 5,
      "z": -26,
      "name": "Soil_Gravel_Lime"
    },
    {
      "x": -38,
      "y": 6,
      "z": -26,
      "name": "Rock_Lime_Cobble"
    },
    {
      "x": -38,
      "y": 7,
      "z": -26,
      "name": "Rock_Lime_Cobble"
    },
    {
      "x": -38,
      "y": 8,
      "z": -26,
      "name": "Rock_Lime_Cobble"
    },
    {
      "x": -38,
      "y": 9,
      "z": -26,
      "name": "Rock_Lime_Cobble"
    },
    {
      "x": -38,
      "y": 10,
      "z": -26,
      "name": "Plant_Coral_Block_Blue"
    },
    {
      "x": -38,
      "y": 11,
      "z": -26,
      "name": "Plant_Coral_Block_Blue"
    },
    {
      "x": -38,
      "y": 12,
      "z": -26,
      "name": "Plant_Coral_Block_Blue"
    },
    {
      "x": -38,
      "y": 13,
      "z": -26,
      "name": "Plant_Coral_Block_Blue"
    },
    {
      "x": -38,
      "y": 14,
      "z": -26,
      "name": "Plant_Coral_Block_Cyan"
    },
    {
      "x": -38,
      "y": 5,
      "z": -25,
      "name": "Rock_Lime_Cobble"
    },
    {
      "x": -38,
      "y": 6,
      "z": -25,
      "name": "Soil_Gravel_Lime"
    },
    {
      "x": -38,
      "y": 7,
      "z": -25,
      "name": "Rock_Lime_Cobble"
    },
    {
      "x": -38,
      "y": 8,
      "z": -25,
      "name": "Rock_Lime"
    },
    {
      "x": -38,
      "y": 9,
      "z": -25,
      "name": "Rock_Lime_Cobble"
    },
    {
      "x": -38,
      "y": 10,
      "z": -25,
      "name": "Plant_Coral_Block_Blue"
    },
    {
      "x": -38,
      "y": 11,
      "z": -25,
      "name": "Plant_Coral_Block_Blue"
    },
    {
      "x": -38,
      "y": 12,
      "z": -25,
      "name": "Plant_Coral_Block_Blue"
    },
    {
      "x": -38,
      "y": 13,
      "z": -25,
      "name": "Plant_Coral_Block_Blue"
    },
    {
      "x": -38,
      "y": 14,
      "z": -25,
      "name": "Plant_Coral_Block_Blue"
    },
    {
      "x": -38,
      "y": 15,
      "z": -25,
      "name": "Plant_Coral_Block_Blue"
    },
    {
      "x": -38,
      "y": 16,
      "z": -25,
      "name": "Plant_Coral_Block_Blue"
    },
    {
      "x": -38,
      "y": 17,
      "z": -25,
      "name": "Plant_Coral_Block_Blue"
    },
    {
      "x": -38,
      "y": 5,
      "z": -24,
      "name": "Rock_Lime"
    },
    {
      "x": -38,
      "y": 6,
      "z": -24,
      "name": "Rock_Lime"
    },
    {
      "x": -38,
      "y": 7,
      "z": -24,
      "name": "Rock_Lime"
    },
    {
      "x": -38,
      "y": 8,
      "z": -24,
      "name": "Rock_Lime"
    },
    {
      "x": -38,
      "y": 9,
      "z": -24,
      "name": "Rock_Lime_Cobble"
    },
    {
      "x": -38,
      "y": 10,
      "z": -24,
      "name": "Plant_Coral_Block_Blue"
    },
    {
      "x": -38,
      "y": 11,
      "z": -24,
      "name": "Plant_Coral_Block_Blue"
    },
    {
      "x": -38,
      "y": 12,
      "z": -24,
      "name": "Plant_Coral_Block_Blue"
    },
    {
      "x": -38,
      "y": 13,
      "z": -24,
      "name": "Plant_Coral_Block_Blue"
    },
    {
      "x": -38,
      "y": 14,
      "z": -24,
      "name": "Plant_Coral_Block_Blue"
    },
    {
      "x": -38,
      "y": 15,
      "z": -24,
      "name": "Plant_Coral_Block_Blue"
    },
    {
      "x": -38,
      "y": 16,
      "z": -24,
      "name": "Plant_Coral_Block_Blue"
    },
    {
      "x": -38,
      "y": 17,
      "z": -24,
      "name": "Plant_Coral_Block_Blue"
    },
    {
      "x": -38,
      "y": 5,
      "z": -23,
      "name": "Soil_Gravel_Lime"
    },
    {
      "x": -38,
      "y": 6,
      "z": -23,
      "name": "Rock_Lime_Cobble"
    },
    {
      "x": -38,
      "y": 7,
      "z": -23,
      "name": "Rock_Lime_Cobble"
    },
    {
      "x": -38,
      "y": 8,
      "z": -23,
      "name": "Rock_Lime_Cobble"
    },
    {
      "x": -38,
      "y": 9,
      "z": -23,
      "name": "Rock_Lime"
    },
    {
      "x": -38,
      "y": 10,
      "z": -23,
      "name": "Plant_Coral_Block_Blue"
    },
    {
      "x": -38,
      "y": 11,
      "z": -23,
      "name": "Plant_Coral_Block_Blue"
    },
    {
      "x": -38,
      "y": 12,
      "z": -23,
      "name": "Plant_Coral_Block_Blue"
    },
    {
      "x": -38,
      "y": 13,
      "z": -23,
      "name": "Plant_Coral_Block_Blue"
    },
    {
      "x": -38,
      "y": 14,
      "z": -23,
      "name": "Plant_Coral_Block_Blue"
    },
    {
      "x": -38,
      "y": 15,
      "z": -23,
      "name": "Plant_Coral_Block_Blue"
    },
    {
      "x": -38,
      "y": 16,
      "z": -23,
      "name": "Plant_Coral_Block_Blue"
    },
    {
      "x": -38,
      "y": 17,
      "z": -23,
      "name": "Plant_Coral_Block_Blue"
    },
    {
      "x": -38,
      "y": 18,
      "z": -23,
      "name": "Plant_Coral_Model_Blue"
    },
    {
      "x": -38,
      "y": 5,
      "z": -22,
      "name": "Rock_Lime"
    },
    {
      "x": -38,
      "y": 6,
      "z": -22,
      "name": "Rock_Lime_Cobble"
    },
    {
      "x": -38,
      "y": 7,
      "z": -22,
      "name": "Soil_Gravel_Lime"
    },
    {
      "x": -38,
      "y": 8,
      "z": -22,
      "name": "Rock_Lime"
    },
    {
      "x": -38,
      "y": 9,
      "z": -22,
      "name": "Rock_Lime_Cobble"
    },
    {
      "x": -38,
      "y": 5,
      "z": -21,
      "name": "Rock_Lime"
    },
    {
      "x": -38,
      "y": 6,
      "z": -21,
      "name": "Soil_Gravel_Lime"
    },
    {
      "x": -38,
      "y": 7,
      "z": -21,
      "name": "Rock_Lime_Cobble"
    },
    {
      "x": -38,
      "y": 8,
      "z": -21,
      "name": "Soil_Gravel_Lime"
    },
    {
      "x": -38,
      "y": 9,
      "z": -21,
      "name": "Soil_Gravel_Lime"
    },
    {
      "x": -38,
      "y": 5,
      "z": -20,
      "name": "Soil_Gravel_Lime"
    },
    {
      "x": -38,
      "y": 6,
      "z": -20,
      "name": "Soil_Gravel_Lime"
    },
    {
      "x": -38,
      "y": 7,
      "z": -20,
      "name": "Rock_Lime"
    },
    {
      "x": -38,
      "y": 8,
      "z": -20,
      "name": "Rock_Lime_Cobble"
    },
    {
      "x": -38,
      "y": 9,
      "z": -20,
      "name": "Rock_Lime"
    },
    {
      "x": -38,
      "y": 10,
      "z": -20,
      "name": "Plant_Coral_Block_Blue"
    },
    {
      "x": -38,
      "y": 11,
      "z": -20,
      "name": "Plant_Coral_Block_Blue"
    },
    {
      "x": -38,
      "y": 12,
      "z": -20,
      "name": "Plant_Coral_Block_Blue"
    },
    {
      "x": -38,
      "y": 13,
      "z": -20,
      "name": "Plant_Coral_Block_Blue"
    },
    {
      "x": -38,
      "y": 14,
      "z": -20,
      "name": "Plant_Coral_Block_Blue"
    },
    {
      "x": -38,
      "y": 15,
      "z": -20,
      "name": "Plant_Coral_Block_Blue"
    },
    {
      "x": -38,
      "y": 16,
      "z": -20,
      "name": "Plant_Coral_Block_Blue"
    },
    {
      "x": -38,
      "y": 17,
      "z": -20,
      "name": "Plant_Coral_Block_Blue"
    },
    {
      "x": -38,
      "y": 5,
      "z": -19,
      "name": "Rock_Lime_Cobble"
    },
    {
      "x": -38,
      "y": 6,
      "z": -19,
      "name": "Rock_Lime_Cobble"
    },
    {
      "x": -38,
      "y": 7,
      "z": -19,
      "name": "Rock_Lime_Cobble"
    },
    {
      "x": -38,
      "y": 8,
      "z": -19,
      "name": "Soil_Gravel_Lime"
    },
    {
      "x": -38,
      "y": 9,
      "z": -19,
      "name": "Soil_Gravel_Lime"
    },
    {
      "x": -38,
      "y": 10,
      "z": -19,
      "name": "Plant_Coral_Block_Blue"
    },
    {
      "x": -38,
      "y": 11,
      "z": -19,
      "name": "Plant_Coral_Block_Blue"
    },
    {
      "x": -38,
      "y": 12,
      "z": -19,
      "name": "Plant_Coral_Block_Blue"
    },
    {
      "x": -38,
      "y": 13,
      "z": -19,
      "name": "Plant_Coral_Block_Blue"
    },
    {
      "x": -38,
      "y": 14,
      "z": -19,
      "name": "Plant_Coral_Block_Blue"
    },
    {
      "x": -38,
      "y": 15,
      "z": -19,
      "name": "Plant_Coral_Block_Blue"
    },
    {
      "x": -38,
      "y": 16,
      "z": -19,
      "name": "Plant_Coral_Block_Cyan"
    },
    {
      "x": -38,
      "y": 5,
      "z": -18,
      "name": "Soil_Gravel_Lime"
    },
    {
      "x": -38,
      "y": 6,
      "z": -18,
      "name": "Soil_Gravel_Lime"
    },
    {
      "x": -38,
      "y": 7,
      "z": -18,
      "name": "Soil_Gravel_Lime"
    },
    {
      "x": -38,
      "y": 8,
      "z": -18,
      "name": "Rock_Lime"
    },
    {
      "x": -38,
      "y": 9,
      "z": -18,
      "name": "Rock_Lime"
    },
    {
      "x": -38,
      "y": 10,
      "z": -18,
      "name": "Plant_Coral_Block_Blue"
    },
    {
      "x": -38,
      "y": 11,
      "z": -18,
      "name": "Plant_Coral_Block_Blue"
    },
    {
      "x": -38,
      "y": 12,
      "z": -18,
      "name": "Plant_Coral_Block_Blue"
    },
    {
      "x": -38,
      "y": 13,
      "z": -18,
      "name": "Plant_Coral_Block_Blue"
    },
    {
      "x": -38,
      "y": 14,
      "z": -18,
      "name": "Plant_Coral_Block_Blue"
    },
    {
      "x": -38,
      "y": 15,
      "z": -18,
      "name": "Plant_Coral_Block_Blue"
    },
    {
      "x": -38,
      "y": 16,
      "z": -18,
      "name": "Plant_Coral_Block_Cyan"
    },
    {
      "x": -38,
      "y": 5,
      "z": -17,
      "name": "Soil_Gravel_Lime"
    },
    {
      "x": -38,
      "y": 6,
      "z": -17,
      "name": "Rock_Lime_Cobble"
    },
    {
      "x": -38,
      "y": 7,
      "z": -17,
      "name": "Soil_Gravel_Lime"
    },
    {
      "x": -38,
      "y": 8,
      "z": -17,
      "name": "Rock_Lime_Cobble"
    },
    {
      "x": -38,
      "y": 9,
      "z": -17,
      "name": "Rock_Lime"
    },
    {
      "x": -38,
      "y": 10,
      "z": -17,
      "name": "Plant_Coral_Model_Cyan"
    },
    {
      "x": -38,
      "y": 13,
      "z": -17,
      "name": "Plant_Coral_Block_Blue"
    },
    {
      "x": -38,
      "y": 14,
      "z": -17,
      "name": "Plant_Coral_Block_Blue"
    },
    {
      "x": -38,
      "y": 15,
      "z": -17,
      "name": "Plant_Coral_Block_Blue"
    },
    {
      "x": -38,
      "y": 16,
      "z": -17,
      "name": "Plant_Coral_Block_Cyan"
    },
    {
      "x": -38,
      "y": 5,
      "z": -16,
      "name": "Rock_Lime"
    },
    {
      "x": -38,
      "y": 6,
      "z": -16,
      "name": "Rock_Lime"
    },
    {
      "x": -38,
      "y": 7,
      "z": -16,
      "name": "Rock_Lime_Cobble"
    },
    {
      "x": -38,
      "y": 8,
      "z": -16,
      "name": "Soil_Gravel_Lime"
    },
    {
      "x": -38,
      "y": 9,
      "z": -16,
      "name": "Soil_Gravel_Lime"
    },
    {
      "x": -38,
      "y": 13,
      "z": -16,
      "name": "Plant_Coral_Block_Blue"
    },
    {
      "x": -38,
      "y": 14,
      "z": -16,
      "name": "Plant_Coral_Block_Blue"
    },
    {
      "x": -38,
      "y": 15,
      "z": -16,
      "name": "Plant_Coral_Block_Blue"
    },
    {
      "x": -38,
      "y": 16,
      "z": -16,
      "name": "Plant_Coral_Block_Blue"
    },
    {
      "x": -38,
      "y": 17,
      "z": -16,
      "name": "Plant_Coral_Block_Blue"
    },
    {
      "x": -38,
      "y": 5,
      "z": -15,
      "name": "Rock_Lime_Cobble"
    },
    {
      "x": -38,
      "y": 6,
      "z": -15,
      "name": "Soil_Gravel_Lime"
    },
    {
      "x": -38,
      "y": 7,
      "z": -15,
      "name": "Soil_Gravel_Lime"
    },
    {
      "x": -38,
      "y": 8,
      "z": -15,
      "name": "Rock_Lime_Cobble"
    },
    {
      "x": -38,
      "y": 9,
      "z": -15,
      "name": "Rock_Lime"
    },
    {
      "x": -38,
      "y": 6,
      "z": -14,
      "name": "Rock_Lime"
    },
    {
      "x": -38,
      "y": 7,
      "z": -14,
      "name": "Rock_Lime"
    },
    {
      "x": -38,
      "y": 8,
      "z": -14,
      "name": "Rock_Lime"
    },
    {
      "x": -38,
      "y": 7,
      "z": -13,
      "name": "Soil_Gravel_Lime"
    },
    {
      "x": -37,
      "y": 7,
      "z": -31,
      "name": "Soil_Gravel_Lime"
    },
    {
      "x": -37,
      "y": 6,
      "z": -30,
      "name": "Rock_Lime"
    },
    {
      "x": -37,
      "y": 7,
      "z": -30,
      "name": "Rock_Lime_Cobble"
    },
    {
      "x": -37,
      "y": 8,
      "z": -30,
      "name": "Rock_Lime"
    },
    {
      "x": -37,
      "y": 5,
      "z": -29,
      "name": "Soil_Gravel_Lime"
    },
    {
      "x": -37,
      "y": 6,
      "z": -29,
      "name": "Soil_Gravel_Lime"
    },
    {
      "x": -37,
      "y": 7,
      "z": -29,
      "name": "Rock_Lime"
    },
    {
      "x": -37,
      "y": 8,
      "z": -29,
      "name": "Soil_Gravel_Lime"
    },
    {
      "x": -37,
      "y": 9,
      "z": -29,
      "name": "Rock_Lime_Cobble"
    },
    {
      "x": -37,
      "y": 5,
      "z": -28,
      "name": "Soil_Gravel_Lime"
    },
    {
      "x": -37,
      "y": 6,
      "z": -28,
      "name": "Rock_Lime_Cobble"
    },
    {
      "x": -37,
      "y": 7,
      "z": -28,
      "name": "Soil_Gravel_Lime"
    },
    {
      "x": -37,
      "y": 8,
      "z": -28,
      "name": "Rock_Lime_Cobble"
    },
    {
      "x": -37,
      "y": 9,
      "z": -28,
      "name": "Soil_Gravel_Lime"
    },
    {
      "x": -37,
      "y": 5,
      "z": -27,
      "name": "Rock_Lime_Cobble"
    },
    {
      "x": -37,
      "y": 6,
      "z": -27,
      "name": "Soil_Gravel_Lime"
    },
    {
      "x": -37,
      "y": 7,
      "z": -27,
      "name": "Soil_Gravel_Lime"
    },
    {
      "x": -37,
      "y": 8,
      "z": -27,
      "name": "Soil_Gravel_Lime"
    },
    {
      "x": -37,
      "y": 9,
      "z": -27,
      "name": "Rock_Lime_Cobble"
    },
    {
      "x": -37,
      "y": 10,
      "z": -27,
      "name": "Plant_Coral_Block_Blue"
    },
    {
      "x": -37,
      "y": 11,
      "z": -27,
      "name": "Plant_Coral_Block_Blue"
    },
    {
      "x": -37,
      "y": 12,
      "z": -27,
      "name": "Plant_Coral_Block_Blue"
    },
    {
      "x": -37,
      "y": 13,
      "z": -27,
      "name": "Plant_Coral_Block_Blue"
    },
    {
      "x": -37,
      "y": 14,
      "z": -27,
      "name": "Plant_Coral_Block_Blue"
    },
    {
      "x": -37,
      "y": 15,
      "z": -27,
      "name": "Plant_Coral_Block_Blue"
    },
    {
      "x": -37,
      "y": 16,
      "z": -27,
      "name": "Plant_Coral_Model_Blue"
    },
    {
      "x": -37,
      "y": 5,
      "z": -26,
      "name": "Rock_Lime"
    },
    {
      "x": -37,
      "y": 6,
      "z": -26,
      "name": "Rock_Lime"
    },
    {
      "x": -37,
      "y": 7,
      "z": -26,
      "name": "Rock_Lime_Cobble"
    },
    {
      "x": -37,
      "y": 8,
      "z": -26,
      "name": "Rock_Lime_Cobble"
    },
    {
      "x": -37,
      "y": 9,
      "z": -26,
      "name": "Rock_Lime_Cobble"
    },
    {
      "x": -37,
      "y": 10,
      "z": -26,
      "name": "Plant_Coral_Block_Blue"
    },
    {
      "x": -37,
      "y": 11,
      "z": -26,
      "name": "Plant_Coral_Block_Blue"
    },
    {
      "x": -37,
      "y": 12,
      "z": -26,
      "name": "Plant_Coral_Block_Blue"
    },
    {
      "x": -37,
      "y": 13,
      "z": -26,
      "name": "Plant_Coral_Block_Blue"
    },
    {
      "x": -37,
      "y": 14,
      "z": -26,
      "name": "Plant_Coral_Block_Blue"
    },
    {
      "x": -37,
      "y": 15,
      "z": -26,
      "name": "Plant_Coral_Block_Blue"
    },
    {
      "x": -37,
      "y": 16,
      "z": -26,
      "name": "Plant_Coral_Block_Blue"
    },
    {
      "x": -37,
      "y": 17,
      "z": -26,
      "name": "Plant_Coral_Block_Blue"
    },
    {
      "x": -37,
      "y": 5,
      "z": -25,
      "name": "Rock_Lime_Cobble"
    },
    {
      "x": -37,
      "y": 6,
      "z": -25,
      "name": "Rock_Lime"
    },
    {
      "x": -37,
      "y": 7,
      "z": -25,
      "name": "Rock_Lime_Cobble"
    },
    {
      "x": -37,
      "y": 8,
      "z": -25,
      "name": "Rock_Lime_Cobble"
    },
    {
      "x": -37,
      "y": 9,
      "z": -25,
      "name": "Rock_Lime_Cobble"
    },
    {
      "x": -37,
      "y": 10,
      "z": -25,
      "name": "Plant_Coral_Block_Blue"
    },
    {
      "x": -37,
      "y": 11,
      "z": -25,
      "name": "Plant_Coral_Block_Blue"
    },
    {
      "x": -37,
      "y": 12,
      "z": -25,
      "name": "Plant_Coral_Block_Blue"
    },
    {
      "x": -37,
      "y": 13,
      "z": -25,
      "name": "Plant_Coral_Block_Blue"
    },
    {
      "x": -37,
      "y": 14,
      "z": -25,
      "name": "Plant_Coral_Block_Blue"
    },
    {
      "x": -37,
      "y": 15,
      "z": -25,
      "name": "Plant_Coral_Block_Blue"
    },
    {
      "x": -37,
      "y": 16,
      "z": -25,
      "name": "Plant_Coral_Block_Cyan"
    },
    {
      "x": -37,
      "y": 5,
      "z": -24,
      "name": "Rock_Lime"
    },
    {
      "x": -37,
      "y": 6,
      "z": -24,
      "name": "Soil_Gravel_Lime"
    },
    {
      "x": -37,
      "y": 7,
      "z": -24,
      "name": "Rock_Lime_Cobble"
    },
    {
      "x": -37,
      "y": 8,
      "z": -24,
      "name": "Soil_Gravel_Lime"
    },
    {
      "x": -37,
      "y": 9,
      "z": -24,
      "name": "Rock_Lime_Cobble"
    },
    {
      "x": -37,
      "y": 10,
      "z": -24,
      "name": "Plant_Coral_Block_Blue"
    },
    {
      "x": -37,
      "y": 11,
      "z": -24,
      "name": "Plant_Coral_Block_Blue"
    },
    {
      "x": -37,
      "y": 12,
      "z": -24,
      "name": "Plant_Coral_Block_Blue"
    },
    {
      "x": -37,
      "y": 13,
      "z": -24,
      "name": "Plant_Coral_Block_Blue"
    },
    {
      "x": -37,
      "y": 14,
      "z": -24,
      "name": "Plant_Coral_Block_Blue"
    },
    {
      "x": -37,
      "y": 15,
      "z": -24,
      "name": "Plant_Coral_Block_Blue"
    },
    {
      "x": -37,
      "y": 16,
      "z": -24,
      "name": "Plant_Coral_Block_Cyan"
    },
    {
      "x": -37,
      "y": 5,
      "z": -23,
      "name": "Rock_Lime"
    },
    {
      "x": -37,
      "y": 6,
      "z": -23,
      "name": "Rock_Lime_Cobble"
    },
    {
      "x": -37,
      "y": 7,
      "z": -23,
      "name": "Rock_Lime_Cobble"
    },
    {
      "x": -37,
      "y": 8,
      "z": -23,
      "name": "Soil_Gravel_Lime"
    },
    {
      "x": -37,
      "y": 9,
      "z": -23,
      "name": "Rock_Lime_Cobble"
    },
    {
      "x": -37,
      "y": 10,
      "z": -23,
      "name": "Plant_Coral_Block_Blue"
    },
    {
      "x": -37,
      "y": 11,
      "z": -23,
      "name": "Plant_Coral_Block_Blue"
    },
    {
      "x": -37,
      "y": 12,
      "z": -23,
      "name": "Plant_Coral_Block_Blue"
    },
    {
      "x": -37,
      "y": 13,
      "z": -23,
      "name": "Plant_Coral_Block_Blue"
    },
    {
      "x": -37,
      "y": 14,
      "z": -23,
      "name": "Plant_Coral_Block_Blue"
    },
    {
      "x": -37,
      "y": 15,
      "z": -23,
      "name": "Plant_Coral_Block_Blue"
    },
    {
      "x": -37,
      "y": 16,
      "z": -23,
      "name": "Plant_Coral_Block_Cyan"
    },
    {
      "x": -37,
      "y": 5,
      "z": -22,
      "name": "Soil_Gravel_Lime"
    },
    {
      "x": -37,
      "y": 6,
      "z": -22,
      "name": "Rock_Lime_Cobble"
    },
    {
      "x": -37,
      "y": 7,
      "z": -22,
      "name": "Rock_Lime_Cobble"
    },
    {
      "x": -37,
      "y": 8,
      "z": -22,
      "name": "Rock_Lime"
    },
    {
      "x": -37,
      "y": 9,
      "z": -22,
      "name": "Rock_Lime"
    },
    {
      "x": -37,
      "y": 13,
      "z": -22,
      "name": "Plant_Coral_Block_Blue"
    },
    {
      "x": -37,
      "y": 14,
      "z": -22,
      "name": "Plant_Coral_Block_Blue"
    },
    {
      "x": -37,
      "y": 15,
      "z": -22,
      "name": "Plant_Coral_Block_Blue"
    },
    {
      "x": -37,
      "y": 16,
      "z": -22,
      "name": "Plant_Coral_Block_Blue"
    },
    {
      "x": -37,
      "y": 17,
      "z": -22,
      "name": "Plant_Coral_Block_Blue"
    },
    {
      "x": -37,
      "y": 18,
      "z": -22,
      "name": "Plant_Coral_Model_Blue"
    },
    {
      "x": -37,
      "y": 5,
      "z": -21,
      "name": "Rock_Lime"
    },
    {
      "x": -37,
      "y": 6,
      "z": -21,
      "name": "Rock_Lime_Cobble"
    },
    {
      "x": -37,
      "y": 7,
      "z": -21,
      "name": "Soil_Gravel_Lime"
    },
    {
      "x": -37,
      "y": 8,
      "z": -21,
      "name": "Rock_Lime_Cobble"
    },
    {
      "x": -37,
      "y": 9,
      "z": -21,
      "name": "Rock_Lime"
    },
    {
      "x": -37,
      "y": 10,
      "z": -21,
      "name": "Plant_Coral_Block_Blue"
    },
    {
      "x": -37,
      "y": 11,
      "z": -21,
      "name": "Plant_Coral_Block_Blue"
    },
    {
      "x": -37,
      "y": 12,
      "z": -21,
      "name": "Plant_Coral_Block_Blue"
    },
    {
      "x": -37,
      "y": 13,
      "z": -21,
      "name": "Plant_Coral_Block_Blue"
    },
    {
      "x": -37,
      "y": 14,
      "z": -21,
      "name": "Plant_Coral_Block_Blue"
    },
    {
      "x": -37,
      "y": 15,
      "z": -21,
      "name": "Plant_Coral_Block_Blue"
    },
    {
      "x": -37,
      "y": 5,
      "z": -20,
      "name": "Rock_Lime_Cobble"
    },
    {
      "x": -37,
      "y": 6,
      "z": -20,
      "name": "Soil_Gravel_Lime"
    },
    {
      "x": -37,
      "y": 7,
      "z": -20,
      "name": "Rock_Lime_Cobble"
    },
    {
      "x": -37,
      "y": 8,
      "z": -20,
      "name": "Soil_Gravel_Lime"
    },
    {
      "x": -37,
      "y": 9,
      "z": -20,
      "name": "Rock_Lime"
    },
    {
      "x": -37,
      "y": 10,
      "z": -20,
      "name": "Plant_Coral_Block_Blue"
    },
    {
      "x": -37,
      "y": 11,
      "z": -20,
      "name": "Plant_Coral_Block_Blue"
    },
    {
      "x": -37,
      "y": 12,
      "z": -20,
      "name": "Plant_Coral_Block_Blue"
    },
    {
      "x": -37,
      "y": 13,
      "z": -20,
      "name": "Plant_Coral_Block_Blue"
    },
    {
      "x": -37,
      "y": 14,
      "z": -20,
      "name": "Plant_Coral_Block_Blue"
    },
    {
      "x": -37,
      "y": 15,
      "z": -20,
      "name": "Plant_Coral_Block_Blue"
    },
    {
      "x": -37,
      "y": 16,
      "z": -20,
      "name": "Plant_Coral_Block_Blue"
    },
    {
      "x": -37,
      "y": 17,
      "z": -20,
      "name": "Plant_Coral_Block_Blue"
    },
    {
      "x": -37,
      "y": 18,
      "z": -20,
      "name": "Plant_Coral_Bush_Blue"
    },
    {
      "x": -37,
      "y": 5,
      "z": -19,
      "name": "Rock_Lime_Cobble"
    },
    {
      "x": -37,
      "y": 6,
      "z": -19,
      "name": "Rock_Lime"
    },
    {
      "x": -37,
      "y": 7,
      "z": -19,
      "name": "Rock_Lime"
    },
    {
      "x": -37,
      "y": 8,
      "z": -19,
      "name": "Rock_Lime_Cobble"
    },
    {
      "x": -37,
      "y": 9,
      "z": -19,
      "name": "Rock_Lime_Cobble"
    },
    {
      "x": -37,
      "y": 10,
      "z": -19,
      "name": "Plant_Coral_Block_Blue"
    },
    {
      "x": -37,
      "y": 11,
      "z": -19,
      "name": "Plant_Coral_Block_Blue"
    },
    {
      "x": -37,
      "y": 12,
      "z": -19,
      "name": "Plant_Coral_Block_Blue"
    },
    {
      "x": -37,
      "y": 13,
      "z": -19,
      "name": "Plant_Coral_Block_Blue"
    },
    {
      "x": -37,
      "y": 14,
      "z": -19,
      "name": "Plant_Coral_Block_Blue"
    },
    {
      "x": -37,
      "y": 15,
      "z": -19,
      "name": "Plant_Coral_Block_Blue"
    },
    {
      "x": -37,
      "y": 16,
      "z": -19,
      "name": "Plant_Coral_Block_Cyan"
    },
    {
      "x": -37,
      "y": 5,
      "z": -18,
      "name": "Soil_Gravel_Lime"
    },
    {
      "x": -37,
      "y": 6,
      "z": -18,
      "name": "Soil_Gravel_Lime"
    },
    {
      "x": -37,
      "y": 7,
      "z": -18,
      "name": "Soil_Gravel_Lime"
    },
    {
      "x": -37,
      "y": 8,
      "z": -18,
      "name": "Soil_Gravel_Lime"
    },
    {
      "x": -37,
      "y": 9,
      "z": -18,
      "name": "Rock_Lime"
    },
    {
      "x": -37,
      "y": 10,
      "z": -18,
      "name": "Plant_Coral_Block_Blue"
    },
    {
      "x": -37,
      "y": 11,
      "z": -18,
      "name": "Plant_Coral_Block_Blue"
    },
    {
      "x": -37,
      "y": 12,
      "z": -18,
      "name": "Plant_Coral_Block_Blue"
    },
    {
      "x": -37,
      "y": 13,
      "z": -18,
      "name": "Plant_Coral_Block_Blue"
    },
    {
      "x": -37,
      "y": 14,
      "z": -18,
      "name": "Plant_Coral_Block_Blue"
    },
    {
      "x": -37,
      "y": 15,
      "z": -18,
      "name": "Plant_Coral_Block_Blue"
    },
    {
      "x": -37,
      "y": 16,
      "z": -18,
      "name": "Plant_Coral_Block_Cyan"
    },
    {
      "x": -37,
      "y": 5,
      "z": -17,
      "name": "Soil_Gravel_Lime"
    },
    {
      "x": -37,
      "y": 6,
      "z": -17,
      "name": "Rock_Lime"
    },
    {
      "x": -37,
      "y": 7,
      "z": -17,
      "name": "Soil_Gravel_Lime"
    },
    {
      "x": -37,
      "y": 8,
      "z": -17,
      "name": "Rock_Lime_Cobble"
    },
    {
      "x": -37,
      "y": 9,
      "z": -17,
      "name": "Rock_Lime"
    },
    {
      "x": -37,
      "y": 10,
      "z": -17,
      "name": "Plant_Coral_Block_Blue"
    },
    {
      "x": -37,
      "y": 11,
      "z": -17,
      "name": "Plant_Coral_Block_Blue"
    },
    {
      "x": -37,
      "y": 12,
      "z": -17,
      "name": "Plant_Coral_Block_Blue"
    },
    {
      "x": -37,
      "y": 13,
      "z": -17,
      "name": "Plant_Coral_Block_Blue"
    },
    {
      "x": -37,
      "y": 14,
      "z": -17,
      "name": "Plant_Coral_Block_Blue"
    },
    {
      "x": -37,
      "y": 15,
      "z": -17,
      "name": "Plant_Coral_Block_Blue"
    },
    {
      "x": -37,
      "y": 16,
      "z": -17,
      "name": "Plant_Coral_Block_Cyan"
    },
    {
      "x": -37,
      "y": 5,
      "z": -16,
      "name": "Rock_Lime"
    },
    {
      "x": -37,
      "y": 6,
      "z": -16,
      "name": "Rock_Lime_Cobble"
    },
    {
      "x": -37,
      "y": 7,
      "z": -16,
      "name": "Rock_Lime_Cobble"
    },
    {
      "x": -37,
      "y": 8,
      "z": -16,
      "name": "Rock_Lime"
    },
    {
      "x": -37,
      "y": 9,
      "z": -16,
      "name": "Rock_Lime_Cobble"
    },
    {
      "x": -37,
      "y": 13,
      "z": -16,
      "name": "Plant_Coral_Block_Blue"
    },
    {
      "x": -37,
      "y": 14,
      "z": -16,
      "name": "Plant_Coral_Block_Blue"
    },
    {
      "x": -37,
      "y": 15,
      "z": -16,
      "name": "Plant_Coral_Block_Blue"
    },
    {
      "x": -37,
      "y": 16,
      "z": -16,
      "name": "Plant_Coral_Block_Blue"
    },
    {
      "x": -37,
      "y": 17,
      "z": -16,
      "name": "Plant_Coral_Block_Blue"
    },
    {
      "x": -37,
      "y": 5,
      "z": -15,
      "name": "Rock_Lime"
    },
    {
      "x": -37,
      "y": 6,
      "z": -15,
      "name": "Rock_Lime"
    },
    {
      "x": -37,
      "y": 7,
      "z": -15,
      "name": "Rock_Lime_Cobble"
    },
    {
      "x": -37,
      "y": 8,
      "z": -15,
      "name": "Soil_Gravel_Lime"
    },
    {
      "x": -37,
      "y": 9,
      "z": -15,
      "name": "Rock_Lime_Cobble"
    },
    {
      "x": -37,
      "y": 10,
      "z": -15,
      "name": "Plant_Coral_Bush_Blue"
    },
    {
      "x": -37,
      "y": 5,
      "z": -14,
      "name": "Rock_Lime"
    },
    {
      "x": -37,
      "y": 6,
      "z": -14,
      "name": "Rock_Lime"
    },
    {
      "x": -37,
      "y": 7,
      "z": -14,
      "name": "Soil_Gravel_Lime"
    },
    {
      "x": -37,
      "y": 8,
      "z": -14,
      "name": "Rock_Lime_Cobble"
    },
    {
      "x": -37,
      "y": 9,
      "z": -14,
      "name": "Rock_Lime"
    },
    {
      "x": -37,
      "y": 6,
      "z": -13,
      "name": "Rock_Lime"
    },
    {
      "x": -37,
      "y": 7,
      "z": -13,
      "name": "Soil_Gravel_Lime"
    },
    {
      "x": -37,
      "y": 8,
      "z": -13,
      "name": "Rock_Lime_Cobble"
    },
    {
      "x": -37,
      "y": 7,
      "z": -12,
      "name": "Rock_Lime"
    },
    {
      "x": -36,
      "y": 6,
      "z": -30,
      "name": "Rock_Lime_Cobble"
    },
    {
      "x": -36,
      "y": 7,
      "z": -30,
      "name": "Rock_Lime_Cobble"
    },
    {
      "x": -36,
      "y": 8,
      "z": -30,
      "name": "Rock_Lime"
    },
    {
      "x": -36,
      "y": 5,
      "z": -29,
      "name": "Rock_Lime"
    },
    {
      "x": -36,
      "y": 6,
      "z": -29,
      "name": "Rock_Lime"
    },
    {
      "x": -36,
      "y": 7,
      "z": -29,
      "name": "Soil_Gravel_Lime"
    },
    {
      "x": -36,
      "y": 8,
      "z": -29,
      "name": "Soil_Gravel_Lime"
    },
    {
      "x": -36,
      "y": 9,
      "z": -29,
      "name": "Rock_Lime_Cobble"
    },
    {
      "x": -36,
      "y": 5,
      "z": -28,
      "name": "Soil_Gravel_Lime"
    },
    {
      "x": -36,
      "y": 6,
      "z": -28,
      "name": "Rock_Lime_Cobble"
    },
    {
      "x": -36,
      "y": 7,
      "z": -28,
      "name": "Soil_Gravel_Lime"
    },
    {
      "x": -36,
      "y": 8,
      "z": -28,
      "name": "Soil_Gravel_Lime"
    },
    {
      "x": -36,
      "y": 9,
      "z": -28,
      "name": "Rock_Lime_Cobble"
    },
    {
      "x": -36,
      "y": 5,
      "z": -27,
      "name": "Rock_Lime_Cobble"
    },
    {
      "x": -36,
      "y": 6,
      "z": -27,
      "name": "Rock_Lime_Cobble"
    },
    {
      "x": -36,
      "y": 7,
      "z": -27,
      "name": "Soil_Gravel_Lime"
    },
    {
      "x": -36,
      "y": 8,
      "z": -27,
      "name": "Rock_Lime_Cobble"
    },
    {
      "x": -36,
      "y": 9,
      "z": -27,
      "name": "Rock_Lime_Cobble"
    },
    {
      "x": -36,
      "y": 10,
      "z": -27,
      "name": "Plant_Coral_Block_Blue"
    },
    {
      "x": -36,
      "y": 11,
      "z": -27,
      "name": "Plant_Coral_Block_Blue"
    },
    {
      "x": -36,
      "y": 12,
      "z": -27,
      "name": "Plant_Coral_Block_Blue"
    },
    {
      "x": -36,
      "y": 13,
      "z": -27,
      "name": "Plant_Coral_Block_Blue"
    },
    {
      "x": -36,
      "y": 14,
      "z": -27,
      "name": "Plant_Coral_Block_Blue"
    },
    {
      "x": -36,
      "y": 15,
      "z": -27,
      "name": "Plant_Coral_Block_Blue"
    },
    {
      "x": -36,
      "y": 5,
      "z": -26,
      "name": "Rock_Lime_Cobble"
    },
    {
      "x": -36,
      "y": 6,
      "z": -26,
      "name": "Rock_Lime"
    },
    {
      "x": -36,
      "y": 7,
      "z": -26,
      "name": "Soil_Gravel_Lime"
    },
    {
      "x": -36,
      "y": 8,
      "z": -26,
      "name": "Rock_Lime_Cobble"
    },
    {
      "x": -36,
      "y": 9,
      "z": -26,
      "name": "Soil_Gravel_Lime"
    },
    {
      "x": -36,
      "y": 10,
      "z": -26,
      "name": "Plant_Coral_Block_Blue"
    },
    {
      "x": -36,
      "y": 11,
      "z": -26,
      "name": "Plant_Coral_Block_Blue"
    },
    {
      "x": -36,
      "y": 12,
      "z": -26,
      "name": "Plant_Coral_Block_Blue"
    },
    {
      "x": -36,
      "y": 13,
      "z": -26,
      "name": "Plant_Coral_Block_Blue"
    },
    {
      "x": -36,
      "y": 14,
      "z": -26,
      "name": "Plant_Coral_Block_Blue"
    },
    {
      "x": -36,
      "y": 15,
      "z": -26,
      "name": "Plant_Coral_Block_Blue"
    },
    {
      "x": -36,
      "y": 16,
      "z": -26,
      "name": "Plant_Coral_Block_Blue"
    },
    {
      "x": -36,
      "y": 17,
      "z": -26,
      "name": "Plant_Coral_Block_Blue"
    },
    {
      "x": -36,
      "y": 18,
      "z": -26,
      "name": "Plant_Coral_Bush_Blue"
    },
    {
      "x": -36,
      "y": 5,
      "z": -25,
      "name": "Rock_Lime_Cobble"
    },
    {
      "x": -36,
      "y": 6,
      "z": -25,
      "name": "Rock_Lime_Cobble"
    },
    {
      "x": -36,
      "y": 7,
      "z": -25,
      "name": "Rock_Lime"
    },
    {
      "x": -36,
      "y": 8,
      "z": -25,
      "name": "Soil_Gravel_Lime"
    },
    {
      "x": -36,
      "y": 9,
      "z": -25,
      "name": "Rock_Lime_Cobble"
    },
    {
      "x": -36,
      "y": 10,
      "z": -25,
      "name": "Plant_Coral_Block_Blue"
    },
    {
      "x": -36,
      "y": 11,
      "z": -25,
      "name": "Plant_Coral_Block_Blue"
    },
    {
      "x": -36,
      "y": 12,
      "z": -25,
      "name": "Plant_Coral_Block_Blue"
    },
    {
      "x": -36,
      "y": 13,
      "z": -25,
      "name": "Plant_Coral_Block_Blue"
    },
    {
      "x": -36,
      "y": 14,
      "z": -25,
      "name": "Plant_Coral_Block_Blue"
    },
    {
      "x": -36,
      "y": 15,
      "z": -25,
      "name": "Plant_Coral_Block_Blue"
    },
    {
      "x": -36,
      "y": 16,
      "z": -25,
      "name": "Plant_Coral_Block_Cyan"
    },
    {
      "x": -36,
      "y": 5,
      "z": -24,
      "name": "Soil_Gravel_Lime"
    },
    {
      "x": -36,
      "y": 6,
      "z": -24,
      "name": "Soil_Gravel_Lime"
    },
    {
      "x": -36,
      "y": 7,
      "z": -24,
      "name": "Rock_Lime"
    },
    {
      "x": -36,
      "y": 8,
      "z": -24,
      "name": "Rock_Lime"
    },
    {
      "x": -36,
      "y": 9,
      "z": -24,
      "name": "Rock_Lime_Cobble"
    },
    {
      "x": -36,
      "y": 10,
      "z": -24,
      "name": "Plant_Coral_Block_Blue"
    },
    {
      "x": -36,
      "y": 11,
      "z": -24,
      "name": "Plant_Coral_Block_Blue"
    },
    {
      "x": -36,
      "y": 12,
      "z": -24,
      "name": "Plant_Coral_Block_Blue"
    },
    {
      "x": -36,
      "y": 13,
      "z": -24,
      "name": "Plant_Coral_Block_Blue"
    },
    {
      "x": -36,
      "y": 14,
      "z": -24,
      "name": "Plant_Coral_Block_Blue"
    },
    {
      "x": -36,
      "y": 15,
      "z": -24,
      "name": "Plant_Coral_Block_Blue"
    },
    {
      "x": -36,
      "y": 16,
      "z": -24,
      "name": "Plant_Coral_Block_Cyan"
    },
    {
      "x": -36,
      "y": 5,
      "z": -23,
      "name": "Soil_Gravel_Lime"
    },
    {
      "x": -36,
      "y": 6,
      "z": -23,
      "name": "Rock_Lime"
    },
    {
      "x": -36,
      "y": 7,
      "z": -23,
      "name": "Soil_Gravel_Lime"
    },
    {
      "x": -36,
      "y": 8,
      "z": -23,
      "name": "Soil_Gravel_Lime"
    },
    {
      "x": -36,
      "y": 9,
      "z": -23,
      "name": "Rock_Lime_Cobble"
    },
    {
      "x": -36,
      "y": 10,
      "z": -23,
      "name": "Plant_Coral_Block_Blue"
    },
    {
      "x": -36,
      "y": 11,
      "z": -23,
      "name": "Plant_Coral_Block_Blue"
    },
    {
      "x": -36,
      "y": 12,
      "z": -23,
      "name": "Plant_Coral_Block_Blue"
    },
    {
      "x": -36,
      "y": 13,
      "z": -23,
      "name": "Plant_Coral_Block_Blue"
    },
    {
      "x": -36,
      "y": 14,
      "z": -23,
      "name": "Plant_Coral_Block_Blue"
    },
    {
      "x": -36,
      "y": 15,
      "z": -23,
      "name": "Plant_Coral_Block_Blue"
    },
    {
      "x": -36,
      "y": 16,
      "z": -23,
      "name": "Plant_Coral_Block_Cyan"
    },
    {
      "x": -36,
      "y": 5,
      "z": -22,
      "name": "Rock_Lime"
    },
    {
      "x": -36,
      "y": 6,
      "z": -22,
      "name": "Soil_Gravel_Lime"
    },
    {
      "x": -36,
      "y": 7,
      "z": -22,
      "name": "Rock_Lime_Cobble"
    },
    {
      "x": -36,
      "y": 8,
      "z": -22,
      "name": "Rock_Lime"
    },
    {
      "x": -36,
      "y": 9,
      "z": -22,
      "name": "Rock_Lime_Cobble"
    },
    {
      "x": -36,
      "y": 10,
      "z": -22,
      "name": "Plant_Coral_Block_Blue"
    },
    {
      "x": -36,
      "y": 11,
      "z": -22,
      "name": "Plant_Coral_Block_Blue"
    },
    {
      "x": -36,
      "y": 13,
      "z": -22,
      "name": "Plant_Coral_Block_Blue"
    },
    {
      "x": -36,
      "y": 14,
      "z": -22,
      "name": "Plant_Coral_Block_Blue"
    },
    {
      "x": -36,
      "y": 15,
      "z": -22,
      "name": "Plant_Coral_Block_Blue"
    },
    {
      "x": -36,
      "y": 16,
      "z": -22,
      "name": "Plant_Coral_Block_Blue"
    },
    {
      "x": -36,
      "y": 17,
      "z": -22,
      "name": "Plant_Coral_Block_Blue"
    },
    {
      "x": -36,
      "y": 5,
      "z": -21,
      "name": "Soil_Gravel_Lime"
    },
    {
      "x": -36,
      "y": 6,
      "z": -21,
      "name": "Soil_Gravel_Lime"
    },
    {
      "x": -36,
      "y": 7,
      "z": -21,
      "name": "Soil_Gravel_Lime"
    },
    {
      "x": -36,
      "y": 8,
      "z": -21,
      "name": "Soil_Gravel_Lime"
    },
    {
      "x": -36,
      "y": 9,
      "z": -21,
      "name": "Rock_Lime"
    },
    {
      "x": -36,
      "y": 10,
      "z": -21,
      "name": "Plant_Coral_Block_Blue"
    },
    {
      "x": -36,
      "y": 11,
      "z": -21,
      "name": "Plant_Coral_Block_Blue"
    },
    {
      "x": -36,
      "y": 12,
      "z": -21,
      "name": "Plant_Coral_Block_Blue"
    },
    {
      "x": -36,
      "y": 13,
      "z": -21,
      "name": "Plant_Coral_Block_Blue"
    },
    {
      "x": -36,
      "y": 14,
      "z": -21,
      "name": "Plant_Coral_Block_Blue"
    },
    {
      "x": -36,
      "y": 15,
      "z": -21,
      "name": "Plant_Coral_Block_Blue"
    },
    {
      "x": -36,
      "y": 5,
      "z": -20,
      "name": "Rock_Lime"
    },
    {
      "x": -36,
      "y": 6,
      "z": -20,
      "name": "Soil_Gravel_Lime"
    },
    {
      "x": -36,
      "y": 7,
      "z": -20,
      "name": "Rock_Lime"
    },
    {
      "x": -36,
      "y": 8,
      "z": -20,
      "name": "Rock_Lime_Cobble"
    },
    {
      "x": -36,
      "y": 9,
      "z": -20,
      "name": "Rock_Lime"
    },
    {
      "x": -36,
      "y": 10,
      "z": -20,
      "name": "Plant_Coral_Block_Blue"
    },
    {
      "x": -36,
      "y": 11,
      "z": -20,
      "name": "Plant_Coral_Block_Blue"
    },
    {
      "x": -36,
      "y": 12,
      "z": -20,
      "name": "Plant_Coral_Block_Blue"
    },
    {
      "x": -36,
      "y": 13,
      "z": -20,
      "name": "Plant_Coral_Block_Blue"
    },
    {
      "x": -36,
      "y": 14,
      "z": -20,
      "name": "Plant_Coral_Block_Blue"
    },
    {
      "x": -36,
      "y": 15,
      "z": -20,
      "name": "Plant_Coral_Block_Blue"
    },
    {
      "x": -36,
      "y": 16,
      "z": -20,
      "name": "Plant_Coral_Block_Blue"
    },
    {
      "x": -36,
      "y": 17,
      "z": -20,
      "name": "Plant_Coral_Block_Blue"
    },
    {
      "x": -36,
      "y": 5,
      "z": -19,
      "name": "Rock_Lime_Cobble"
    },
    {
      "x": -36,
      "y": 6,
      "z": -19,
      "name": "Soil_Gravel_Lime"
    },
    {
      "x": -36,
      "y": 7,
      "z": -19,
      "name": "Rock_Lime"
    },
    {
      "x": -36,
      "y": 8,
      "z": -19,
      "name": "Rock_Lime"
    },
    {
      "x": -36,
      "y": 9,
      "z": -19,
      "name": "Soil_Gravel_Lime"
    },
    {
      "x": -36,
      "y": 10,
      "z": -19,
      "name": "Plant_Coral_Block_Blue"
    },
    {
      "x": -36,
      "y": 11,
      "z": -19,
      "name": "Plant_Coral_Block_Blue"
    },
    {
      "x": -36,
      "y": 12,
      "z": -19,
      "name": "Plant_Coral_Block_Blue"
    },
    {
      "x": -36,
      "y": 13,
      "z": -19,
      "name": "Plant_Coral_Block_Blue"
    },
    {
      "x": -36,
      "y": 14,
      "z": -19,
      "name": "Plant_Coral_Block_Blue"
    },
    {
      "x": -36,
      "y": 15,
      "z": -19,
      "name": "Plant_Coral_Block_Blue"
    },
    {
      "x": -36,
      "y": 16,
      "z": -19,
      "name": "Plant_Coral_Block_Cyan"
    },
    {
      "x": -36,
      "y": 5,
      "z": -18,
      "name": "Rock_Lime_Cobble"
    },
    {
      "x": -36,
      "y": 6,
      "z": -18,
      "name": "Rock_Lime_Cobble"
    },
    {
      "x": -36,
      "y": 7,
      "z": -18,
      "name": "Rock_Lime_Cobble"
    },
    {
      "x": -36,
      "y": 8,
      "z": -18,
      "name": "Soil_Gravel_Lime"
    },
    {
      "x": -36,
      "y": 9,
      "z": -18,
      "name": "Rock_Lime_Cobble"
    },
    {
      "x": -36,
      "y": 10,
      "z": -18,
      "name": "Plant_Coral_Block_Blue"
    },
    {
      "x": -36,
      "y": 11,
      "z": -18,
      "name": "Plant_Coral_Block_Blue"
    },
    {
      "x": -36,
      "y": 12,
      "z": -18,
      "name": "Plant_Coral_Block_Blue"
    },
    {
      "x": -36,
      "y": 13,
      "z": -18,
      "name": "Plant_Coral_Block_Blue"
    },
    {
      "x": -36,
      "y": 14,
      "z": -18,
      "name": "Plant_Coral_Block_Blue"
    },
    {
      "x": -36,
      "y": 15,
      "z": -18,
      "name": "Plant_Coral_Block_Blue"
    },
    {
      "x": -36,
      "y": 16,
      "z": -18,
      "name": "Plant_Coral_Block_Cyan"
    },
    {
      "x": -36,
      "y": 5,
      "z": -17,
      "name": "Rock_Lime"
    },
    {
      "x": -36,
      "y": 6,
      "z": -17,
      "name": "Rock_Lime_Cobble"
    },
    {
      "x": -36,
      "y": 7,
      "z": -17,
      "name": "Soil_Gravel_Lime"
    },
    {
      "x": -36,
      "y": 8,
      "z": -17,
      "name": "Rock_Lime"
    },
    {
      "x": -36,
      "y": 9,
      "z": -17,
      "name": "Rock_Lime"
    },
    {
      "x": -36,
      "y": 10,
      "z": -17,
      "name": "Plant_Coral_Block_Blue"
    },
    {
      "x": -36,
      "y": 11,
      "z": -17,
      "name": "Plant_Coral_Block_Blue"
    },
    {
      "x": -36,
      "y": 12,
      "z": -17,
      "name": "Plant_Coral_Block_Blue"
    },
    {
      "x": -36,
      "y": 13,
      "z": -17,
      "name": "Plant_Coral_Block_Blue"
    },
    {
      "x": -36,
      "y": 14,
      "z": -17,
      "name": "Plant_Coral_Block_Blue"
    },
    {
      "x": -36,
      "y": 15,
      "z": -17,
      "name": "Plant_Coral_Block_Blue"
    },
    {
      "x": -36,
      "y": 16,
      "z": -17,
      "name": "Plant_Coral_Block_Cyan"
    },
    {
      "x": -36,
      "y": 5,
      "z": -16,
      "name": "Soil_Gravel_Lime"
    },
    {
      "x": -36,
      "y": 6,
      "z": -16,
      "name": "Soil_Gravel_Lime"
    },
    {
      "x": -36,
      "y": 7,
      "z": -16,
      "name": "Soil_Gravel_Lime"
    },
    {
      "x": -36,
      "y": 8,
      "z": -16,
      "name": "Soil_Gravel_Lime"
    },
    {
      "x": -36,
      "y": 9,
      "z": -16,
      "name": "Rock_Lime_Cobble"
    },
    {
      "x": -36,
      "y": 10,
      "z": -16,
      "name": "Plant_Coral_Model_Cyan"
    },
    {
      "x": -36,
      "y": 13,
      "z": -16,
      "name": "Plant_Coral_Block_Blue"
    },
    {
      "x": -36,
      "y": 14,
      "z": -16,
      "name": "Plant_Coral_Block_Blue"
    },
    {
      "x": -36,
      "y": 15,
      "z": -16,
      "name": "Plant_Coral_Block_Blue"
    },
    {
      "x": -36,
      "y": 16,
      "z": -16,
      "name": "Plant_Coral_Block_Blue"
    },
    {
      "x": -36,
      "y": 17,
      "z": -16,
      "name": "Plant_Coral_Block_Blue"
    },
    {
      "x": -36,
      "y": 18,
      "z": -16,
      "name": "Plant_Coral_Bush_Blue"
    },
    {
      "x": -36,
      "y": 5,
      "z": -15,
      "name": "Soil_Gravel_Lime"
    },
    {
      "x": -36,
      "y": 6,
      "z": -15,
      "name": "Rock_Lime_Cobble"
    },
    {
      "x": -36,
      "y": 7,
      "z": -15,
      "name": "Rock_Lime_Cobble"
    },
    {
      "x": -36,
      "y": 8,
      "z": -15,
      "name": "Soil_Gravel_Lime"
    },
    {
      "x": -36,
      "y": 9,
      "z": -15,
      "name": "Soil_Gravel_Lime"
    },
    {
      "x": -36,
      "y": 5,
      "z": -14,
      "name": "Rock_Lime_Cobble"
    },
    {
      "x": -36,
      "y": 6,
      "z": -14,
      "name": "Rock_Lime_Cobble"
    },
    {
      "x": -36,
      "y": 7,
      "z": -14,
      "name": "Soil_Gravel_Lime"
    },
    {
      "x": -36,
      "y": 8,
      "z": -14,
      "name": "Soil_Gravel_Lime"
    },
    {
      "x": -36,
      "y": 9,
      "z": -14,
      "name": "Rock_Lime_Cobble"
    },
    {
      "x": -36,
      "y": 5,
      "z": -13,
      "name": "Rock_Lime_Cobble"
    },
    {
      "x": -36,
      "y": 6,
      "z": -13,
      "name": "Rock_Lime_Cobble"
    },
    {
      "x": -36,
      "y": 7,
      "z": -13,
      "name": "Soil_Gravel_Lime"
    },
    {
      "x": -36,
      "y": 8,
      "z": -13,
      "name": "Rock_Lime"
    },
    {
      "x": -36,
      "y": 9,
      "z": -13,
      "name": "Rock_Lime_Cobble"
    },
    {
      "x": -36,
      "y": 6,
      "z": -12,
      "name": "Soil_Gravel_Lime"
    },
    {
      "x": -36,
      "y": 7,
      "z": -12,
      "name": "Rock_Lime_Cobble"
    },
    {
      "x": -36,
      "y": 8,
      "z": -12,
      "name": "Rock_Lime_Cobble"
    },
    {
      "x": -35,
      "y": 7,
      "z": -30,
      "name": "Rock_Lime_Cobble"
    },
    {
      "x": -35,
      "y": 8,
      "z": -30,
      "name": "Rock_Lime_Cobble"
    },
    {
      "x": -35,
      "y": 9,
      "z": -30,
      "name": "Rock_Lime_Cobble"
    },
    {
      "x": -35,
      "y": 6,
      "z": -29,
      "name": "Rock_Lime_Cobble"
    },
    {
      "x": -35,
      "y": 7,
      "z": -29,
      "name": "Rock_Lime"
    },
    {
      "x": -35,
      "y": 8,
      "z": -29,
      "name": "Rock_Lime_Cobble"
    },
    {
      "x": -35,
      "y": 9,
      "z": -29,
      "name": "Rock_Lime_Cobble"
    },
    {
      "x": -35,
      "y": 5,
      "z": -28,
      "name": "Soil_Gravel_Lime"
    },
    {
      "x": -35,
      "y": 6,
      "z": -28,
      "name": "Soil_Gravel_Lime"
    },
    {
      "x": -35,
      "y": 7,
      "z": -28,
      "name": "Rock_Lime_Cobble"
    },
    {
      "x": -35,
      "y": 8,
      "z": -28,
      "name": "Rock_Lime"
    },
    {
      "x": -35,
      "y": 9,
      "z": -28,
      "name": "Rock_Lime_Cobble"
    },
    {
      "x": -35,
      "y": 5,
      "z": -27,
      "name": "Rock_Lime_Cobble"
    },
    {
      "x": -35,
      "y": 6,
      "z": -27,
      "name": "Rock_Lime"
    },
    {
      "x": -35,
      "y": 7,
      "z": -27,
      "name": "Soil_Gravel_Lime"
    },
    {
      "x": -35,
      "y": 8,
      "z": -27,
      "name": "Rock_Lime"
    },
    {
      "x": -35,
      "y": 9,
      "z": -27,
      "name": "Rock_Lime"
    },
    {
      "x": -35,
      "y": 10,
      "z": -27,
      "name": "Plant_Coral_Model_Cyan"
    },
    {
      "x": -35,
      "y": 5,
      "z": -26,
      "name": "Rock_Lime_Cobble"
    },
    {
      "x": -35,
      "y": 6,
      "z": -26,
      "name": "Rock_Lime_Cobble"
    },
    {
      "x": -35,
      "y": 7,
      "z": -26,
      "name": "Soil_Gravel_Lime"
    },
    {
      "x": -35,
      "y": 8,
      "z": -26,
      "name": "Soil_Gravel_Lime"
    },
    {
      "x": -35,
      "y": 9,
      "z": -26,
      "name": "Rock_Lime"
    },
    {
      "x": -35,
      "y": 10,
      "z": -26,
      "name": "Plant_Coral_Block_Blue"
    },
    {
      "x": -35,
      "y": 11,
      "z": -26,
      "name": "Plant_Coral_Block_Blue"
    },
    {
      "x": -35,
      "y": 12,
      "z": -26,
      "name": "Plant_Coral_Block_Blue"
    },
    {
      "x": -35,
      "y": 13,
      "z": -26,
      "name": "Plant_Coral_Block_Blue"
    },
    {
      "x": -35,
      "y": 14,
      "z": -26,
      "name": "Plant_Coral_Block_Blue"
    },
    {
      "x": -35,
      "y": 15,
      "z": -26,
      "name": "Plant_Coral_Block_Blue"
    },
    {
      "x": -35,
      "y": 16,
      "z": -26,
      "name": "Plant_Coral_Block_Blue"
    },
    {
      "x": -35,
      "y": 17,
      "z": -26,
      "name": "Plant_Coral_Block_Blue"
    },
    {
      "x": -35,
      "y": 5,
      "z": -25,
      "name": "Soil_Gravel_Lime"
    },
    {
      "x": -35,
      "y": 6,
      "z": -25,
      "name": "Soil_Gravel_Lime"
    },
    {
      "x": -35,
      "y": 7,
      "z": -25,
      "name": "Soil_Gravel_Lime"
    },
    {
      "x": -35,
      "y": 8,
      "z": -25,
      "name": "Rock_Lime_Cobble"
    },
    {
      "x": -35,
      "y": 9,
      "z": -25,
      "name": "Rock_Lime_Cobble"
    },
    {
      "x": -35,
      "y": 10,
      "z": -25,
      "name": "Plant_Coral_Block_Blue"
    },
    {
      "x": -35,
      "y": 11,
      "z": -25,
      "name": "Plant_Coral_Block_Blue"
    },
    {
      "x": -35,
      "y": 12,
      "z": -25,
      "name": "Plant_Coral_Block_Blue"
    },
    {
      "x": -35,
      "y": 13,
      "z": -25,
      "name": "Plant_Coral_Block_Blue"
    },
    {
      "x": -35,
      "y": 14,
      "z": -25,
      "name": "Plant_Coral_Block_Blue"
    },
    {
      "x": -35,
      "y": 15,
      "z": -25,
      "name": "Plant_Coral_Block_Blue"
    },
    {
      "x": -35,
      "y": 16,
      "z": -25,
      "name": "Plant_Coral_Block_Cyan"
    },
    {
      "x": -35,
      "y": 5,
      "z": -24,
      "name": "Rock_Lime"
    },
    {
      "x": -35,
      "y": 6,
      "z": -24,
      "name": "Rock_Lime"
    },
    {
      "x": -35,
      "y": 7,
      "z": -24,
      "name": "Rock_Lime"
    },
    {
      "x": -35,
      "y": 8,
      "z": -24,
      "name": "Rock_Lime"
    },
    {
      "x": -35,
      "y": 9,
      "z": -24,
      "name": "Rock_Lime"
    },
    {
      "x": -35,
      "y": 10,
      "z": -24,
      "name": "Plant_Coral_Block_Blue"
    },
    {
      "x": -35,
      "y": 11,
      "z": -24,
      "name": "Plant_Coral_Block_Blue"
    },
    {
      "x": -35,
      "y": 12,
      "z": -24,
      "name": "Plant_Coral_Block_Blue"
    },
    {
      "x": -35,
      "y": 13,
      "z": -24,
      "name": "Plant_Coral_Block_Blue"
    },
    {
      "x": -35,
      "y": 14,
      "z": -24,
      "name": "Plant_Coral_Block_Blue"
    },
    {
      "x": -35,
      "y": 15,
      "z": -24,
      "name": "Plant_Coral_Block_Blue"
    },
    {
      "x": -35,
      "y": 16,
      "z": -24,
      "name": "Plant_Coral_Block_Cyan"
    },
    {
      "x": -35,
      "y": 5,
      "z": -23,
      "name": "Rock_Lime"
    },
    {
      "x": -35,
      "y": 6,
      "z": -23,
      "name": "Rock_Lime_Cobble"
    },
    {
      "x": -35,
      "y": 7,
      "z": -23,
      "name": "Soil_Gravel_Lime"
    },
    {
      "x": -35,
      "y": 8,
      "z": -23,
      "name": "Rock_Lime_Cobble"
    },
    {
      "x": -35,
      "y": 9,
      "z": -23,
      "name": "Soil_Gravel_Lime"
    },
    {
      "x": -35,
      "y": 13,
      "z": -23,
      "name": "Plant_Coral_Block_Blue"
    },
    {
      "x": -35,
      "y": 14,
      "z": -23,
      "name": "Plant_Coral_Block_Blue"
    },
    {
      "x": -35,
      "y": 15,
      "z": -23,
      "name": "Plant_Coral_Block_Blue"
    },
    {
      "x": -35,
      "y": 16,
      "z": -23,
      "name": "Plant_Coral_Block_Cyan"
    },
    {
      "x": -35,
      "y": 5,
      "z": -22,
      "name": "Rock_Lime"
    },
    {
      "x": -35,
      "y": 6,
      "z": -22,
      "name": "Soil_Gravel_Lime"
    },
    {
      "x": -35,
      "y": 7,
      "z": -22,
      "name": "Rock_Lime_Cobble"
    },
    {
      "x": -35,
      "y": 8,
      "z": -22,
      "name": "Rock_Lime"
    },
    {
      "x": -35,
      "y": 9,
      "z": -22,
      "name": "Rock_Lime"
    },
    {
      "x": -35,
      "y": 10,
      "z": -22,
      "name": "Plant_Coral_Block_Blue"
    },
    {
      "x": -35,
      "y": 11,
      "z": -22,
      "name": "Plant_Coral_Block_Blue"
    },
    {
      "x": -35,
      "y": 13,
      "z": -22,
      "name": "Plant_Coral_Block_Blue"
    },
    {
      "x": -35,
      "y": 14,
      "z": -22,
      "name": "Plant_Coral_Block_Blue"
    },
    {
      "x": -35,
      "y": 15,
      "z": -22,
      "name": "Plant_Coral_Block_Blue"
    },
    {
      "x": -35,
      "y": 16,
      "z": -22,
      "name": "Plant_Coral_Block_Blue"
    },
    {
      "x": -35,
      "y": 17,
      "z": -22,
      "name": "Plant_Coral_Block_Blue"
    },
    {
      "x": -35,
      "y": 5,
      "z": -21,
      "name": "Rock_Lime"
    },
    {
      "x": -35,
      "y": 6,
      "z": -21,
      "name": "Rock_Lime"
    },
    {
      "x": -35,
      "y": 7,
      "z": -21,
      "name": "Soil_Gravel_Lime"
    },
    {
      "x": -35,
      "y": 8,
      "z": -21,
      "name": "Rock_Lime"
    },
    {
      "x": -35,
      "y": 9,
      "z": -21,
      "name": "Soil_Gravel_Lime"
    },
    {
      "x": -35,
      "y": 10,
      "z": -21,
      "name": "Plant_Coral_Block_Blue"
    },
    {
      "x": -35,
      "y": 11,
      "z": -21,
      "name": "Plant_Coral_Block_Blue"
    },
    {
      "x": -35,
      "y": 12,
      "z": -21,
      "name": "Plant_Coral_Block_Blue"
    },
    {
      "x": -35,
      "y": 13,
      "z": -21,
      "name": "Plant_Coral_Block_Blue"
    },
    {
      "x": -35,
      "y": 14,
      "z": -21,
      "name": "Plant_Coral_Block_Blue"
    },
    {
      "x": -35,
      "y": 15,
      "z": -21,
      "name": "Plant_Coral_Block_Blue"
    },
    {
      "x": -35,
      "y": 16,
      "z": -21,
      "name": "Plant_Coral_Model_Blue"
    },
    {
      "x": -35,
      "y": 5,
      "z": -20,
      "name": "Soil_Gravel_Lime"
    },
    {
      "x": -35,
      "y": 6,
      "z": -20,
      "name": "Rock_Lime"
    },
    {
      "x": -35,
      "y": 7,
      "z": -20,
      "name": "Rock_Lime_Cobble"
    },
    {
      "x": -35,
      "y": 8,
      "z": -20,
      "name": "Rock_Lime"
    },
    {
      "x": -35,
      "y": 9,
      "z": -20,
      "name": "Rock_Lime_Cobble"
    },
    {
      "x": -35,
      "y": 10,
      "z": -20,
      "name": "Plant_Coral_Block_Blue"
    },
    {
      "x": -35,
      "y": 11,
      "z": -20,
      "name": "Plant_Coral_Block_Blue"
    },
    {
      "x": -35,
      "y": 12,
      "z": -20,
      "name": "Plant_Coral_Block_Blue"
    },
    {
      "x": -35,
      "y": 13,
      "z": -20,
      "name": "Plant_Coral_Block_Blue"
    },
    {
      "x": -35,
      "y": 14,
      "z": -20,
      "name": "Plant_Coral_Block_Cyan"
    },
    {
      "x": -35,
      "y": 5,
      "z": -19,
      "name": "Soil_Gravel_Lime"
    },
    {
      "x": -35,
      "y": 6,
      "z": -19,
      "name": "Rock_Lime"
    },
    {
      "x": -35,
      "y": 7,
      "z": -19,
      "name": "Rock_Lime_Cobble"
    },
    {
      "x": -35,
      "y": 8,
      "z": -19,
      "name": "Rock_Lime_Cobble"
    },
    {
      "x": -35,
      "y": 9,
      "z": -19,
      "name": "Rock_Lime_Cobble"
    },
    {
      "x": -35,
      "y": 10,
      "z": -19,
      "name": "Plant_Coral_Block_Blue"
    },
    {
      "x": -35,
      "y": 11,
      "z": -19,
      "name": "Plant_Coral_Block_Blue"
    },
    {
      "x": -35,
      "y": 12,
      "z": -19,
      "name": "Plant_Coral_Block_Blue"
    },
    {
      "x": -35,
      "y": 13,
      "z": -19,
      "name": "Plant_Coral_Block_Blue"
    },
    {
      "x": -35,
      "y": 14,
      "z": -19,
      "name": "Plant_Coral_Block_Blue"
    },
    {
      "x": -35,
      "y": 15,
      "z": -19,
      "name": "Plant_Coral_Block_Blue"
    },
    {
      "x": -35,
      "y": 16,
      "z": -19,
      "name": "Plant_Coral_Block_Blue"
    },
    {
      "x": -35,
      "y": 17,
      "z": -19,
      "name": "Plant_Coral_Block_Blue"
    },
    {
      "x": -35,
      "y": 5,
      "z": -18,
      "name": "Rock_Lime"
    },
    {
      "x": -35,
      "y": 6,
      "z": -18,
      "name": "Rock_Lime_Cobble"
    },
    {
      "x": -35,
      "y": 7,
      "z": -18,
      "name": "Rock_Lime"
    },
    {
      "x": -35,
      "y": 8,
      "z": -18,
      "name": "Soil_Gravel_Lime"
    },
    {
      "x": -35,
      "y": 9,
      "z": -18,
      "name": "Rock_Lime"
    },
    {
      "x": -35,
      "y": 10,
      "z": -18,
      "name": "Plant_Coral_Block_Blue"
    },
    {
      "x": -35,
      "y": 11,
      "z": -18,
      "name": "Plant_Coral_Block_Blue"
    },
    {
      "x": -35,
      "y": 12,
      "z": -18,
      "name": "Plant_Coral_Block_Blue"
    },
    {
      "x": -35,
      "y": 13,
      "z": -18,
      "name": "Plant_Coral_Block_Blue"
    },
    {
      "x": -35,
      "y": 14,
      "z": -18,
      "name": "Plant_Coral_Block_Blue"
    },
    {
      "x": -35,
      "y": 15,
      "z": -18,
      "name": "Plant_Coral_Block_Blue"
    },
    {
      "x": -35,
      "y": 16,
      "z": -18,
      "name": "Plant_Coral_Block_Blue"
    },
    {
      "x": -35,
      "y": 17,
      "z": -18,
      "name": "Plant_Coral_Block_Blue"
    },
    {
      "x": -35,
      "y": 18,
      "z": -18,
      "name": "Plant_Coral_Model_Blue"
    },
    {
      "x": -35,
      "y": 5,
      "z": -17,
      "name": "Rock_Lime"
    },
    {
      "x": -35,
      "y": 6,
      "z": -17,
      "name": "Rock_Lime"
    },
    {
      "x": -35,
      "y": 7,
      "z": -17,
      "name": "Soil_Gravel_Lime"
    },
    {
      "x": -35,
      "y": 8,
      "z": -17,
      "name": "Rock_Lime_Cobble"
    },
    {
      "x": -35,
      "y": 9,
      "z": -17,
      "name": "Soil_Gravel_Lime"
    },
    {
      "x": -35,
      "y": 10,
      "z": -17,
      "name": "Plant_Coral_Block_Blue"
    },
    {
      "x": -35,
      "y": 11,
      "z": -17,
      "name": "Plant_Coral_Block_Blue"
    },
    {
      "x": -35,
      "y": 12,
      "z": -17,
      "name": "Plant_Coral_Block_Blue"
    },
    {
      "x": -35,
      "y": 13,
      "z": -17,
      "name": "Plant_Coral_Block_Blue"
    },
    {
      "x": -35,
      "y": 14,
      "z": -17,
      "name": "Plant_Coral_Block_Blue"
    },
    {
      "x": -35,
      "y": 15,
      "z": -17,
      "name": "Plant_Coral_Block_Blue"
    },
    {
      "x": -35,
      "y": 16,
      "z": -17,
      "name": "Plant_Coral_Block_Blue"
    },
    {
      "x": -35,
      "y": 17,
      "z": -17,
      "name": "Plant_Coral_Block_Blue"
    },
    {
      "x": -35,
      "y": 5,
      "z": -16,
      "name": "Soil_Gravel_Lime"
    },
    {
      "x": -35,
      "y": 6,
      "z": -16,
      "name": "Rock_Lime_Cobble"
    },
    {
      "x": -35,
      "y": 7,
      "z": -16,
      "name": "Rock_Lime_Cobble"
    },
    {
      "x": -35,
      "y": 8,
      "z": -16,
      "name": "Soil_Gravel_Lime"
    },
    {
      "x": -35,
      "y": 9,
      "z": -16,
      "name": "Rock_Lime_Cobble"
    },
    {
      "x": -35,
      "y": 5,
      "z": -15,
      "name": "Rock_Lime_Cobble"
    },
    {
      "x": -35,
      "y": 6,
      "z": -15,
      "name": "Rock_Lime_Cobble"
    },
    {
      "x": -35,
      "y": 7,
      "z": -15,
      "name": "Rock_Lime_Cobble"
    },
    {
      "x": -35,
      "y": 8,
      "z": -15,
      "name": "Rock_Lime_Cobble"
    },
    {
      "x": -35,
      "y": 9,
      "z": -15,
      "name": "Rock_Lime_Cobble"
    },
    {
      "x": -35,
      "y": 5,
      "z": -14,
      "name": "Rock_Lime"
    },
    {
      "x": -35,
      "y": 6,
      "z": -14,
      "name": "Rock_Lime_Cobble"
    },
    {
      "x": -35,
      "y": 7,
      "z": -14,
      "name": "Rock_Lime"
    },
    {
      "x": -35,
      "y": 8,
      "z": -14,
      "name": "Rock_Lime"
    },
    {
      "x": -35,
      "y": 9,
      "z": -14,
      "name": "Rock_Lime"
    },
    {
      "x": -35,
      "y": 5,
      "z": -13,
      "name": "Rock_Lime_Cobble"
    },
    {
      "x": -35,
      "y": 6,
      "z": -13,
      "name": "Rock_Lime"
    },
    {
      "x": -35,
      "y": 7,
      "z": -13,
      "name": "Rock_Lime"
    },
    {
      "x": -35,
      "y": 8,
      "z": -13,
      "name": "Rock_Lime_Cobble"
    },
    {
      "x": -35,
      "y": 9,
      "z": -13,
      "name": "Soil_Gravel_Lime"
    },
    {
      "x": -35,
      "y": 6,
      "z": -12,
      "name": "Soil_Gravel_Lime"
    },
    {
      "x": -35,
      "y": 7,
      "z": -12,
      "name": "Rock_Lime_Cobble"
    },
    {
      "x": -35,
      "y": 8,
      "z": -12,
      "name": "Rock_Lime_Cobble"
    },
    {
      "x": -34,
      "y": 6,
      "z": -30,
      "name": "Rock_Lime_Cobble"
    },
    {
      "x": -34,
      "y": 7,
      "z": -30,
      "name": "Soil_Gravel_Lime"
    },
    {
      "x": -34,
      "y": 8,
      "z": -30,
      "name": "Rock_Lime_Cobble"
    },
    {
      "x": -34,
      "y": 5,
      "z": -29,
      "name": "Soil_Gravel_Lime"
    },
    {
      "x": -34,
      "y": 6,
      "z": -29,
      "name": "Rock_Lime"
    },
    {
      "x": -34,
      "y": 7,
      "z": -29,
      "name": "Soil_Gravel_Lime"
    },
    {
      "x": -34,
      "y": 8,
      "z": -29,
      "name": "Rock_Lime"
    },
    {
      "x": -34,
      "y": 9,
      "z": -29,
      "name": "Soil_Gravel_Lime"
    },
    {
      "x": -34,
      "y": 5,
      "z": -28,
      "name": "Soil_Gravel_Lime"
    },
    {
      "x": -34,
      "y": 6,
      "z": -28,
      "name": "Soil_Gravel_Lime"
    },
    {
      "x": -34,
      "y": 7,
      "z": -28,
      "name": "Soil_Gravel_Lime"
    },
    {
      "x": -34,
      "y": 8,
      "z": -28,
      "name": "Rock_Lime_Cobble"
    },
    {
      "x": -34,
      "y": 9,
      "z": -28,
      "name": "Rock_Lime"
    },
    {
      "x": -34,
      "y": 5,
      "z": -27,
      "name": "Rock_Lime_Cobble"
    },
    {
      "x": -34,
      "y": 6,
      "z": -27,
      "name": "Rock_Lime"
    },
    {
      "x": -34,
      "y": 7,
      "z": -27,
      "name": "Soil_Gravel_Lime"
    },
    {
      "x": -34,
      "y": 8,
      "z": -27,
      "name": "Rock_Lime"
    },
    {
      "x": -34,
      "y": 9,
      "z": -27,
      "name": "Rock_Lime"
    },
    {
      "x": -34,
      "y": 5,
      "z": -26,
      "name": "Rock_Lime"
    },
    {
      "x": -34,
      "y": 6,
      "z": -26,
      "name": "Soil_Gravel_Lime"
    },
    {
      "x": -34,
      "y": 7,
      "z": -26,
      "name": "Rock_Lime"
    },
    {
      "x": -34,
      "y": 8,
      "z": -26,
      "name": "Soil_Gravel_Lime"
    },
    {
      "x": -34,
      "y": 9,
      "z": -26,
      "name": "Rock_Lime_Cobble"
    },
    {
      "x": -34,
      "y": 5,
      "z": -25,
      "name": "Soil_Gravel_Lime"
    },
    {
      "x": -34,
      "y": 6,
      "z": -25,
      "name": "Soil_Gravel_Lime"
    },
    {
      "x": -34,
      "y": 7,
      "z": -25,
      "name": "Rock_Lime"
    },
    {
      "x": -34,
      "y": 8,
      "z": -25,
      "name": "Rock_Lime"
    },
    {
      "x": -34,
      "y": 9,
      "z": -25,
      "name": "Rock_Lime"
    },
    {
      "x": -34,
      "y": 13,
      "z": -25,
      "name": "Plant_Coral_Block_Blue"
    },
    {
      "x": -34,
      "y": 14,
      "z": -25,
      "name": "Plant_Coral_Block_Blue"
    },
    {
      "x": -34,
      "y": 15,
      "z": -25,
      "name": "Plant_Coral_Block_Blue"
    },
    {
      "x": -34,
      "y": 16,
      "z": -25,
      "name": "Plant_Coral_Block_Blue"
    },
    {
      "x": -34,
      "y": 17,
      "z": -25,
      "name": "Plant_Coral_Block_Blue"
    },
    {
      "x": -34,
      "y": 5,
      "z": -24,
      "name": "Rock_Lime_Cobble"
    },
    {
      "x": -34,
      "y": 6,
      "z": -24,
      "name": "Soil_Gravel_Lime"
    },
    {
      "x": -34,
      "y": 7,
      "z": -24,
      "name": "Rock_Lime_Cobble"
    },
    {
      "x": -34,
      "y": 8,
      "z": -24,
      "name": "Rock_Lime_Cobble"
    },
    {
      "x": -34,
      "y": 9,
      "z": -24,
      "name": "Soil_Gravel_Lime"
    },
    {
      "x": -34,
      "y": 13,
      "z": -24,
      "name": "Plant_Coral_Block_Blue"
    },
    {
      "x": -34,
      "y": 14,
      "z": -24,
      "name": "Plant_Coral_Block_Blue"
    },
    {
      "x": -34,
      "y": 15,
      "z": -24,
      "name": "Plant_Coral_Block_Blue"
    },
    {
      "x": -34,
      "y": 16,
      "z": -24,
      "name": "Plant_Coral_Block_Blue"
    },
    {
      "x": -34,
      "y": 17,
      "z": -24,
      "name": "Plant_Coral_Block_Blue"
    },
    {
      "x": -34,
      "y": 18,
      "z": -24,
      "name": "Plant_Coral_Model_Blue"
    },
    {
      "x": -34,
      "y": 5,
      "z": -23,
      "name": "Rock_Lime_Cobble"
    },
    {
      "x": -34,
      "y": 6,
      "z": -23,
      "name": "Soil_Gravel_Lime"
    },
    {
      "x": -34,
      "y": 7,
      "z": -23,
      "name": "Rock_Lime_Cobble"
    },
    {
      "x": -34,
      "y": 8,
      "z": -23,
      "name": "Soil_Gravel_Lime"
    },
    {
      "x": -34,
      "y": 9,
      "z": -23,
      "name": "Soil_Gravel_Lime"
    },
    {
      "x": -34,
      "y": 10,
      "z": -23,
      "name": "Plant_Coral_Model_Cyan"
    },
    {
      "x": -34,
      "y": 13,
      "z": -23,
      "name": "Plant_Coral_Block_Blue"
    },
    {
      "x": -34,
      "y": 14,
      "z": -23,
      "name": "Plant_Coral_Block_Blue"
    },
    {
      "x": -34,
      "y": 15,
      "z": -23,
      "name": "Plant_Coral_Block_Blue"
    },
    {
      "x": -34,
      "y": 16,
      "z": -23,
      "name": "Plant_Coral_Block_Blue"
    },
    {
      "x": -34,
      "y": 17,
      "z": -23,
      "name": "Plant_Coral_Block_Blue"
    },
    {
      "x": -34,
      "y": 5,
      "z": -22,
      "name": "Rock_Lime"
    },
    {
      "x": -34,
      "y": 6,
      "z": -22,
      "name": "Soil_Gravel_Lime"
    },
    {
      "x": -34,
      "y": 7,
      "z": -22,
      "name": "Rock_Lime_Cobble"
    },
    {
      "x": -34,
      "y": 8,
      "z": -22,
      "name": "Soil_Gravel_Lime"
    },
    {
      "x": -34,
      "y": 9,
      "z": -22,
      "name": "Soil_Gravel_Lime"
    },
    {
      "x": -34,
      "y": 10,
      "z": -22,
      "name": "Plant_Coral_Block_Blue"
    },
    {
      "x": -34,
      "y": 11,
      "z": -22,
      "name": "Plant_Coral_Block_Blue"
    },
    {
      "x": -34,
      "y": 12,
      "z": -22,
      "name": "Plant_Coral_Bush_Blue"
    },
    {
      "x": -34,
      "y": 5,
      "z": -21,
      "name": "Rock_Lime_Cobble"
    },
    {
      "x": -34,
      "y": 6,
      "z": -21,
      "name": "Soil_Gravel_Lime"
    },
    {
      "x": -34,
      "y": 7,
      "z": -21,
      "name": "Soil_Gravel_Lime"
    },
    {
      "x": -34,
      "y": 8,
      "z": -21,
      "name": "Rock_Lime_Cobble"
    },
    {
      "x": -34,
      "y": 9,
      "z": -21,
      "name": "Rock_Lime"
    },
    {
      "x": -34,
      "y": 10,
      "z": -21,
      "name": "Plant_Coral_Block_Blue"
    },
    {
      "x": -34,
      "y": 11,
      "z": -21,
      "name": "Plant_Coral_Block_Blue"
    },
    {
      "x": -34,
      "y": 5,
      "z": -20,
      "name": "Rock_Lime_Cobble"
    },
    {
      "x": -34,
      "y": 6,
      "z": -20,
      "name": "Soil_Gravel_Lime"
    },
    {
      "x": -34,
      "y": 7,
      "z": -20,
      "name": "Soil_Gravel_Lime"
    },
    {
      "x": -34,
      "y": 8,
      "z": -20,
      "name": "Rock_Lime_Cobble"
    },
    {
      "x": -34,
      "y": 9,
      "z": -20,
      "name": "Rock_Lime"
    },
    {
      "x": -34,
      "y": 10,
      "z": -20,
      "name": "Plant_Coral_Block_Blue"
    },
    {
      "x": -34,
      "y": 11,
      "z": -20,
      "name": "Plant_Coral_Block_Blue"
    },
    {
      "x": -34,
      "y": 12,
      "z": -20,
      "name": "Plant_Coral_Block_Blue"
    },
    {
      "x": -34,
      "y": 13,
      "z": -20,
      "name": "Plant_Coral_Block_Blue"
    },
    {
      "x": -34,
      "y": 14,
      "z": -20,
      "name": "Plant_Coral_Block_Blue"
    },
    {
      "x": -34,
      "y": 15,
      "z": -20,
      "name": "Plant_Coral_Block_Blue"
    },
    {
      "x": -34,
      "y": 5,
      "z": -19,
      "name": "Rock_Lime"
    },
    {
      "x": -34,
      "y": 6,
      "z": -19,
      "name": "Rock_Lime_Cobble"
    },
    {
      "x": -34,
      "y": 7,
      "z": -19,
      "name": "Rock_Lime"
    },
    {
      "x": -34,
      "y": 8,
      "z": -19,
      "name": "Rock_Lime"
    },
    {
      "x": -34,
      "y": 9,
      "z": -19,
      "name": "Rock_Lime_Cobble"
    },
    {
      "x": -34,
      "y": 10,
      "z": -19,
      "name": "Plant_Coral_Block_Blue"
    },
    {
      "x": -34,
      "y": 11,
      "z": -19,
      "name": "Plant_Coral_Block_Blue"
    },
    {
      "x": -34,
      "y": 12,
      "z": -19,
      "name": "Plant_Coral_Block_Blue"
    },
    {
      "x": -34,
      "y": 13,
      "z": -19,
      "name": "Plant_Coral_Block_Blue"
    },
    {
      "x": -34,
      "y": 14,
      "z": -19,
      "name": "Plant_Coral_Block_Blue"
    },
    {
      "x": -34,
      "y": 15,
      "z": -19,
      "name": "Plant_Coral_Block_Blue"
    },
    {
      "x": -34,
      "y": 16,
      "z": -19,
      "name": "Plant_Coral_Bush_Blue"
    },
    {
      "x": -34,
      "y": 5,
      "z": -18,
      "name": "Rock_Lime"
    },
    {
      "x": -34,
      "y": 6,
      "z": -18,
      "name": "Rock_Lime"
    },
    {
      "x": -34,
      "y": 7,
      "z": -18,
      "name": "Rock_Lime"
    },
    {
      "x": -34,
      "y": 8,
      "z": -18,
      "name": "Rock_Lime_Cobble"
    },
    {
      "x": -34,
      "y": 9,
      "z": -18,
      "name": "Soil_Gravel_Lime"
    },
    {
      "x": -34,
      "y": 10,
      "z": -18,
      "name": "Plant_Coral_Block_Blue"
    },
    {
      "x": -34,
      "y": 11,
      "z": -18,
      "name": "Plant_Coral_Block_Blue"
    },
    {
      "x": -34,
      "y": 12,
      "z": -18,
      "name": "Plant_Coral_Block_Blue"
    },
    {
      "x": -34,
      "y": 13,
      "z": -18,
      "name": "Plant_Coral_Block_Blue"
    },
    {
      "x": -34,
      "y": 14,
      "z": -18,
      "name": "Plant_Coral_Block_Blue"
    },
    {
      "x": -34,
      "y": 15,
      "z": -18,
      "name": "Plant_Coral_Block_Blue"
    },
    {
      "x": -34,
      "y": 5,
      "z": -17,
      "name": "Soil_Gravel_Lime"
    },
    {
      "x": -34,
      "y": 6,
      "z": -17,
      "name": "Rock_Lime_Cobble"
    },
    {
      "x": -34,
      "y": 7,
      "z": -17,
      "name": "Rock_Lime"
    },
    {
      "x": -34,
      "y": 8,
      "z": -17,
      "name": "Rock_Lime_Cobble"
    },
    {
      "x": -34,
      "y": 9,
      "z": -17,
      "name": "Rock_Lime_Cobble"
    },
    {
      "x": -34,
      "y": 10,
      "z": -17,
      "name": "Plant_Coral_Model_Cyan"
    },
    {
      "x": -34,
      "y": 5,
      "z": -16,
      "name": "Rock_Lime"
    },
    {
      "x": -34,
      "y": 6,
      "z": -16,
      "name": "Rock_Lime_Cobble"
    },
    {
      "x": -34,
      "y": 7,
      "z": -16,
      "name": "Soil_Gravel_Lime"
    },
    {
      "x": -34,
      "y": 8,
      "z": -16,
      "name": "Rock_Lime_Cobble"
    },
    {
      "x": -34,
      "y": 9,
      "z": -16,
      "name": "Soil_Gravel_Lime"
    },
    {
      "x": -34,
      "y": 5,
      "z": -15,
      "name": "Rock_Lime_Cobble"
    },
    {
      "x": -34,
      "y": 6,
      "z": -15,
      "name": "Rock_Lime_Cobble"
    },
    {
      "x": -34,
      "y": 7,
      "z": -15,
      "name": "Soil_Gravel_Lime"
    },
    {
      "x": -34,
      "y": 8,
      "z": -15,
      "name": "Rock_Lime"
    },
    {
      "x": -34,
      "y": 9,
      "z": -15,
      "name": "Rock_Lime_Cobble"
    },
    {
      "x": -34,
      "y": 5,
      "z": -14,
      "name": "Rock_Lime_Cobble"
    },
    {
      "x": -34,
      "y": 6,
      "z": -14,
      "name": "Soil_Gravel_Lime"
    },
    {
      "x": -34,
      "y": 7,
      "z": -14,
      "name": "Soil_Gravel_Lime"
    },
    {
      "x": -34,
      "y": 8,
      "z": -14,
      "name": "Rock_Lime_Cobble"
    },
    {
      "x": -34,
      "y": 9,
      "z": -14,
      "name": "Rock_Lime"
    },
    {
      "x": -34,
      "y": 6,
      "z": -13,
      "name": "Rock_Lime_Cobble"
    },
    {
      "x": -34,
      "y": 7,
      "z": -13,
      "name": "Soil_Gravel_Lime"
    },
    {
      "x": -34,
      "y": 8,
      "z": -13,
      "name": "Soil_Gravel_Lime"
    },
    {
      "x": -34,
      "y": 7,
      "z": -12,
